Workbook

Sheet Sheet1
A1: 学籍番号 | B1: クラス | C1: 氏名 | D1: 卒業・退学 | E1: 進路区分 | F1: 最終合格校 | G1: 出願経験 | H1: 1年生 | I1: 退学理由 | J1: 進学希望 | K1: 卒業者進路 | L1: 大学・大学院 | M1: 専門学校 | N1: 進学先
A2: 2304010 | B2: 2-1 | C2: 尹 麗 | D2: 卒業 | E2: 専門学校 | F2: 兵庫県立総合衛生学院 | G2: 有 | J2: =IF(OR(テーブル1[[#This Row],[最終合格校]]<>"",テーブル1[[#This Row],[進路区分]]="進学未定",テーブル1[[#This Row],[出願経験]]="有"),"○","")&F2 -> ○兵庫県立総合衛生学院 | K2: =IF(OR(D2="卒業",D2="修了",D2="延長"),E2,"") -> 専門学校 | L2: =IF(E2="大学",F2,IF(E2="大学院",F2,"")) | M2: =IF(E2="専門学校",F2,"") -> 兵庫県立総合衛生学院 | N2: =テーブル1[[#This Row],[大学・大学院]]&テーブル1[[#This Row],[専門学校]] -> 兵庫県立総合衛生学院
A3: 2304066 | B3: 2-1 | C3: PAING SHIN HTET | D3: 卒業 | E3: 専門学校 | F3: 神戸電子専門学校 | G3: 有 | J3: =IF(OR(テーブル1[[#This Row],[最終合格校]]<>"",テーブル1[[#This Row],[進路区分]]="進学未定",テーブル1[[#This Row],[出願経験]]="有"),"○","")&F3 -> ○神戸電子専門学校 | K3: =IF(OR(D3="卒業",D3="修了",D3="延長"),E3,"") -> 専門学校 | L3: =IF(E3="大学",F3,IF(E3="大学院",F3,"")) | M3: =IF(E3="専門学校",F3,"") -> 神戸電子専門学校 | N3: =テーブル1[[#This Row],[大学・大学院]]&テーブル1[[#This Row],[専門学校]] -> 神戸電子専門学校
A4: 2304067 | B4: 2-1 | C4: HTET HTOO KHIN | D4: 卒業 | E4: 専門学校 | F4: 神戸電子専門学校 | G4: 有 | J4: =IF(OR(テーブル1[[#This Row],[最終合格校]]<>"",テーブル1[[#This Row],[進路区分]]="進学未定",テーブル1[[#This Row],[出願経験]]="有"),"○","")&F4 -> ○神戸電子専門学校 | K4: =IF(OR(D4="卒業",D4="修了",D4="延長"),E4,"") -> 専門学校 | L4: =IF(E4="大学",F4,IF(E4="大学院",F4,"")) | M4: =IF(E4="専門学校",F4,"") -> 神戸電子専門学校 | N4: =テーブル1[[#This Row],[大学・大学院]]&テーブル1[[#This Row],[専門学校]] -> 神戸電子専門学校
A5: 2304069 | B5: 2-1 | C5: THIRI HNIN HTET | D5: 卒業 | E5: 専門学校 | F5: 東京国際ビジネスカレッジ神戸校 | G5: 有 | J5: =IF(OR(テーブル1[[#This Row],[最終合格校]]<>"",テーブル1[[#This Row],[進路区分]]="進学未定",テーブル1[[#This Row],[出願経験]]="有"),"○","")&F5 -> ○東京国際ビジネスカレッジ神戸校 | K5: =IF(OR(D5="卒業",D5="修了",D5="延長"),E5,"") -> 専門学校 | L5: =IF(E5="大学",F5,IF(E5="大学院",F5,"")) | M5: =IF(E5="専門学校",F5,"") -> 東京国際ビジネスカレッジ神戸校 | N5: =テーブル1[[#This Row],[大学・大学院]]&テーブル1[[#This Row],[専門学校]] -> 東京国際ビジネスカレッジ神戸校
A6: 2304070 | B6: 2-1 | C6: YOON LAE LAE TUN | D6: 卒業 | E6: 大学 | F6: 神戸国際大学 | G6: 有 | J6: =IF(OR(テーブル1[[#This Row],[最終合格校]]<>"",テーブル1[[#This Row],[進路区分]]="進学未定",テーブル1[[#This Row],[出願経験]]="有"),"○","")&F6 -> ○神戸国際大学 | K6: =IF(OR(D6="卒業",D6="修了",D6="延長"),E6,"") -> 大学 | L6: =IF(E6="大学",F6,IF(E6="大学院",F6,"")) -> 神戸国際大学 | M6: =IF(E6="専門学校",F6,"") | N6: =テーブル1[[#This Row],[大学・大学院]]&テーブル1[[#This Row],[専門学校]] -> 神戸国際大学
A7: 2304071 | B7: 2-1 | C7: AYE WAI PHYO | D7: 卒業 | E7: 専門学校 | F7: ECCコンピュータ専門学校 | G7: 有 | J7: =IF(OR(テーブル1[[#This Row],[最終合格校]]<>"",テーブル1[[#This Row],[進路区分]]="進学未定",テーブル1[[#This Row],[出願経験]]="有"),"○","")&F7 -> ○ECCコンピュータ専門学校 | K7: =IF(OR(D7="卒業",D7="修了",D7="延長"),E7,"") -> 専門学校 | L7: =IF(E7="大学",F7,IF(E7="大学院",F7,"")) | M7: =IF(E7="専門学校",F7,"") -> ECCコンピュータ専門学校 | N7: =テーブル1[[#This Row],[大学・大学院]]&テーブル1[[#This Row],[専門学校]] -> ECCコンピュータ専門学校
A8: 2304072 | B8: 2-1 | C8: ARKAR HEIN | D8: 卒業 | E8: 専門学校 | F8: トヨタ神戸自動車大学校 | G8: 有 | J8: =IF(OR(テーブル1[[#This Row],[最終合格校]]<>"",テーブル1[[#This Row],[進路区分]]="進学未定",テーブル1[[#This Row],[出願経験]]="有"),"○","")&F8 -> ○トヨタ神戸自動車大学校 | K8: =IF(OR(D8="卒業",D8="修了",D8="延長"),E8,"") -> 専門学校 | L8: =IF(E8="大学",F8,IF(E8="大学院",F8,"")) | M8: =IF(E8="専門学校",F8,"") -> トヨタ神戸自動車大学校 | N8: =テーブル1[[#This Row],[大学・大学院]]&テーブル1[[#This Row],[専門学校]] -> トヨタ神戸自動車大学校
A9: 2304073 | B9: 2-1 | C9: WIN THEINGI SHWE | D9: 卒業 | E9: 専門学校 | F9: ECCコンピュータ専門学校 | G9: 有 | J9: =IF(OR(テーブル1[[#This Row],[最終合格校]]<>"",テーブル1[[#This Row],[進路区分]]="進学未定",テーブル1[[#This Row],[出願経験]]="有"),"○","")&F9 -> ○ECCコンピュータ専門学校 | K9: =IF(OR(D9="卒業",D9="修了",D9="延長"),E9,"") -> 専門学校 | L9: =IF(E9="大学",F9,IF(E9="大学院",F9,"")) | M9: =IF(E9="専門学校",F9,"") -> ECCコンピュータ専門学校 | N9: =テーブル1[[#This Row],[大学・大学院]]&テーブル1[[#This Row],[専門学校]] -> ECCコンピュータ専門学校
A10: 2304074 | B10: 2-1 | C10: MAY THINZAR KYAW | D10: 卒業 | E10: 専門学校 | F10: ECC国際外語専門学校 | G10: 有 | J10: =IF(OR(テーブル1[[#This Row],[最終合格校]]<>"",テーブル1[[#This Row],[進路区分]]="進学未定",テーブル1[[#This Row],[出願経験]]="有"),"○","")&F10 -> ○ECC国際外語専門学校 | K10: =IF(OR(D10="卒業",D10="修了",D10="延長"),E10,"") -> 専門学校 | L10: =IF(E10="大学",F10,IF(E10="大学院",F10,"")) | M10: =IF(E10="専門学校",F10,"") -> ECC国際外語専門学校 | N10: =テーブル1[[#This Row],[大学・大学院]]&テーブル1[[#This Row],[専門学校]] -> ECC国際外語専門学校
A11: 2304075 | B11: 2-1 | C11: EI THAE PHYU | D11: 卒業 | E11: 専門学校 | F11: ECC国際外語専門学校 | G11: 有 | J11: =IF(OR(テーブル1[[#This Row],[最終合格校]]<>"",テーブル1[[#This Row],[進路区分]]="進学未定",テーブル1[[#This Row],[出願経験]]="有"),"○","")&F11 -> ○ECC国際外語専門学校 | K11: =IF(OR(D11="卒業",D11="修了",D11="延長"),E11,"") -> 専門学校 | L11: =IF(E11="大学",F11,IF(E11="大学院",F11,"")) | M11: =IF(E11="専門学校",F11,"") -> ECC国際外語専門学校 | N11: =テーブル1[[#This Row],[大学・大学院]]&テーブル1[[#This Row],[専門学校]] -> ECC国際外語専門学校
A12: 2304081 | B12: 2-1 | C12: KAUNG KHANT SAN | D12: 卒業 | E12: 専門学校 | F12: 神戸電子専門学校 | G12: 有 | J12: =IF(OR(テーブル1[[#This Row],[最終合格校]]<>"",テーブル1[[#This Row],[進路区分]]="進学未定",テーブル1[[#This Row],[出願経験]]="有"),"○","")&F12 -> ○神戸電子専門学校 | K12: =IF(OR(D12="卒業",D12="修了",D12="延長"),E12,"") -> 専門学校 | L12: =IF(E12="大学",F12,IF(E12="大学院",F12,"")) | M12: =IF(E12="専門学校",F12,"") -> 神戸電子専門学校 | N12: =テーブル1[[#This Row],[大学・大学院]]&テーブル1[[#This Row],[専門学校]] -> 神戸電子専門学校
A13: 2304090 | B13: 2-1 | C13: HTET NAING WIN | D13: 卒業 | E13: 専門学校 | F13: ECCコンピュータ専門学校 | G13: 有 | J13: =IF(OR(テーブル1[[#This Row],[最終合格校]]<>"",テーブル1[[#This Row],[進路区分]]="進学未定",テーブル1[[#This Row],[出願経験]]="有"),"○","")&F13 -> ○ECCコンピュータ専門学校 | K13: =IF(OR(D13="卒業",D13="修了",D13="延長"),E13,"") -> 専門学校 | L13: =IF(E13="大学",F13,IF(E13="大学院",F13,"")) | M13: =IF(E13="専門学校",F13,"") -> ECCコンピュータ専門学校 | N13: =テーブル1[[#This Row],[大学・大学院]]&テーブル1[[#This Row],[専門学校]] -> ECCコンピュータ専門学校
... A24: 2304080 | B24: 2-2 | C24: KAUNG MYAT TUN | D24: 卒業 | E24: 専門学校 | F24: CAD製図専門学校 | G24: 有 | J24: =IF(OR(テーブル1[[#This Row],[最終合格校]]<>"",テーブル1[[#This Row],[進路区分]]="進学未定",テーブル1[[#This Row],[出願経験]]="有"),"○","")&F24 -> ○CAD製図専門学校 | K24: =IF(OR(D24="卒業",D24="修了",D24="延長"),E24,"") -> 専門学校 | L24: =IF(E24="大学",F24,IF(E24="大学院",F24,"")) | M24: =IF(E24="専門学校",F24,"") -> CAD製図専門学校 | N24: =テーブル1[[#This Row],[大学・大学院]]&テーブル1[[#This Row],[専門学校]] -> CAD製図専門学校
A25: 2304083 | B25: 2-2 | C25: EI EI HTUN | D25: 卒業 | E25: 特定活動ビザ | J25: =IF(OR(テーブル1[[#This Row],[最終合格校]]<>"",テーブル1[[#This Row],[進路区分]]="進学未定",テーブル1[[#This Row],[出願経験]]="有"),"○","")&F25 | K25: =IF(OR(D25="卒業",D25="修了",D25="延長"),E25,"") -> 特定活動ビザ | L25: =IF(E25="大学",F25,IF(E25="大学院",F25,"")) | M25: =IF(E25="専門学校",F25,"") | N25: =テーブル1[[#This Row],[大学・大学院]]&テーブル1[[#This Row],[専門学校]]
A26: 2304084 | B26: 2-2 | C26: ZAW WAI PHYO | D26: 卒業 | E26: 専門学校 | F26: 東京国際ビジネスカレッジ神戸校 | G26: 有 | J26: =IF(OR(テーブル1[[#This Row],[最終合格校]]<>"",テーブル1[[#This Row],[進路区分]]="進学未定",テーブル1[[#This Row],[出願経験]]="有"),"○","")&F26 -> ○東京国際ビジネスカレッジ神戸校 | K26: =IF(OR(D26="卒業",D26="修了",D26="延長"),E26,"") -> 専門学校 | L26: =IF(E26="大学",F26,IF(E26="大学院",F26,"")) | M26: =IF(E26="専門学校",F26,"") -> 東京国際ビジネスカレッジ神戸校 | N26: =テーブル1[[#This Row],[大学・大学院]]&テーブル1[[#This Row],[専門学校]] -> 東京国際ビジネスカレッジ神戸校
A27: 2304085 | B27: 2-2 | C27: MOE PYAE SAN | D27: 卒業 | E27: 専門学校 | F27: エール学園 | G27: 有 | J27: =IF(OR(テーブル1[[#This Row],[最終合格校]]<>"",テーブル1[[#This Row],[進路区分]]="進学未定",テーブル1[[#This Row],[出願経験]]="有"),"○","")&F27 -> ○エール学園 | K27: =IF(OR(D27="卒業",D27="修了",D27="延長"),E27,"") -> 専門学校 | L27: =IF(E27="大学",F27,IF(E27="大学院",F27,"")) | M27: =IF(E27="専門学校",F27,"") -> エール学園 | N27: =テーブル1[[#This Row],[大学・大学院]]&テーブル1[[#This Row],[専門学校]] -> エール学園
A28: 2304086 | B28: 2-2 | C28: MAY THAZIN PHOO | D28: 卒業 | E28: 専門学校 | F28: プロスペラ学院ビジネス専門学校 | G28: 有 | J28: =IF(OR(テーブル1[[#This Row],[最終合格校]]<>"",テーブル1[[#This Row],[進路区分]]="進学未定",テーブル1[[#This Row],[出願経験]]="有"),"○","")&F28 -> ○プロスペラ学院ビジネス専門学校 | K28: =IF(OR(D28="卒業",D28="修了",D28="延長"),E28,"") -> 専門学校 | L28: =IF(E28="大学",F28,IF(E28="大学院",F28,"")) | M28: =IF(E28="専門学校",F28,"") -> プロスペラ学院ビジネス専門学校 | N28: =テーブル1[[#This Row],[大学・大学院]]&テーブル1[[#This Row],[専門学校]] -> プロスペラ学院ビジネス専門学校
A29: 2304139 | B29: 2-2 | C29: NAGOLLE GEDARA LAHIRU MADUSHAN JAYARATHNE | D29: 卒業 | E29: 専門学校 | F29: 東亜経理専門学校 | G29: 有 | J29: =IF(OR(テーブル1[[#This Row],[最終合格校]]<>"",テーブル1[[#This Row],[進路区分]]="進学未定",テーブル1[[#This Row],[出願経験]]="有"),"○","")&F29 -> ○東亜経理専門学校 | K29: =IF(OR(D29="卒業",D29="修了",D29="延長"),E29,"") -> 専門学校 | L29: =IF(E29="大学",F29,IF(E29="大学院",F29,"")) | M29: =IF(E29="専門学校",F29,"") -> 東亜経理専門学校 | N29: =テーブル1[[#This Row],[大学・大学院]]&テーブル1[[#This Row],[専門学校]] -> 東亜経理専門学校
A30: 2304140 | B30: 2-2 | C30: SAMARAWEERA KUSAL DILITHA | D30: 卒業 | E30: 専門学校 | F30: 東京自動車大学校 | G30: 有 | J30: =IF(OR(テーブル1[[#This Row],[最終合格校]]<>"",テーブル1[[#This Row],[進路区分]]="進学未定",テーブル1[[#This Row],[出願経験]]="有"),"○","")&F30 -> ○東京自動車大学校 | K30: =IF(OR(D30="卒業",D30="修了",D30="延長"),E30,"") -> 専門学校 | L30: =IF(E30="大学",F30,IF(E30="大学院",F30,"")) | M30: =IF(E30="専門学校",F30,"") -> 東京自動車大学校 | N30: =テーブル1[[#This Row],[大学・大学院]]&テーブル1[[#This Row],[専門学校]] -> 東京自動車大学校
A31: 2304141 | B31: 2-2 | C31: SHAHADAT HOSSAIN | D31: 卒業 | E31: 専門学校 | F31: CAD製図専門学校 | G31: 有 | J31: =IF(OR(テーブル1[[#This Row],[最終合格校]]<>"",テーブル1[[#This Row],[進路区分]]="進学未定",テーブル1[[#This Row],[出願経験]]="有"),"○","")&F31 -> ○CAD製図専門学校 | K31: =IF(OR(D31="卒業",D31="修了",D31="延長"),E31,"") -> 専門学校 | L31: =IF(E31="大学",F31,IF(E31="大学院",F31,"")) | M31: =IF(E31="専門学校",F31,"") -> CAD製図専門学校 | N31: =テーブル1[[#This Row],[大学・大学院]]&テーブル1[[#This Row],[専門学校]] -> CAD製図専門学校
A32: 2307010 | B32: 2-2 | C32: MARKARIO | D32: 卒業 | E32: 大学 | F32: 流通科学大学 | G32: 有 | J32: =IF(OR(テーブル1[[#This Row],[最終合格校]]<>"",テーブル1[[#This Row],[進路区分]]="進学未定",テーブル1[[#This Row],[出願経験]]="有"),"○","")&F32 -> ○流通科学大学 | K32: =IF(OR(D32="卒業",D32="修了",D32="延長"),E32,"") -> 大学 | L32: =IF(E32="大学",F32,IF(E32="大学院",F32,"")) -> 流通科学大学 | M32: =IF(E32="専門学校",F32,"") | N32: =テーブル1[[#This Row],[大学・大学院]]&テーブル1[[#This Row],[専門学校]] -> 流通科学大学
A33: 2307018 | B33: 2-2 | C33: HNIN YU YU HLAING | D33: 卒業 | E33: 大学 | F33: 流通科学大学 | G33: 有 | J33: =IF(OR(テーブル1[[#This Row],[最終合格校]]<>"",テーブル1[[#This Row],[進路区分]]="進学未定",テーブル1[[#This Row],[出願経験]]="有"),"○","")&F33 -> ○流通科学大学 | K33: =IF(OR(D33="卒業",D33="修了",D33="延長"),E33,"") -> 大学 | L33: =IF(E33="大学",F33,IF(E33="大学院",F33,"")) -> 流通科学大学 | M33: =IF(E33="専門学校",F33,"") | N33: =テーブル1[[#This Row],[大学・大学院]]&テーブル1[[#This Row],[専門学校]] -> 流通科学大学
A34: 2307022 | B34: 2-2 | C34: CHIT SU SU THEINT ZUN | D34: 卒業 | E34: 大学 | F34: 大阪女学院大学 | G34: 有 | J34: =IF(OR(テーブル1[[#This Row],[最終合格校]]<>"",テーブル1[[#This Row],[進路区分]]="進学未定",テーブル1[[#This Row],[出願経験]]="有"),"○","")&F34 -> ○大阪女学院大学 | K34: =IF(OR(D34="卒業",D34="修了",D34="延長"),E34,"") -> 大学 | L34: =IF(E34="大学",F34,IF(E34="大学院",F34,"")) -> 大阪女学院大学 | M34: =IF(E34="専門学校",F34,"") | N34: =テーブル1[[#This Row],[大学・大学院]]&テーブル1[[#This Row],[専門学校]] -> 大阪女学院大学
A35: 2307023 | B35: 2-2 | C35: HANNI ZAW OO | D35: 卒業 | E35: 専門学校 | F35: 中央工学校OSAKA | G35: 有 | J35: =IF(OR(テーブル1[[#This Row],[最終合格校]]<>"",テーブル1[[#This Row],[進路区分]]="進学未定",テーブル1[[#This Row],[出願経験]]="有"),"○","")&F35 -> ○中央工学校OSAKA | K35: =IF(OR(D35="卒業",D35="修了",D35="延長"),E35,"") -> 専門学校 | L35: =IF(E35="大学",F35,IF(E35="大学院",F35,"")) | M35: =IF(E35="専門学校",F35,"") -> 中央工学校OSAKA | N35: =テーブル1[[#This Row],[大学・大学院]]&テーブル1[[#This Row],[専門学校]] -> 中央工学校OSAKA
A36: 2307055 | B36: 2-2 | C36: PRADHAN ANMOLISHA | D36: 卒業 | E36: 大学 | F36: 桃山学院大学 | G36: 有 | J36: =IF(OR(テーブル1[[#This Row],[最終合格校]]<>"",テーブル1[[#This Row],[進路区分]]="進学未定",テーブル1[[#This Row],[出願経験]]="有"),"○","")&F36 -> ○桃山学院大学 | K36: =IF(OR(D36="卒業",D36="修了",D36="延長"),E36,"") -> 大学 | L36: =IF(E36="大学",F36,IF(E36="大学院",F36,"")) -> 桃山学院大学 | M36: =IF(E36="専門学校",F36,"") | N36: =テーブル1[[#This Row],[大学・大学院]]&テーブル1[[#This Row],[専門学校]] -> 桃山学院大学
A37: 2310014 | B37: 2-2 | C37: HNIN PWINT WAI | D37: 卒業 | E37: 専門学校 | F37: 駿台観光＆ホテルブライダルビジネスカレッジ | G37: 有 | J37: =IF(OR(テーブル1[[#This Row],[最終合格校]]<>"",テーブル1[[#This Row],[進路区分]]="進学未定",テーブル1[[#This Row],[出願経験]]="有"),"○","")&F37 -> ○駿台観光＆ホテルブライダルビジネスカレッジ | K37: =IF(OR(D37="卒業",D37="修了",D37="延長"),E37,"") -> 専門学校 | L37: =IF(E37="大学",F37,IF(E37="大学院",F37,"")) | M37: =IF(E37="専門学校",F37,"") -> 駿台観光＆ホテルブライダルビジネスカレッジ | N37: =テーブル1[[#This Row],[大学・大学院]]&テーブル1[[#This Row],[専門学校]] -> 駿台観光＆ホテルブライダルビジネスカレッジ
... A85: 2304052 | B85: 2-5 | C85: ANJALI LO TAMANG | D85: 卒業 | E85: 専門学校 | F85: 大阪観光ビジネス学院 | G85: 有 | J85: =IF(OR(テーブル1[[#This Row],[最終合格校]]<>"",テーブル1[[#This Row],[進路区分]]="進学未定",テーブル1[[#This Row],[出願経験]]="有"),"○","")&F85 -> ○大阪観光ビジネス学院 | K85: =IF(OR(D85="卒業",D85="修了",D85="延長"),E85,"") -> 専門学校 | L85: =IF(E85="大学",F85,IF(E85="大学院",F85,"")) | M85: =IF(E85="専門学校",F85,"") -> 大阪観光ビジネス学院 | N85: =テーブル1[[#This Row],[大学・大学院]]&テーブル1[[#This Row],[専門学校]] -> 大阪観光ビジネス学院
A86: 2304078 | B86: 2-5 | C86: ZWE MARN OO | D86: 卒業 | E86: 特定活動ビザ | J86: =IF(OR(テーブル1[[#This Row],[最終合格校]]<>"",テーブル1[[#This Row],[進路区分]]="進学未定",テーブル1[[#This Row],[出願経験]]="有"),"○","")&F86 | K86: =IF(OR(D86="卒業",D86="修了",D86="延長"),E86,"") -> 特定活動ビザ | L86: =IF(E86="大学",F86,IF(E86="大学院",F86,"")) | M86: =IF(E86="専門学校",F86,"") | N86: =テーブル1[[#This Row],[大学・大学院]]&テーブル1[[#This Row],[専門学校]]
A87: 2304079 | B87: 2-5 | C87: PYAE PHYO HEIN | D87: 卒業 | E87: 専門学校 | F87: 神戸電子専門学校 | G87: 有 | J87: =IF(OR(テーブル1[[#This Row],[最終合格校]]<>"",テーブル1[[#This Row],[進路区分]]="進学未定",テーブル1[[#This Row],[出願経験]]="有"),"○","")&F87 -> ○神戸電子専門学校 | K87: =IF(OR(D87="卒業",D87="修了",D87="延長"),E87,"") -> 専門学校 | L87: =IF(E87="大学",F87,IF(E87="大学院",F87,"")) | M87: =IF(E87="専門学校",F87,"") -> 神戸電子専門学校 | N87: =テーブル1[[#This Row],[大学・大学院]]&テーブル1[[#This Row],[専門学校]] -> 神戸電子専門学校
A88: 2304088 | B88: 2-5 | C88: YAMONE PHOO | D88: 卒業 | E88: 特定活動ビザ | F88: 関西国際旅行・ホテル専門学校 | G88: 有 | J88: =IF(OR(テーブル1[[#This Row],[最終合格校]]<>"",テーブル1[[#This Row],[進路区分]]="進学未定",テーブル1[[#This Row],[出願経験]]="有"),"○","")&F88 -> ○関西国際旅行・ホテル専門学校 | K88: =IF(OR(D88="卒業",D88="修了",D88="延長"),E88,"") -> 特定活動ビザ | L88: =IF(E88="大学",F88,IF(E88="大学院",F88,"")) | M88: =IF(E88="専門学校",F88,"") | N88: =テーブル1[[#This Row],[大学・大学院]]&テーブル1[[#This Row],[専門学校]]
A89: 2304096 | B89: 2-5 | C89: KAMRUL HASSAN SHIAM | D89: 卒業 | E89: 専門学校 | F89: 東亜経理専門学校 | G89: 有 | J89: =IF(OR(テーブル1[[#This Row],[最終合格校]]<>"",テーブル1[[#This Row],[進路区分]]="進学未定",テーブル1[[#This Row],[出願経験]]="有"),"○","")&F89 -> ○東亜経理専門学校 | K89: =IF(OR(D89="卒業",D89="修了",D89="延長"),E89,"") -> 専門学校 | L89: =IF(E89="大学",F89,IF(E89="大学院",F89,"")) | M89: =IF(E89="専門学校",F89,"") -> 東亜経理専門学校 | N89: =テーブル1[[#This Row],[大学・大学院]]&テーブル1[[#This Row],[専門学校]] -> 東亜経理専門学校
A90: 2304102 | B90: 2-5 | C90: REZWANA TASNIM NAWMI | D90: 卒業 | E90: 専門学校 | F90: 関西国際旅行・ホテル専門学校 | G90: 有 | J90: =IF(OR(テーブル1[[#This Row],[最終合格校]]<>"",テーブル1[[#This Row],[進路区分]]="進学未定",テーブル1[[#This Row],[出願経験]]="有"),"○","")&F90 -> ○関西国際旅行・ホテル専門学校 | K90: =IF(OR(D90="卒業",D90="修了",D90="延長"),E90,"") -> 専門学校 | L90: =IF(E90="大学",F90,IF(E90="大学院",F90,"")) | M90: =IF(E90="専門学校",F90,"") -> 関西国際旅行・ホテル専門学校 | N90: =テーブル1[[#This Row],[大学・大学院]]&テーブル1[[#This Row],[専門学校]] -> 関西国際旅行・ホテル専門学校
A91: 2304104 | B91: 2-5 | C91: GOLAM SAJJAD | D91: 卒業 | E91: 専門学校 | F91: 中央美術学園 | G91: 有 | J91: =IF(OR(テーブル1[[#This Row],[最終合格校]]<>"",テーブル1[[#This Row],[進路区分]]="進学未定",テーブル1[[#This Row],[出願経験]]="有"),"○","")&F91 -> ○中央美術学園 | K91: =IF(OR(D91="卒業",D91="修了",D91="延長"),E91,"") -> 専門学校 | L91: =IF(E91="大学",F91,IF(E91="大学院",F91,"")) | M91: =IF(E91="専門学校",F91,"") -> 中央美術学園 | N91: =テーブル1[[#This Row],[大学・大学院]]&テーブル1[[#This Row],[専門学校]] -> 中央美術学園
A92: 2304110 | B92: 2-5 | C92: MANIK MIA | D92: 卒業 | E92: 専門学校 | F92: 東京国際ビジネスカレッジ神戸校 | G92: 有 | J92: =IF(OR(テーブル1[[#This Row],[最終合格校]]<>"",テーブル1[[#This Row],[進路区分]]="進学未定",テーブル1[[#This Row],[出願経験]]="有"),"○","")&F92 -> ○東京国際ビジネスカレッジ神戸校 | K92: =IF(OR(D92="卒業",D92="修了",D92="延長"),E92,"") -> 専門学校 | L92: =IF(E92="大学",F92,IF(E92="大学院",F92,"")) | M92: =IF(E92="専門学校",F92,"") -> 東京国際ビジネスカレッジ神戸校 | N92: =テーブル1[[#This Row],[大学・大学院]]&テーブル1[[#This Row],[専門学校]] -> 東京国際ビジネスカレッジ神戸校
A93: 2304121 | B93: 2-5 | C93: ISLAM MD SAIDUL | D93: 卒業 | E93: 専門学校 | F93: CAD製図専門学校 | G93: 有 | J93: =IF(OR(テーブル1[[#This Row],[最終合格校]]<>"",テーブル1[[#This Row],[進路区分]]="進学未定",テーブル1[[#This Row],[出願経験]]="有"),"○","")&F93 -> ○CAD製図専門学校 | K93: =IF(OR(D93="卒業",D93="修了",D93="延長"),E93,"") -> 専門学校 | L93: =IF(E93="大学",F93,IF(E93="大学院",F93,"")) | M93: =IF(E93="専門学校",F93,"") -> CAD製図専門学校 | N93: =テーブル1[[#This Row],[大学・大学院]]&テーブル1[[#This Row],[専門学校]] -> CAD製図専門学校
A94: 2304125 | B94: 2-5 | C94: MREDUL CHOUDHURY | D94: 卒業 | E94: 専門学校 | F94: 神戸電子専門学校 | G94: 有 | J94: =IF(OR(テーブル1[[#This Row],[最終合格校]]<>"",テーブル1[[#This Row],[進路区分]]="進学未定",テーブル1[[#This Row],[出願経験]]="有"),"○","")&F94 -> ○神戸電子専門学校 | K94: =IF(OR(D94="卒業",D94="修了",D94="延長"),E94,"") -> 専門学校 | L94: =IF(E94="大学",F94,IF(E94="大学院",F94,"")) | M94: =IF(E94="専門学校",F94,"") -> 神戸電子専門学校 | N94: =テーブル1[[#This Row],[大学・大学院]]&テーブル1[[#This Row],[専門学校]] -> 神戸電子専門学校
A95: 2304127 | B95: 2-5 | C95: MD.EASIN HOSSEN REDOY | D95: 卒業 | E95: 専門学校 | F95: 中央美術学園 | G95: 有 | J95: =IF(OR(テーブル1[[#This Row],[最終合格校]]<>"",テーブル1[[#This Row],[進路区分]]="進学未定",テーブル1[[#This Row],[出願経験]]="有"),"○","")&F95 -> ○中央美術学園 | K95: =IF(OR(D95="卒業",D95="修了",D95="延長"),E95,"") -> 専門学校 | L95: =IF(E95="大学",F95,IF(E95="大学院",F95,"")) | M95: =IF(E95="専門学校",F95,"") -> 中央美術学園 | N95: =テーブル1[[#This Row],[大学・大学院]]&テーブル1[[#This Row],[専門学校]] -> 中央美術学園
A96: 2307012 | B96: 2-5 | C96: TIN ZAW WIN | D96: 卒業 | E96: 専門学校 | F96: トヨタ神戸自動車大学校 | G96: 有 | J96: =IF(OR(テーブル1[[#This Row],[最終合格校]]<>"",テーブル1[[#This Row],[進路区分]]="進学未定",テーブル1[[#This Row],[出願経験]]="有"),"○","")&F96 -> ○トヨタ神戸自動車大学校 | K96: =IF(OR(D96="卒業",D96="修了",D96="延長"),E96,"") -> 専門学校 | L96: =IF(E96="大学",F96,IF(E96="大学院",F96,"")) | M96: =IF(E96="専門学校",F96,"") -> トヨタ神戸自動車大学校 | N96: =テーブル1[[#This Row],[大学・大学院]]&テーブル1[[#This Row],[専門学校]] -> トヨタ神戸自動車大学校
A97: 2307076 | B97: 2-5 | C97: SHAIDUL ISLAM | D97: 卒業 | E97: 大学院 | F97: 南山大学大学院研修生 | G97: 有 | J97: =IF(OR(テーブル1[[#This Row],[最終合格校]]<>"",テーブル1[[#This Row],[進路区分]]="進学未定",テーブル1[[#This Row],[出願経験]]="有"),"○","")&F97 -> ○南山大学大学院研修生 | K97: =IF(OR(D97="卒業",D97="修了",D97="延長"),E97,"") -> 大学院 | L97: =IF(E97="大学",F97,IF(E97="大学院",F97,"")) -> 南山大学大学院研修生 | M97: =IF(E97="専門学校",F97,"") | N97: =テーブル1[[#This Row],[大学・大学院]]&テーブル1[[#This Row],[専門学校]] -> 南山大学大学院研修生
...

Sheet 卒業者割合
A1: 卒業・修了 | B1: =COUNTIF(Sheet1!D:D,"卒業")+COUNTIF(Sheet1!D:D,"修了") -> 250
A2: 退学 | B2: =COUNTIF(Sheet1!D:D,"退学") -> 13
A3: 延長 | B3: =COUNTIF(Sheet1!D:D,"延長") -> 0

Sheet 卒業生進路
A1: 専門学校 | B1: =COUNTIF(Sheet1!K:K,A1) -> 197 | C1: =B1/SUM(B$1:B$10) -> 0.82426778
A2: 大学 | B2: =COUNTIF(Sheet1!K:K,A2) -> 40 | C2: =B2/SUM(B$1:B$10) -> 0.16736402
A3: 大学院 | B3: =COUNTIF(Sheet1!K:K,A3) -> 1 | C3: =B3/SUM(B$1:B$10) -> 0.0041841004
A4: 進学未定 | B4: =COUNTIF(Sheet1!K:K,A4) -> 0 | C4: =B4/SUM(B$1:B$10) -> 0
A5: 帰国予定 | B5: =COUNTIF(Sheet1!K:K,A5) -> 0 | C5: =B5/SUM(B$1:B$10) -> 0
A6: 就職 | B6: =COUNTIF(Sheet1!K:K,A6) -> 0 | C6: =B6/SUM(B$1:B$10) -> 0
A7: 短期大学 | B7: =COUNTIF(Sheet1!K:K,A7) -> 0 | C7: =B7/SUM(B$1:B$10) -> 0
A8: 就職予定 | B8: =COUNTIF(Sheet1!K:K,A8) -> 0 | C8: =B8/SUM(B$1:B$10) -> 0
A9: 家族滞在 | B9: =COUNTIF(Sheet1!K:K,A9) -> 0 | C9: =B9/SUM(B$1:B$10) -> 0
A10: 帰国 | B10: =COUNTIF(Sheet1!K:K,A10) -> 1 | C10: =B10/SUM(B$1:B$10) -> 0.0041841004

Sheet 退学内訳
A1: 自己都合 | B1: =COUNTIF(Sheet1!I:I,A1) -> 3
A2: 進学 | B2: =COUNTIF(Sheet1!I:I,A2) -> 2
A3: 就職 | B3: =COUNTIF(Sheet1!I:I,A3) -> 3
A4: 家族滞在ビザ変更 | B4: =COUNTIF(Sheet1!I:I,A4) -> 0
A5: 学費未納 | B5: =COUNTIF(Sheet1!I:I,A5) -> 0
A6: 病気 | B6: =COUNTIF(Sheet1!I:I,A6) -> 1
A7: 転校 | B7: =COUNTIF(Sheet1!I:I,A7) -> 0
A8: 家庭事情 | B8: =COUNTIF(Sheet1!I:I,A8) -> 0
A9: 失踪 | B9: =COUNTIF(Sheet1!I:I,A9) -> 0
A10: 妊娠 | B10: =COUNTIF(Sheet1!I:I,A10) -> 0
A11: コロナ自粛帰国 | B11: =COUNTIF(Sheet1!I:I,A11) -> 0
A12: ビザ不交付 | B12: =COUNTIF(Sheet1!I:I,A12) -> 0
... A15: 学力不良 | B15: =COUNTIF(Sheet1!I:I,A15) -> 0

Sheet 合格率
A1: 進学希望者 | B1: =COUNTIF(Sheet1!J:J,"○*") -> 246
A2: 合格者 | B2: =B1-COUNTIF(Sheet1!J:J,"○") -> 245
A3: 未合格者 | B3: =B1-B2 -> 1
A5: 進学希望者：過去に進学を希望したことがある者（退学者含む）
A6: 合格者：いずれかの学校に合格した者（辞退者含む）
A7: 未合格者：進学を希望しているが、まだ合格していない者

Sheet 大学進学先
A1: 進学先 | B1: 人数
A2: 流通科学大学 | B2: 11
A3: 神戸親和大学 | B3: 7
A4: 日本経済大学 | B4: 5
A5: 神戸国際大学 | B5: 3
A6: 芦屋大学 | B6: 2
A7: 大阪女学院大学 | B7: 2
A8: 大阪産業大学 | B8: 1
A9: 日本経済大学渋谷キャンパス | B9: 1
A10: 神戸松蔭大学 | B10: 1
A11: 神戸市外国語大学大学院研究生 | B11: 1
A12: 兵庫大学 | B12: 1
A13: 大阪観光大学 | B13: 1
... A21: 総計 | B21: 43

Sheet 専門学校進学先
A1: 進学先 | B1: 人数
A2: 関西国際旅行・ホテル専門学校 | B2: 23
A3: 東京国際ビジネスカレッジ神戸校 | B3: 18
A4: 東亜経理専門学校 | B4: 15
A5: 神戸電子専門学校 | B5: 13
A6: CAD製図専門学校 | B6: 10
A7: 専門学校アートカレッジ神戸 | B7: 10
A8: ICT専門学校 | B8: 10
A9: 中央美術学園 | B9: 9
A10: 愛甲学院専門学校 | B10: 9
A11: ECCコンピュータ専門学校 | B11: 8
A12: 太田工科専門学校 | B12: 6
A13: トヨタ神戸自動車大学校 | B13: 6
... A49: 総計 | B49: 197
