Workbook
Name 試験名: 設定!$A$2
Name 試験名一覧: T_試験[書籍名および実施回]
Name 試験名一覧: T_試験[書籍名および実施回]

Sheet 設定
A1: ↓使用する試験を選んでください
A2: 完全模試N4第2回

Sheet 受験者
A1: 学籍番号 | B1: クラス | C1: 出席番号 | D1: 名前
A2: 2504094 | B2: 1-13 | C2: 13 | D2: UGESH SAPKOTA
A3: 2504103 | B3: 1-13 | C3: 14 | D3: DHAKAL LILA MAYA
A4: 2504108 | B4: 1-13 | C4: 15 | D4: NIRMALA BIST
A5: 2504114 | B5: 1-13 | C5: 16 | D5: CHAUDHARY RAJESH
A6: 2510013 | B6: 1-13 | C6: 20 | D6: LE XUAN BACH
A7: 2504019 | B7: 1-13 | C7: 3 | D7: KC HIMAL

Sheet 解答入力
C1: 1 | D1: 2 | E1: 3 | F1: 4 | G1: 5 | H1: 6 | I1: 7 | J1: 8 | K1: 9 | L1: 10 | M1: 11 | N1: 12 | O1: 13 | P1: 14 | Q1: 15 | R1: 16 | S1: 17 | T1: 18 | U1: 19 | V1: 20 | AE1: 1 | AF1: 2 | AG1: 3 | AH1: 4 | AI1: 5 | AJ1: 6 | AK1: 7 | AL1: 8 | AM1: 9 | AN1: 10 | AO1: 11 | AP1: 12 | AQ1: 13 | AR1: 14 | AS1: 15 | AT1: 16 | AU1: 17 | AV1: 18 | AW1: 19 | AX1: 20
A2: ="使用試験："&試験名 -> 使用試験：完全模試N4第2回 | C2: {=_xlfn.XLOOKUP(C1,T_受験者[[#All],[出席番号]],T_受験者[[#All],[名前]],"",0,1)} | D2: {=_xlfn.XLOOKUP(D1,T_受験者[[#All],[出席番号]],T_受験者[[#All],[名前]],"",0,1)} | E2: {=_xlfn.XLOOKUP(E1,T_受験者[[#All],[出席番号]],T_受験者[[#All],[名前]],"",0,1)} -> KC HIMAL | F2: {=_xlfn.XLOOKUP(F1,T_受験者[[#All],[出席番号]],T_受験者[[#All],[名前]],"",0,1)} | G2: {=_xlfn.XLOOKUP(G1,T_受験者[[#All],[出席番号]],T_受験者[[#All],[名前]],"",0,1)} | H2: {=_xlfn.XLOOKUP(H1,T_受験者[[#All],[出席番号]],T_受験者[[#All],[名前]],"",0,1)} | I2: {=_xlfn.XLOOKUP(I1,T_受験者[[#All],[出席番号]],T_受験者[[#All],[名前]],"",0,1)} | J2: {=_xlfn.XLOOKUP(J1,T_受験者[[#All],[出席番号]],T_受験者[[#All],[名前]],"",0,1)} | ... V2: {=_xlfn.XLOOKUP(V1,T_受験者[[#All],[出席番号]],T_受験者[[#All],[名前]],"",0,1)} -> LE XUAN BACH | X2: 1 | Y2: 2 | Z2: 3 | AA2: 4 | AB2: 未回答 | AC2: 正答 | AD2: 正解率 | AE2: {=_xlfn.XLOOKUP(AE1,T_受験者[[#All],[出席番号]],T_受験者[[#All],[名前]],"",0,1)} | AF2: {=_xlfn.XLOOKUP(AF1,T_受験者[[#All],[出席番号]],T_受験者[[#All],[名前]],"",0,1)} | AG2: {=_xlfn.XLOOKUP(AG1,T_受験者[[#All],[出席番号]],T_受験者[[#All],[名前]],"",0,1)} -> KC HIMAL | AH2: {=_xlfn.XLOOKUP(AH1,T_受験者[[#All],[出席番号]],T_受験者[[#All],[名前]],"",0,1)} | AI2: {=_xlfn.XLOOKUP(AI1,T_受験者[[#All],[出席番号]],T_受験者[[#All],[名前]],"",0,1)} | AJ2: {=_xlfn.XLOOKUP(AJ1,T_受験者[[#All],[出席番号]],T_受験者[[#All],[名前]],"",0,1)} | AK2: {=_xlfn.XLOOKUP(AK1,T_受験者[[#All],[出席番号]],T_受験者[[#All],[名前]],"",0,1)} | AL2: {=_xlfn.XLOOKUP(AL1,T_受験者[[#All],[出席番号]],T_受験者[[#All],[名前]],"",0,1)} | ... AX2: {=_xlfn.XLOOKUP(AX1,T_受験者[[#All],[出席番号]],T_受験者[[#All],[名前]],"",0,1)} -> LE XUAN BACH
A3: {=INDIRECT("'"&試験名&"'!A"&ROW()-2)} -> 文字語彙 | B3: =IF(A3="","",IF(A2=A3,B2+1,1)) -> 1 | E3: 4 | O3: 2 | P3: 4 | Q3: 1 | R3: 4 | V3: 4 | W3: =B3 -> 1 | X3: =IF(W3="","",COUNTIF($C3:$V3,X$2)) -> 1 | Y3: =IF(W3="","",COUNTIF($C3:$V3,Y$2)) -> 1 | Z3: =IF(W3="","",COUNTIF($C3:$V3,Z$2)) -> 0 | AA3: =IF(W3="","",COUNTIF($C3:$V3,AA$2)) -> 4 | AB3: =IF(W3="","",COUNTA(T_受験者[])/4-COUNTA($C3:$V3)) -> 0 | AC3: {=IF(W3="","",INDIRECT("'"&試験名&"'!B"&ROW()-2))} -> 4 | AD3: =IF(W3="","",COUNTIF(AE3:AX3,"〇")/(COUNTA(T_受験者[])/4)) -> 0.66666667 | AE3: =IF($W3="","",IF(C3=$AC3,"〇","×")) -> × | AF3: =IF($W3="","",IF(D3=$AC3,"〇","×")) -> × | AG3: =IF($W3="","",IF(E3=$AC3,"〇","×")) -> 〇 | AH3: =IF($W3="","",IF(F3=$AC3,"〇","×")) -> × | AI3: =IF($W3="","",IF(G3=$AC3,"〇","×")) -> × | AJ3: =IF($W3="","",IF(H3=$AC3,"〇","×")) -> × | AK3: =IF($W3="","",IF(I3=$AC3,"〇","×")) -> × | AL3: =IF($W3="","",IF(J3=$AC3,"〇","×")) -> × | ... AX3: =IF($W3="","",IF(V3=$AC3,"〇","×")) -> 〇
A4: {=INDIRECT("'"&試験名&"'!A"&ROW()-2)} -> 文字語彙 | B4: =IF(A4="","",IF(A3=A4,B3+1,1)) -> 2 | E4: 4 | O4: 4 | P4: 1 | Q4: 4 | R4: 1 | V4: 1 | W4: =B4 -> 2 | X4: =IF(W4="","",COUNTIF($C4:$V4,X$2)) -> 3 | Y4: =IF(W4="","",COUNTIF($C4:$V4,Y$2)) -> 0 | Z4: =IF(W4="","",COUNTIF($C4:$V4,Z$2)) -> 0 | AA4: =IF(W4="","",COUNTIF($C4:$V4,AA$2)) -> 3 | AB4: =IF(W4="","",COUNTA(T_受験者[])/4-COUNTA($C4:$V4)) -> 0 | AC4: {=IF(W4="","",INDIRECT("'"&試験名&"'!B"&ROW()-2))} -> 1 | AD4: =IF(W4="","",COUNTIF(AE4:AX4,"〇")/(COUNTA(T_受験者[])/4)) -> 0.5 | AE4: =IF($W4="","",IF(C4=$AC4,"〇","×")) -> × | AF4: =IF($W4="","",IF(D4=$AC4,"〇","×")) -> × | AG4: =IF($W4="","",IF(E4=$AC4,"〇","×")) -> × | AH4: =IF($W4="","",IF(F4=$AC4,"〇","×")) -> × | AI4: =IF($W4="","",IF(G4=$AC4,"〇","×")) -> × | AJ4: =IF($W4="","",IF(H4=$AC4,"〇","×")) -> × | AK4: =IF($W4="","",IF(I4=$AC4,"〇","×")) -> × | AL4: =IF($W4="","",IF(J4=$AC4,"〇","×")) -> × | ... AX4: =IF($W4="","",IF(V4=$AC4,"〇","×")) -> 〇
A5: {=INDIRECT("'"&試験名&"'!A"&ROW()-2)} -> 文字語彙 | B5: =IF(A5="","",IF(A4=A5,B4+1,1)) -> 3 | E5: 3 | O5: 3 | P5: 3 | Q5: 3 | R5: 3 | V5: 3 | W5: =B5 -> 3 | X5: =IF(W5="","",COUNTIF($C5:$V5,X$2)) -> 0 | Y5: =IF(W5="","",COUNTIF($C5:$V5,Y$2)) -> 0 | Z5: =IF(W5="","",COUNTIF($C5:$V5,Z$2)) -> 6 | AA5: =IF(W5="","",COUNTIF($C5:$V5,AA$2)) -> 0 | AB5: =IF(W5="","",COUNTA(T_受験者[])/4-COUNTA($C5:$V5)) -> 0 | AC5: {=IF(W5="","",INDIRECT("'"&試験名&"'!B"&ROW()-2))} -> 3 | AD5: =IF(W5="","",COUNTIF(AE5:AX5,"〇")/(COUNTA(T_受験者[])/4)) -> 1 | AE5: =IF($W5="","",IF(C5=$AC5,"〇","×")) -> × | AF5: =IF($W5="","",IF(D5=$AC5,"〇","×")) -> × | AG5: =IF($W5="","",IF(E5=$AC5,"〇","×")) -> 〇 | AH5: =IF($W5="","",IF(F5=$AC5,"〇","×")) -> × | AI5: =IF($W5="","",IF(G5=$AC5,"〇","×")) -> × | AJ5: =IF($W5="","",IF(H5=$AC5,"〇","×")) -> × | AK5: =IF($W5="","",IF(I5=$AC5,"〇","×")) -> × | AL5: =IF($W5="","",IF(J5=$AC5,"〇","×")) -> × | ... AX5: =IF($W5="","",IF(V5=$AC5,"〇","×")) -> 〇
A6: {=INDIRECT("'"&試験名&"'!A"&ROW()-2)} -> 文字語彙 | B6: =IF(A6="","",IF(A5=A6,B5+1,1)) -> 4 | E6: 2 | O6: 4 | P6: 2 | R6: 2 | V6: 2 | W6: =B6 -> 4 | X6: =IF(W6="","",COUNTIF($C6:$V6,X$2)) -> 0 | Y6: =IF(W6="","",COUNTIF($C6:$V6,Y$2)) -> 4 | Z6: =IF(W6="","",COUNTIF($C6:$V6,Z$2)) -> 0 | AA6: =IF(W6="","",COUNTIF($C6:$V6,AA$2)) -> 1 | AB6: =IF(W6="","",COUNTA(T_受験者[])/4-COUNTA($C6:$V6)) -> 1 | AC6: {=IF(W6="","",INDIRECT("'"&試験名&"'!B"&ROW()-2))} -> 4 | AD6: =IF(W6="","",COUNTIF(AE6:AX6,"〇")/(COUNTA(T_受験者[])/4)) -> 0.16666667 | AE6: =IF($W6="","",IF(C6=$AC6,"〇","×")) -> × | AF6: =IF($W6="","",IF(D6=$AC6,"〇","×")) -> × | AG6: =IF($W6="","",IF(E6=$AC6,"〇","×")) -> × | AH6: =IF($W6="","",IF(F6=$AC6,"〇","×")) -> × | AI6: =IF($W6="","",IF(G6=$AC6,"〇","×")) -> × | AJ6: =IF($W6="","",IF(H6=$AC6,"〇","×")) -> × | AK6: =IF($W6="","",IF(I6=$AC6,"〇","×")) -> × | AL6: =IF($W6="","",IF(J6=$AC6,"〇","×")) -> × | ... AX6: =IF($W6="","",IF(V6=$AC6,"〇","×")) -> ×
A7: {=INDIRECT("'"&試験名&"'!A"&ROW()-2)} -> 文字語彙 | B7: =IF(A7="","",IF(A6=A7,B6+1,1)) -> 5 | E7: 2 | O7: 2 | P7: 2 | Q7: 2 | R7: 2 | V7: 2 | W7: =B7 -> 5 | X7: =IF(W7="","",COUNTIF($C7:$V7,X$2)) -> 0 | Y7: =IF(W7="","",COUNTIF($C7:$V7,Y$2)) -> 6 | Z7: =IF(W7="","",COUNTIF($C7:$V7,Z$2)) -> 0 | AA7: =IF(W7="","",COUNTIF($C7:$V7,AA$2)) -> 0 | AB7: =IF(W7="","",COUNTA(T_受験者[])/4-COUNTA($C7:$V7)) -> 0 | AC7: {=IF(W7="","",INDIRECT("'"&試験名&"'!B"&ROW()-2))} -> 2 | AD7: =IF(W7="","",COUNTIF(AE7:AX7,"〇")/(COUNTA(T_受験者[])/4)) -> 1 | AE7: =IF($W7="","",IF(C7=$AC7,"〇","×")) -> × | AF7: =IF($W7="","",IF(D7=$AC7,"〇","×")) -> × | AG7: =IF($W7="","",IF(E7=$AC7,"〇","×")) -> 〇 | AH7: =IF($W7="","",IF(F7=$AC7,"〇","×")) -> × | AI7: =IF($W7="","",IF(G7=$AC7,"〇","×")) -> × | AJ7: =IF($W7="","",IF(H7=$AC7,"〇","×")) -> × | AK7: =IF($W7="","",IF(I7=$AC7,"〇","×")) -> × | AL7: =IF($W7="","",IF(J7=$AC7,"〇","×")) -> × | ... AX7: =IF($W7="","",IF(V7=$AC7,"〇","×")) -> 〇
A8: {=INDIRECT("'"&試験名&"'!A"&ROW()-2)} -> 文字語彙 | B8: =IF(A8="","",IF(A7=A8,B7+1,1)) -> 6 | E8: 4 | O8: 3 | P8: 3 | Q8: 4 | R8: 3 | V8: 3 | W8: =B8 -> 6 | X8: =IF(W8="","",COUNTIF($C8:$V8,X$2)) -> 0 | Y8: =IF(W8="","",COUNTIF($C8:$V8,Y$2)) -> 0 | Z8: =IF(W8="","",COUNTIF($C8:$V8,Z$2)) -> 4 | AA8: =IF(W8="","",COUNTIF($C8:$V8,AA$2)) -> 2 | AB8: =IF(W8="","",COUNTA(T_受験者[])/4-COUNTA($C8:$V8)) -> 0 | AC8: {=IF(W8="","",INDIRECT("'"&試験名&"'!B"&ROW()-2))} -> 3 | AD8: =IF(W8="","",COUNTIF(AE8:AX8,"〇")/(COUNTA(T_受験者[])/4)) -> 0.66666667 | AE8: =IF($W8="","",IF(C8=$AC8,"〇","×")) -> × | AF8: =IF($W8="","",IF(D8=$AC8,"〇","×")) -> × | AG8: =IF($W8="","",IF(E8=$AC8,"〇","×")) -> × | AH8: =IF($W8="","",IF(F8=$AC8,"〇","×")) -> × | AI8: =IF($W8="","",IF(G8=$AC8,"〇","×")) -> × | AJ8: =IF($W8="","",IF(H8=$AC8,"〇","×")) -> × | AK8: =IF($W8="","",IF(I8=$AC8,"〇","×")) -> × | AL8: =IF($W8="","",IF(J8=$AC8,"〇","×")) -> × | ... AX8: =IF($W8="","",IF(V8=$AC8,"〇","×")) -> 〇
A9: {=INDIRECT("'"&試験名&"'!A"&ROW()-2)} -> 文字語彙 | B9: =IF(A9="","",IF(A8=A9,B8+1,1)) -> 7 | E9: 2 | O9: 1 | P9: 1 | Q9: 1 | R9: 1 | V9: 1 | W9: =B9 -> 7 | X9: =IF(W9="","",COUNTIF($C9:$V9,X$2)) -> 5 | Y9: =IF(W9="","",COUNTIF($C9:$V9,Y$2)) -> 1 | Z9: =IF(W9="","",COUNTIF($C9:$V9,Z$2)) -> 0 | AA9: =IF(W9="","",COUNTIF($C9:$V9,AA$2)) -> 0 | AB9: =IF(W9="","",COUNTA(T_受験者[])/4-COUNTA($C9:$V9)) -> 0 | AC9: {=IF(W9="","",INDIRECT("'"&試験名&"'!B"&ROW()-2))} -> 1 | AD9: =IF(W9="","",COUNTIF(AE9:AX9,"〇")/(COUNTA(T_受験者[])/4)) -> 0.83333333 | AE9: =IF($W9="","",IF(C9=$AC9,"〇","×")) -> × | AF9: =IF($W9="","",IF(D9=$AC9,"〇","×")) -> × | AG9: =IF($W9="","",IF(E9=$AC9,"〇","×")) -> × | AH9: =IF($W9="","",IF(F9=$AC9,"〇","×")) -> × | AI9: =IF($W9="","",IF(G9=$AC9,"〇","×")) -> × | AJ9: =IF($W9="","",IF(H9=$AC9,"〇","×")) -> × | AK9: =IF($W9="","",IF(I9=$AC9,"〇","×")) -> × | AL9: =IF($W9="","",IF(J9=$AC9,"〇","×")) -> × | ... AX9: =IF($W9="","",IF(V9=$AC9,"〇","×")) -> 〇
A10: {=INDIRECT("'"&試験名&"'!A"&ROW()-2)} -> 文字語彙 | B10: =IF(A10="","",IF(A9=A10,B9+1,1)) -> 8 | E10: 2 | O10: 2 | P10: 2 | Q10: 2 | R10: 2 | V10: 2 | W10: =B10 -> 8 | X10: =IF(W10="","",COUNTIF($C10:$V10,X$2)) -> 0 | Y10: =IF(W10="","",COUNTIF($C10:$V10,Y$2)) -> 6 | Z10: =IF(W10="","",COUNTIF($C10:$V10,Z$2)) -> 0 | AA10: =IF(W10="","",COUNTIF($C10:$V10,AA$2)) -> 0 | AB10: =IF(W10="","",COUNTA(T_受験者[])/4-COUNTA($C10:$V10)) -> 0 | AC10: {=IF(W10="","",INDIRECT("'"&試験名&"'!B"&ROW()-2))} -> 2 | AD10: =IF(W10="","",COUNTIF(AE10:AX10,"〇")/(COUNTA(T_受験者[])/4)) -> 1 | AE10: =IF($W10="","",IF(C10=$AC10,"〇","×")) -> × | AF10: =IF($W10="","",IF(D10=$AC10,"〇","×")) -> × | AG10: =IF($W10="","",IF(E10=$AC10,"〇","×")) -> 〇 | AH10: =IF($W10="","",IF(F10=$AC10,"〇","×")) -> × | AI10: =IF($W10="","",IF(G10=$AC10,"〇","×")) -> × | AJ10: =IF($W10="","",IF(H10=$AC10,"〇","×")) -> × | AK10: =IF($W10="","",IF(I10=$AC10,"〇","×")) -> × | AL10: =IF($W10="","",IF(J10=$AC10,"〇","×")) -> × | ... AX10: =IF($W10="","",IF(V10=$AC10,"〇","×")) -> 〇
A11: {=INDIRECT("'"&試験名&"'!A"&ROW()-2)} -> 文字語彙 | B11: =IF(A11="","",IF(A10=A11,B10+1,1)) -> 9 | E11: 1 | O11: 4 | P11: 1 | Q11: 2 | R11: 1 | V11: 2 | W11: =B11 -> 9 | X11: =IF(W11="","",COUNTIF($C11:$V11,X$2)) -> 3 | Y11: =IF(W11="","",COUNTIF($C11:$V11,Y$2)) -> 2 | Z11: =IF(W11="","",COUNTIF($C11:$V11,Z$2)) -> 0 | AA11: =IF(W11="","",COUNTIF($C11:$V11,AA$2)) -> 1 | AB11: =IF(W11="","",COUNTA(T_受験者[])/4-COUNTA($C11:$V11)) -> 0 | AC11: {=IF(W11="","",INDIRECT("'"&試験名&"'!B"&ROW()-2))} -> 1 | AD11: =IF(W11="","",COUNTIF(AE11:AX11,"〇")/(COUNTA(T_受験者[])/4)) -> 0.5 | AE11: =IF($W11="","",IF(C11=$AC11,"〇","×")) -> × | AF11: =IF($W11="","",IF(D11=$AC11,"〇","×")) -> × | AG11: =IF($W11="","",IF(E11=$AC11,"〇","×")) -> 〇 | AH11: =IF($W11="","",IF(F11=$AC11,"〇","×")) -> × | AI11: =IF($W11="","",IF(G11=$AC11,"〇","×")) -> × | AJ11: =IF($W11="","",IF(H11=$AC11,"〇","×")) -> × | AK11: =IF($W11="","",IF(I11=$AC11,"〇","×")) -> × | AL11: =IF($W11="","",IF(J11=$AC11,"〇","×")) -> × | ... AX11: =IF($W11="","",IF(V11=$AC11,"〇","×")) -> ×
A12: {=INDIRECT("'"&試験名&"'!A"&ROW()-2)} -> 文字語彙 | B12: =IF(A12="","",IF(A11=A12,B11+1,1)) -> 10 | E12: 4 | O12: 4 | P12: 4 | Q12: 4 | R12: 4 | V12: 4 | W12: =B12 -> 10 | X12: =IF(W12="","",COUNTIF($C12:$V12,X$2)) -> 0 | Y12: =IF(W12="","",COUNTIF($C12:$V12,Y$2)) -> 0 | Z12: =IF(W12="","",COUNTIF($C12:$V12,Z$2)) -> 0 | AA12: =IF(W12="","",COUNTIF($C12:$V12,AA$2)) -> 6 | AB12: =IF(W12="","",COUNTA(T_受験者[])/4-COUNTA($C12:$V12)) -> 0 | AC12: {=IF(W12="","",INDIRECT("'"&試験名&"'!B"&ROW()-2))} -> 4 | AD12: =IF(W12="","",COUNTIF(AE12:AX12,"〇")/(COUNTA(T_受験者[])/4)) -> 1 | AE12: =IF($W12="","",IF(C12=$AC12,"〇","×")) -> × | AF12: =IF($W12="","",IF(D12=$AC12,"〇","×")) -> × | AG12: =IF($W12="","",IF(E12=$AC12,"〇","×")) -> 〇 | AH12: =IF($W12="","",IF(F12=$AC12,"〇","×")) -> × | AI12: =IF($W12="","",IF(G12=$AC12,"〇","×")) -> × | AJ12: =IF($W12="","",IF(H12=$AC12,"〇","×")) -> × | AK12: =IF($W12="","",IF(I12=$AC12,"〇","×")) -> × | AL12: =IF($W12="","",IF(J12=$AC12,"〇","×")) -> × | ... AX12: =IF($W12="","",IF(V12=$AC12,"〇","×")) -> 〇
A13: {=INDIRECT("'"&試験名&"'!A"&ROW()-2)} -> 文字語彙 | B13: =IF(A13="","",IF(A12=A13,B12+1,1)) -> 11 | E13: 1 | O13: 4 | P13: 2 | Q13: 2 | R13: 3 | V13: 1 | W13: =B13 -> 11 | X13: =IF(W13="","",COUNTIF($C13:$V13,X$2)) -> 2 | Y13: =IF(W13="","",COUNTIF($C13:$V13,Y$2)) -> 2 | Z13: =IF(W13="","",COUNTIF($C13:$V13,Z$2)) -> 1 | AA13: =IF(W13="","",COUNTIF($C13:$V13,AA$2)) -> 1 | AB13: =IF(W13="","",COUNTA(T_受験者[])/4-COUNTA($C13:$V13)) -> 0 | AC13: {=IF(W13="","",INDIRECT("'"&試験名&"'!B"&ROW()-2))} -> 1 | AD13: =IF(W13="","",COUNTIF(AE13:AX13,"〇")/(COUNTA(T_受験者[])/4)) -> 0.33333333 | AE13: =IF($W13="","",IF(C13=$AC13,"〇","×")) -> × | AF13: =IF($W13="","",IF(D13=$AC13,"〇","×")) -> × | AG13: =IF($W13="","",IF(E13=$AC13,"〇","×")) -> 〇 | AH13: =IF($W13="","",IF(F13=$AC13,"〇","×")) -> × | AI13: =IF($W13="","",IF(G13=$AC13,"〇","×")) -> × | AJ13: =IF($W13="","",IF(H13=$AC13,"〇","×")) -> × | AK13: =IF($W13="","",IF(I13=$AC13,"〇","×")) -> × | AL13: =IF($W13="","",IF(J13=$AC13,"〇","×")) -> × | ... AX13: =IF($W13="","",IF(V13=$AC13,"〇","×")) -> 〇
A14: {=INDIRECT("'"&試験名&"'!A"&ROW()-2)} -> 文字語彙 | B14: =IF(A14="","",IF(A13=A14,B13+1,1)) -> 12 | E14: 3 | O14: 2 | P14: 1 | Q14: 2 | R14: 2 | V14: 1 | W14: =B14 -> 12 | X14: =IF(W14="","",COUNTIF($C14:$V14,X$2)) -> 2 | Y14: =IF(W14="","",COUNTIF($C14:$V14,Y$2)) -> 3 | Z14: =IF(W14="","",COUNTIF($C14:$V14,Z$2)) -> 1 | AA14: =IF(W14="","",COUNTIF($C14:$V14,AA$2)) -> 0 | AB14: =IF(W14="","",COUNTA(T_受験者[])/4-COUNTA($C14:$V14)) -> 0 | AC14: {=IF(W14="","",INDIRECT("'"&試験名&"'!B"&ROW()-2))} -> 1 | AD14: =IF(W14="","",COUNTIF(AE14:AX14,"〇")/(COUNTA(T_受験者[])/4)) -> 0.33333333 | AE14: =IF($W14="","",IF(C14=$AC14,"〇","×")) -> × | AF14: =IF($W14="","",IF(D14=$AC14,"〇","×")) -> × | AG14: =IF($W14="","",IF(E14=$AC14,"〇","×")) -> × | AH14: =IF($W14="","",IF(F14=$AC14,"〇","×")) -> × | AI14: =IF($W14="","",IF(G14=$AC14,"〇","×")) -> × | AJ14: =IF($W14="","",IF(H14=$AC14,"〇","×")) -> × | AK14: =IF($W14="","",IF(I14=$AC14,"〇","×")) -> × | AL14: =IF($W14="","",IF(J14=$AC14,"〇","×")) -> × | ... AX14: =IF($W14="","",IF(V14=$AC14,"〇","×")) -> 〇
A15: {=INDIRECT("'"&試験名&"'!A"&ROW()-2)} -> 文字語彙 | B15: =IF(A15="","",IF(A14=A15,B14+1,1)) -> 13 | E15: 4 | O15: 4 | P15: 4 | Q15: 4 | R15: 4 | V15: 4 | W15: =B15 -> 13 | X15: =IF(W15="","",COUNTIF($C15:$V15,X$2)) -> 0 | Y15: =IF(W15="","",COUNTIF($C15:$V15,Y$2)) -> 0 | Z15: =IF(W15="","",COUNTIF($C15:$V15,Z$2)) -> 0 | AA15: =IF(W15="","",COUNTIF($C15:$V15,AA$2)) -> 6 | AB15: =IF(W15="","",COUNTA(T_受験者[])/4-COUNTA($C15:$V15)) -> 0 | AC15: {=IF(W15="","",INDIRECT("'"&試験名&"'!B"&ROW()-2))} -> 4 | AD15: =IF(W15="","",COUNTIF(AE15:AX15,"〇")/(COUNTA(T_受験者[])/4)) -> 1 | AE15: =IF($W15="","",IF(C15=$AC15,"〇","×")) -> × | AF15: =IF($W15="","",IF(D15=$AC15,"〇","×")) -> × | AG15: =IF($W15="","",IF(E15=$AC15,"〇","×")) -> 〇 | AH15: =IF($W15="","",IF(F15=$AC15,"〇","×")) -> × | AI15: =IF($W15="","",IF(G15=$AC15,"〇","×")) -> × | AJ15: =IF($W15="","",IF(H15=$AC15,"〇","×")) -> × | AK15: =IF($W15="","",IF(I15=$AC15,"〇","×")) -> × | AL15: =IF($W15="","",IF(J15=$AC15,"〇","×")) -> × | ... AX15: =IF($W15="","",IF(V15=$AC15,"〇","×")) -> 〇
A16: {=INDIRECT("'"&試験名&"'!A"&ROW()-2)} -> 文字語彙 | B16: =IF(A16="","",IF(A15=A16,B15+1,1)) -> 14 | E16: 1 | O16: 3 | P16: 2 | Q16: 4 | R16: 3 | V16: 2 | W16: =B16 -> 14 | X16: =IF(W16="","",COUNTIF($C16:$V16,X$2)) -> 1 | Y16: =IF(W16="","",COUNTIF($C16:$V16,Y$2)) -> 2 | Z16: =IF(W16="","",COUNTIF($C16:$V16,Z$2)) -> 2 | AA16: =IF(W16="","",COUNTIF($C16:$V16,AA$2)) -> 1 | AB16: =IF(W16="","",COUNTA(T_受験者[])/4-COUNTA($C16:$V16)) -> 0 | AC16: {=IF(W16="","",INDIRECT("'"&試験名&"'!B"&ROW()-2))} -> 2 | AD16: =IF(W16="","",COUNTIF(AE16:AX16,"〇")/(COUNTA(T_受験者[])/4)) -> 0.33333333 | AE16: =IF($W16="","",IF(C16=$AC16,"〇","×")) -> × | AF16: =IF($W16="","",IF(D16=$AC16,"〇","×")) -> × | AG16: =IF($W16="","",IF(E16=$AC16,"〇","×")) -> × | AH16: =IF($W16="","",IF(F16=$AC16,"〇","×")) -> × | AI16: =IF($W16="","",IF(G16=$AC16,"〇","×")) -> × | AJ16: =IF($W16="","",IF(H16=$AC16,"〇","×")) -> × | AK16: =IF($W16="","",IF(I16=$AC16,"〇","×")) -> × | AL16: =IF($W16="","",IF(J16=$AC16,"〇","×")) -> × | ... AX16: =IF($W16="","",IF(V16=$AC16,"〇","×")) -> 〇
A17: {=INDIRECT("'"&試験名&"'!A"&ROW()-2)} -> 文字語彙 | B17: =IF(A17="","",IF(A16=A17,B16+1,1)) -> 15 | E17: 2 | O17: 2 | P17: 1 | Q17: 2 | R17: 2 | V17: 4 | W17: =B17 -> 15 | X17: =IF(W17="","",COUNTIF($C17:$V17,X$2)) -> 1 | Y17: =IF(W17="","",COUNTIF($C17:$V17,Y$2)) -> 4 | Z17: =IF(W17="","",COUNTIF($C17:$V17,Z$2)) -> 0 | AA17: =IF(W17="","",COUNTIF($C17:$V17,AA$2)) -> 1 | AB17: =IF(W17="","",COUNTA(T_受験者[])/4-COUNTA($C17:$V17)) -> 0 | AC17: {=IF(W17="","",INDIRECT("'"&試験名&"'!B"&ROW()-2))} -> 1 | AD17: =IF(W17="","",COUNTIF(AE17:AX17,"〇")/(COUNTA(T_受験者[])/4)) -> 0.16666667 | AE17: =IF($W17="","",IF(C17=$AC17,"〇","×")) -> × | AF17: =IF($W17="","",IF(D17=$AC17,"〇","×")) -> × | AG17: =IF($W17="","",IF(E17=$AC17,"〇","×")) -> × | AH17: =IF($W17="","",IF(F17=$AC17,"〇","×")) -> × | AI17: =IF($W17="","",IF(G17=$AC17,"〇","×")) -> × | AJ17: =IF($W17="","",IF(H17=$AC17,"〇","×")) -> × | AK17: =IF($W17="","",IF(I17=$AC17,"〇","×")) -> × | AL17: =IF($W17="","",IF(J17=$AC17,"〇","×")) -> × | ... AX17: =IF($W17="","",IF(V17=$AC17,"〇","×")) -> ×
A18: {=INDIRECT("'"&試験名&"'!A"&ROW()-2)} -> 文字語彙 | B18: =IF(A18="","",IF(A17=A18,B17+1,1)) -> 16 | E18: 1 | O18: 3 | P18: 3 | Q18: 1 | R18: 1 | V18: 1 | W18: =B18 -> 16 | X18: =IF(W18="","",COUNTIF($C18:$V18,X$2)) -> 4 | Y18: =IF(W18="","",COUNTIF($C18:$V18,Y$2)) -> 0 | Z18: =IF(W18="","",COUNTIF($C18:$V18,Z$2)) -> 2 | AA18: =IF(W18="","",COUNTIF($C18:$V18,AA$2)) -> 0 | AB18: =IF(W18="","",COUNTA(T_受験者[])/4-COUNTA($C18:$V18)) -> 0 | AC18: {=IF(W18="","",INDIRECT("'"&試験名&"'!B"&ROW()-2))} -> 1 | AD18: =IF(W18="","",COUNTIF(AE18:AX18,"〇")/(COUNTA(T_受験者[])/4)) -> 0.66666667 | AE18: =IF($W18="","",IF(C18=$AC18,"〇","×")) -> × | AF18: =IF($W18="","",IF(D18=$AC18,"〇","×")) -> × | AG18: =IF($W18="","",IF(E18=$AC18,"〇","×")) -> 〇 | AH18: =IF($W18="","",IF(F18=$AC18,"〇","×")) -> × | AI18: =IF($W18="","",IF(G18=$AC18,"〇","×")) -> × | AJ18: =IF($W18="","",IF(H18=$AC18,"〇","×")) -> × | AK18: =IF($W18="","",IF(I18=$AC18,"〇","×")) -> × | AL18: =IF($W18="","",IF(J18=$AC18,"〇","×")) -> × | ... AX18: =IF($W18="","",IF(V18=$AC18,"〇","×")) -> 〇
... A59: {=INDIRECT("'"&試験名&"'!A"&ROW()-2)} -> 文法 | B59: =IF(A59="","",IF(A58=A59,B58+1,1)) -> 23 | E59: 1 | O59: 2 | P59: 1 | Q59: 4 | R59: 1 | V59: 4 | W59: =B59 -> 23 | X59: =IF(W59="","",COUNTIF($C59:$V59,X$2)) -> 3 | Y59: =IF(W59="","",COUNTIF($C59:$V59,Y$2)) -> 1 | Z59: =IF(W59="","",COUNTIF($C59:$V59,Z$2)) -> 0 | AA59: =IF(W59="","",COUNTIF($C59:$V59,AA$2)) -> 2 | AB59: =IF(W59="","",COUNTA(T_受験者[])/4-COUNTA($C59:$V59)) -> 0 | AC59: {=IF(W59="","",INDIRECT("'"&試験名&"'!B"&ROW()-2))} -> 1 | AD59: =IF(W59="","",COUNTIF(AE59:AX59,"〇")/(COUNTA(T_受験者[])/4)) -> 0.5 | AE59: =IF($W59="","",IF(C59=$AC59,"〇","×")) -> × | AF59: =IF($W59="","",IF(D59=$AC59,"〇","×")) -> × | AG59: =IF($W59="","",IF(E59=$AC59,"〇","×")) -> 〇 | AH59: =IF($W59="","",IF(F59=$AC59,"〇","×")) -> × | AI59: =IF($W59="","",IF(G59=$AC59,"〇","×")) -> × | AJ59: =IF($W59="","",IF(H59=$AC59,"〇","×")) -> × | AK59: =IF($W59="","",IF(I59=$AC59,"〇","×")) -> × | AL59: =IF($W59="","",IF(J59=$AC59,"〇","×")) -> × | ... AX59: =IF($W59="","",IF(V59=$AC59,"〇","×")) -> ×
A60: {=INDIRECT("'"&試験名&"'!A"&ROW()-2)} -> 文法 | B60: =IF(A60="","",IF(A59=A60,B59+1,1)) -> 24 | E60: 2 | O60: 3 | P60: 2 | Q60: 2 | R60: 2 | W60: =B60 -> 24 | X60: =IF(W60="","",COUNTIF($C60:$V60,X$2)) -> 0 | Y60: =IF(W60="","",COUNTIF($C60:$V60,Y$2)) -> 4 | Z60: =IF(W60="","",COUNTIF($C60:$V60,Z$2)) -> 1 | AA60: =IF(W60="","",COUNTIF($C60:$V60,AA$2)) -> 0 | AB60: =IF(W60="","",COUNTA(T_受験者[])/4-COUNTA($C60:$V60)) -> 1 | AC60: {=IF(W60="","",INDIRECT("'"&試験名&"'!B"&ROW()-2))} -> 2 | AD60: =IF(W60="","",COUNTIF(AE60:AX60,"〇")/(COUNTA(T_受験者[])/4)) -> 0.66666667 | AE60: =IF($W60="","",IF(C60=$AC60,"〇","×")) -> × | AF60: =IF($W60="","",IF(D60=$AC60,"〇","×")) -> × | AG60: =IF($W60="","",IF(E60=$AC60,"〇","×")) -> 〇 | AH60: =IF($W60="","",IF(F60=$AC60,"〇","×")) -> × | AI60: =IF($W60="","",IF(G60=$AC60,"〇","×")) -> × | AJ60: =IF($W60="","",IF(H60=$AC60,"〇","×")) -> × | AK60: =IF($W60="","",IF(I60=$AC60,"〇","×")) -> × | AL60: =IF($W60="","",IF(J60=$AC60,"〇","×")) -> × | ... AX60: =IF($W60="","",IF(V60=$AC60,"〇","×")) -> ×
A61: {=INDIRECT("'"&試験名&"'!A"&ROW()-2)} -> 文法 | B61: =IF(A61="","",IF(A60=A61,B60+1,1)) -> 25 | E61: 4 | O61: 4 | P61: 1 | Q61: 3 | R61: 1 | V61: 1 | W61: =B61 -> 25 | X61: =IF(W61="","",COUNTIF($C61:$V61,X$2)) -> 3 | Y61: =IF(W61="","",COUNTIF($C61:$V61,Y$2)) -> 0 | Z61: =IF(W61="","",COUNTIF($C61:$V61,Z$2)) -> 1 | AA61: =IF(W61="","",COUNTIF($C61:$V61,AA$2)) -> 2 | AB61: =IF(W61="","",COUNTA(T_受験者[])/4-COUNTA($C61:$V61)) -> 0 | AC61: {=IF(W61="","",INDIRECT("'"&試験名&"'!B"&ROW()-2))} -> 3 | AD61: =IF(W61="","",COUNTIF(AE61:AX61,"〇")/(COUNTA(T_受験者[])/4)) -> 0.16666667 | AE61: =IF($W61="","",IF(C61=$AC61,"〇","×")) -> × | AF61: =IF($W61="","",IF(D61=$AC61,"〇","×")) -> × | AG61: =IF($W61="","",IF(E61=$AC61,"〇","×")) -> × | AH61: =IF($W61="","",IF(F61=$AC61,"〇","×")) -> × | AI61: =IF($W61="","",IF(G61=$AC61,"〇","×")) -> × | AJ61: =IF($W61="","",IF(H61=$AC61,"〇","×")) -> × | AK61: =IF($W61="","",IF(I61=$AC61,"〇","×")) -> × | AL61: =IF($W61="","",IF(J61=$AC61,"〇","×")) -> × | ... AX61: =IF($W61="","",IF(V61=$AC61,"〇","×")) -> ×
A62: {=INDIRECT("'"&試験名&"'!A"&ROW()-2)} -> 読解 | B62: =IF(A62="","",IF(A61=A62,B61+1,1)) -> 1 | E62: 3 | O62: 4 | P62: 4 | Q62: 4 | R62: 1 | V62: 4 | W62: =B62 -> 1 | X62: =IF(W62="","",COUNTIF($C62:$V62,X$2)) -> 1 | Y62: =IF(W62="","",COUNTIF($C62:$V62,Y$2)) -> 0 | Z62: =IF(W62="","",COUNTIF($C62:$V62,Z$2)) -> 1 | AA62: =IF(W62="","",COUNTIF($C62:$V62,AA$2)) -> 4 | AB62: =IF(W62="","",COUNTA(T_受験者[])/4-COUNTA($C62:$V62)) -> 0 | AC62: {=IF(W62="","",INDIRECT("'"&試験名&"'!B"&ROW()-2))} -> 1 | AD62: =IF(W62="","",COUNTIF(AE62:AX62,"〇")/(COUNTA(T_受験者[])/4)) -> 0.16666667 | AE62: =IF($W62="","",IF(C62=$AC62,"〇","×")) -> × | AF62: =IF($W62="","",IF(D62=$AC62,"〇","×")) -> × | AG62: =IF($W62="","",IF(E62=$AC62,"〇","×")) -> × | AH62: =IF($W62="","",IF(F62=$AC62,"〇","×")) -> × | AI62: =IF($W62="","",IF(G62=$AC62,"〇","×")) -> × | AJ62: =IF($W62="","",IF(H62=$AC62,"〇","×")) -> × | AK62: =IF($W62="","",IF(I62=$AC62,"〇","×")) -> × | AL62: =IF($W62="","",IF(J62=$AC62,"〇","×")) -> × | ... AX62: =IF($W62="","",IF(V62=$AC62,"〇","×")) -> ×
A63: {=INDIRECT("'"&試験名&"'!A"&ROW()-2)} -> 読解 | B63: =IF(A63="","",IF(A62=A63,B62+1,1)) -> 2 | E63: 1 | O63: 4 | P63: 1 | Q63: 3 | R63: 4 | V63: 2 | W63: =B63 -> 2 | X63: =IF(W63="","",COUNTIF($C63:$V63,X$2)) -> 2 | Y63: =IF(W63="","",COUNTIF($C63:$V63,Y$2)) -> 1 | Z63: =IF(W63="","",COUNTIF($C63:$V63,Z$2)) -> 1 | AA63: =IF(W63="","",COUNTIF($C63:$V63,AA$2)) -> 2 | AB63: =IF(W63="","",COUNTA(T_受験者[])/4-COUNTA($C63:$V63)) -> 0 | AC63: {=IF(W63="","",INDIRECT("'"&試験名&"'!B"&ROW()-2))} -> 4 | AD63: =IF(W63="","",COUNTIF(AE63:AX63,"〇")/(COUNTA(T_受験者[])/4)) -> 0.33333333 | AE63: =IF($W63="","",IF(C63=$AC63,"〇","×")) -> × | AF63: =IF($W63="","",IF(D63=$AC63,"〇","×")) -> × | AG63: =IF($W63="","",IF(E63=$AC63,"〇","×")) -> × | AH63: =IF($W63="","",IF(F63=$AC63,"〇","×")) -> × | AI63: =IF($W63="","",IF(G63=$AC63,"〇","×")) -> × | AJ63: =IF($W63="","",IF(H63=$AC63,"〇","×")) -> × | AK63: =IF($W63="","",IF(I63=$AC63,"〇","×")) -> × | AL63: =IF($W63="","",IF(J63=$AC63,"〇","×")) -> × | ... AX63: =IF($W63="","",IF(V63=$AC63,"〇","×")) -> ×
A64: {=INDIRECT("'"&試験名&"'!A"&ROW()-2)} -> 読解 | B64: =IF(A64="","",IF(A63=A64,B63+1,1)) -> 3 | E64: 2 | O64: 2 | P64: 4 | Q64: 2 | R64: 2 | V64: 1 | W64: =B64 -> 3 | X64: =IF(W64="","",COUNTIF($C64:$V64,X$2)) -> 1 | Y64: =IF(W64="","",COUNTIF($C64:$V64,Y$2)) -> 4 | Z64: =IF(W64="","",COUNTIF($C64:$V64,Z$2)) -> 0 | AA64: =IF(W64="","",COUNTIF($C64:$V64,AA$2)) -> 1 | AB64: =IF(W64="","",COUNTA(T_受験者[])/4-COUNTA($C64:$V64)) -> 0 | AC64: {=IF(W64="","",INDIRECT("'"&試験名&"'!B"&ROW()-2))} -> 2 | AD64: =IF(W64="","",COUNTIF(AE64:AX64,"〇")/(COUNTA(T_受験者[])/4)) -> 0.66666667 | AE64: =IF($W64="","",IF(C64=$AC64,"〇","×")) -> × | AF64: =IF($W64="","",IF(D64=$AC64,"〇","×")) -> × | AG64: =IF($W64="","",IF(E64=$AC64,"〇","×")) -> 〇 | AH64: =IF($W64="","",IF(F64=$AC64,"〇","×")) -> × | AI64: =IF($W64="","",IF(G64=$AC64,"〇","×")) -> × | AJ64: =IF($W64="","",IF(H64=$AC64,"〇","×")) -> × | AK64: =IF($W64="","",IF(I64=$AC64,"〇","×")) -> × | AL64: =IF($W64="","",IF(J64=$AC64,"〇","×")) -> × | ... AX64: =IF($W64="","",IF(V64=$AC64,"〇","×")) -> ×
A65: {=INDIRECT("'"&試験名&"'!A"&ROW()-2)} -> 読解 | B65: =IF(A65="","",IF(A64=A65,B64+1,1)) -> 4 | E65: 2 | O65: 4 | P65: 4 | Q65: 3 | R65: 3 | V65: 2 | W65: =B65 -> 4 | X65: =IF(W65="","",COUNTIF($C65:$V65,X$2)) -> 0 | Y65: =IF(W65="","",COUNTIF($C65:$V65,Y$2)) -> 2 | Z65: =IF(W65="","",COUNTIF($C65:$V65,Z$2)) -> 2 | AA65: =IF(W65="","",COUNTIF($C65:$V65,AA$2)) -> 2 | AB65: =IF(W65="","",COUNTA(T_受験者[])/4-COUNTA($C65:$V65)) -> 0 | AC65: {=IF(W65="","",INDIRECT("'"&試験名&"'!B"&ROW()-2))} -> 2 | AD65: =IF(W65="","",COUNTIF(AE65:AX65,"〇")/(COUNTA(T_受験者[])/4)) -> 0.33333333 | AE65: =IF($W65="","",IF(C65=$AC65,"〇","×")) -> × | AF65: =IF($W65="","",IF(D65=$AC65,"〇","×")) -> × | AG65: =IF($W65="","",IF(E65=$AC65,"〇","×")) -> 〇 | AH65: =IF($W65="","",IF(F65=$AC65,"〇","×")) -> × | AI65: =IF($W65="","",IF(G65=$AC65,"〇","×")) -> × | AJ65: =IF($W65="","",IF(H65=$AC65,"〇","×")) -> × | AK65: =IF($W65="","",IF(I65=$AC65,"〇","×")) -> × | AL65: =IF($W65="","",IF(J65=$AC65,"〇","×")) -> × | ... AX65: =IF($W65="","",IF(V65=$AC65,"〇","×")) -> 〇
A66: {=INDIRECT("'"&試験名&"'!A"&ROW()-2)} -> 読解 | B66: =IF(A66="","",IF(A65=A66,B65+1,1)) -> 5 | E66: 1 | O66: 1 | P66: 2 | Q66: 3 | R66: 2 | V66: 2 | W66: =B66 -> 5 | X66: =IF(W66="","",COUNTIF($C66:$V66,X$2)) -> 2 | Y66: =IF(W66="","",COUNTIF($C66:$V66,Y$2)) -> 3 | Z66: =IF(W66="","",COUNTIF($C66:$V66,Z$2)) -> 1 | AA66: =IF(W66="","",COUNTIF($C66:$V66,AA$2)) -> 0 | AB66: =IF(W66="","",COUNTA(T_受験者[])/4-COUNTA($C66:$V66)) -> 0 | AC66: {=IF(W66="","",INDIRECT("'"&試験名&"'!B"&ROW()-2))} -> 4 | AD66: =IF(W66="","",COUNTIF(AE66:AX66,"〇")/(COUNTA(T_受験者[])/4)) -> 0 | AE66: =IF($W66="","",IF(C66=$AC66,"〇","×")) -> × | AF66: =IF($W66="","",IF(D66=$AC66,"〇","×")) -> × | AG66: =IF($W66="","",IF(E66=$AC66,"〇","×")) -> × | AH66: =IF($W66="","",IF(F66=$AC66,"〇","×")) -> × | AI66: =IF($W66="","",IF(G66=$AC66,"〇","×")) -> × | AJ66: =IF($W66="","",IF(H66=$AC66,"〇","×")) -> × | AK66: =IF($W66="","",IF(I66=$AC66,"〇","×")) -> × | AL66: =IF($W66="","",IF(J66=$AC66,"〇","×")) -> × | ... AX66: =IF($W66="","",IF(V66=$AC66,"〇","×")) -> ×
A67: {=INDIRECT("'"&試験名&"'!A"&ROW()-2)} -> 読解 | B67: =IF(A67="","",IF(A66=A67,B66+1,1)) -> 6 | E67: 3 | O67: 2 | P67: 4 | Q67: 2 | R67: 4 | V67: 1 | W67: =B67 -> 6 | X67: =IF(W67="","",COUNTIF($C67:$V67,X$2)) -> 1 | Y67: =IF(W67="","",COUNTIF($C67:$V67,Y$2)) -> 2 | Z67: =IF(W67="","",COUNTIF($C67:$V67,Z$2)) -> 1 | AA67: =IF(W67="","",COUNTIF($C67:$V67,AA$2)) -> 2 | AB67: =IF(W67="","",COUNTA(T_受験者[])/4-COUNTA($C67:$V67)) -> 0 | AC67: {=IF(W67="","",INDIRECT("'"&試験名&"'!B"&ROW()-2))} -> 1 | AD67: =IF(W67="","",COUNTIF(AE67:AX67,"〇")/(COUNTA(T_受験者[])/4)) -> 0.16666667 | AE67: =IF($W67="","",IF(C67=$AC67,"〇","×")) -> × | AF67: =IF($W67="","",IF(D67=$AC67,"〇","×")) -> × | AG67: =IF($W67="","",IF(E67=$AC67,"〇","×")) -> × | AH67: =IF($W67="","",IF(F67=$AC67,"〇","×")) -> × | AI67: =IF($W67="","",IF(G67=$AC67,"〇","×")) -> × | AJ67: =IF($W67="","",IF(H67=$AC67,"〇","×")) -> × | AK67: =IF($W67="","",IF(I67=$AC67,"〇","×")) -> × | AL67: =IF($W67="","",IF(J67=$AC67,"〇","×")) -> × | ... AX67: =IF($W67="","",IF(V67=$AC67,"〇","×")) -> 〇
A68: {=INDIRECT("'"&試験名&"'!A"&ROW()-2)} -> 読解 | B68: =IF(A68="","",IF(A67=A68,B67+1,1)) -> 7 | E68: 4 | O68: 4 | P68: 4 | Q68: 4 | R68: 1 | V68: 3 | W68: =B68 -> 7 | X68: =IF(W68="","",COUNTIF($C68:$V68,X$2)) -> 1 | Y68: =IF(W68="","",COUNTIF($C68:$V68,Y$2)) -> 0 | Z68: =IF(W68="","",COUNTIF($C68:$V68,Z$2)) -> 1 | AA68: =IF(W68="","",COUNTIF($C68:$V68,AA$2)) -> 4 | AB68: =IF(W68="","",COUNTA(T_受験者[])/4-COUNTA($C68:$V68)) -> 0 | AC68: {=IF(W68="","",INDIRECT("'"&試験名&"'!B"&ROW()-2))} -> 4 | AD68: =IF(W68="","",COUNTIF(AE68:AX68,"〇")/(COUNTA(T_受験者[])/4)) -> 0.66666667 | AE68: =IF($W68="","",IF(C68=$AC68,"〇","×")) -> × | AF68: =IF($W68="","",IF(D68=$AC68,"〇","×")) -> × | AG68: =IF($W68="","",IF(E68=$AC68,"〇","×")) -> 〇 | AH68: =IF($W68="","",IF(F68=$AC68,"〇","×")) -> × | AI68: =IF($W68="","",IF(G68=$AC68,"〇","×")) -> × | AJ68: =IF($W68="","",IF(H68=$AC68,"〇","×")) -> × | AK68: =IF($W68="","",IF(I68=$AC68,"〇","×")) -> × | AL68: =IF($W68="","",IF(J68=$AC68,"〇","×")) -> × | ... AX68: =IF($W68="","",IF(V68=$AC68,"〇","×")) -> ×
A69: {=INDIRECT("'"&試験名&"'!A"&ROW()-2)} -> 読解 | B69: =IF(A69="","",IF(A68=A69,B68+1,1)) -> 8 | E69: 2 | O69: 1 | P69: 3 | Q69: 4 | R69: 3 | V69: 2 | W69: =B69 -> 8 | X69: =IF(W69="","",COUNTIF($C69:$V69,X$2)) -> 1 | Y69: =IF(W69="","",COUNTIF($C69:$V69,Y$2)) -> 2 | Z69: =IF(W69="","",COUNTIF($C69:$V69,Z$2)) -> 2 | AA69: =IF(W69="","",COUNTIF($C69:$V69,AA$2)) -> 1 | AB69: =IF(W69="","",COUNTA(T_受験者[])/4-COUNTA($C69:$V69)) -> 0 | AC69: {=IF(W69="","",INDIRECT("'"&試験名&"'!B"&ROW()-2))} -> 3 | AD69: =IF(W69="","",COUNTIF(AE69:AX69,"〇")/(COUNTA(T_受験者[])/4)) -> 0.33333333 | AE69: =IF($W69="","",IF(C69=$AC69,"〇","×")) -> × | AF69: =IF($W69="","",IF(D69=$AC69,"〇","×")) -> × | AG69: =IF($W69="","",IF(E69=$AC69,"〇","×")) -> × | AH69: =IF($W69="","",IF(F69=$AC69,"〇","×")) -> × | AI69: =IF($W69="","",IF(G69=$AC69,"〇","×")) -> × | AJ69: =IF($W69="","",IF(H69=$AC69,"〇","×")) -> × | AK69: =IF($W69="","",IF(I69=$AC69,"〇","×")) -> × | AL69: =IF($W69="","",IF(J69=$AC69,"〇","×")) -> × | ... AX69: =IF($W69="","",IF(V69=$AC69,"〇","×")) -> ×
A70: {=INDIRECT("'"&試験名&"'!A"&ROW()-2)} -> 読解 | B70: =IF(A70="","",IF(A69=A70,B69+1,1)) -> 9 | E70: 2 | O70: 4 | P70: 4 | Q70: 1 | R70: 2 | V70: 1 | W70: =B70 -> 9 | X70: =IF(W70="","",COUNTIF($C70:$V70,X$2)) -> 2 | Y70: =IF(W70="","",COUNTIF($C70:$V70,Y$2)) -> 2 | Z70: =IF(W70="","",COUNTIF($C70:$V70,Z$2)) -> 0 | AA70: =IF(W70="","",COUNTIF($C70:$V70,AA$2)) -> 2 | AB70: =IF(W70="","",COUNTA(T_受験者[])/4-COUNTA($C70:$V70)) -> 0 | AC70: {=IF(W70="","",INDIRECT("'"&試験名&"'!B"&ROW()-2))} -> 1 | AD70: =IF(W70="","",COUNTIF(AE70:AX70,"〇")/(COUNTA(T_受験者[])/4)) -> 0.33333333 | AE70: =IF($W70="","",IF(C70=$AC70,"〇","×")) -> × | AF70: =IF($W70="","",IF(D70=$AC70,"〇","×")) -> × | AG70: =IF($W70="","",IF(E70=$AC70,"〇","×")) -> × | AH70: =IF($W70="","",IF(F70=$AC70,"〇","×")) -> × | AI70: =IF($W70="","",IF(G70=$AC70,"〇","×")) -> × | AJ70: =IF($W70="","",IF(H70=$AC70,"〇","×")) -> × | AK70: =IF($W70="","",IF(I70=$AC70,"〇","×")) -> × | AL70: =IF($W70="","",IF(J70=$AC70,"〇","×")) -> × | ... AX70: =IF($W70="","",IF(V70=$AC70,"〇","×")) -> 〇
A71: {=INDIRECT("'"&試験名&"'!A"&ROW()-2)} -> 読解 | B71: =IF(A71="","",IF(A70=A71,B70+1,1)) -> 10 | E71: 1 | O71: 3 | P71: 4 | Q71: 3 | R71: 4 | V71: 3 | W71: =B71 -> 10 | X71: =IF(W71="","",COUNTIF($C71:$V71,X$2)) -> 1 | Y71: =IF(W71="","",COUNTIF($C71:$V71,Y$2)) -> 0 | Z71: =IF(W71="","",COUNTIF($C71:$V71,Z$2)) -> 3 | AA71: =IF(W71="","",COUNTIF($C71:$V71,AA$2)) -> 2 | AB71: =IF(W71="","",COUNTA(T_受験者[])/4-COUNTA($C71:$V71)) -> 0 | AC71: {=IF(W71="","",INDIRECT("'"&試験名&"'!B"&ROW()-2))} -> 4 | AD71: =IF(W71="","",COUNTIF(AE71:AX71,"〇")/(COUNTA(T_受験者[])/4)) -> 0.33333333 | AE71: =IF($W71="","",IF(C71=$AC71,"〇","×")) -> × | AF71: =IF($W71="","",IF(D71=$AC71,"〇","×")) -> × | AG71: =IF($W71="","",IF(E71=$AC71,"〇","×")) -> × | AH71: =IF($W71="","",IF(F71=$AC71,"〇","×")) -> × | AI71: =IF($W71="","",IF(G71=$AC71,"〇","×")) -> × | AJ71: =IF($W71="","",IF(H71=$AC71,"〇","×")) -> × | AK71: =IF($W71="","",IF(I71=$AC71,"〇","×")) -> × | AL71: =IF($W71="","",IF(J71=$AC71,"〇","×")) -> × | ... AX71: =IF($W71="","",IF(V71=$AC71,"〇","×")) -> ×
A72: {=INDIRECT("'"&試験名&"'!A"&ROW()-2)} -> 聴解 | B72: =IF(A72="","",IF(A71=A72,B71+1,1)) -> 1 | E72: 2 | O72: 1 | P72: 2 | Q72: 2 | R72: 2 | V72: 2 | W72: =B72 -> 1 | X72: =IF(W72="","",COUNTIF($C72:$V72,X$2)) -> 1 | Y72: =IF(W72="","",COUNTIF($C72:$V72,Y$2)) -> 5 | Z72: =IF(W72="","",COUNTIF($C72:$V72,Z$2)) -> 0 | AA72: =IF(W72="","",COUNTIF($C72:$V72,AA$2)) -> 0 | AB72: =IF(W72="","",COUNTA(T_受験者[])/4-COUNTA($C72:$V72)) -> 0 | AC72: {=IF(W72="","",INDIRECT("'"&試験名&"'!B"&ROW()-2))} -> 2 | AD72: =IF(W72="","",COUNTIF(AE72:AX72,"〇")/(COUNTA(T_受験者[])/4)) -> 0.83333333 | AE72: =IF($W72="","",IF(C72=$AC72,"〇","×")) -> × | AF72: =IF($W72="","",IF(D72=$AC72,"〇","×")) -> × | AG72: =IF($W72="","",IF(E72=$AC72,"〇","×")) -> 〇 | AH72: =IF($W72="","",IF(F72=$AC72,"〇","×")) -> × | AI72: =IF($W72="","",IF(G72=$AC72,"〇","×")) -> × | AJ72: =IF($W72="","",IF(H72=$AC72,"〇","×")) -> × | AK72: =IF($W72="","",IF(I72=$AC72,"〇","×")) -> × | AL72: =IF($W72="","",IF(J72=$AC72,"〇","×")) -> × | ... AX72: =IF($W72="","",IF(V72=$AC72,"〇","×")) -> 〇
... A99: {=INDIRECT("'"&試験名&"'!A"&ROW()-2)} -> 聴解 | B99: =IF(A99="","",IF(A98=A99,B98+1,1)) -> 28 | E99: 2 | O99: 1 | P99: 3 | Q99: 3 | R99: 3 | V99: 3 | W99: =B99 -> 28 | X99: =IF(W99="","",COUNTIF($C99:$V99,X$2)) -> 1 | Y99: =IF(W99="","",COUNTIF($C99:$V99,Y$2)) -> 1 | Z99: =IF(W99="","",COUNTIF($C99:$V99,Z$2)) -> 4 | AA99: =IF(W99="","",COUNTIF($C99:$V99,AA$2)) -> 0 | AB99: =IF(W99="","",COUNTA(T_受験者[])/4-COUNTA($C99:$V99)) -> 0 | AC99: {=IF(W99="","",INDIRECT("'"&試験名&"'!B"&ROW()-2))} -> 3 | AD99: =IF(W99="","",COUNTIF(AE99:AX99,"〇")/(COUNTA(T_受験者[])/4)) -> 0.66666667 | AE99: =IF($W99="","",IF(C99=$AC99,"〇","×")) -> × | AF99: =IF($W99="","",IF(D99=$AC99,"〇","×")) -> × | AG99: =IF($W99="","",IF(E99=$AC99,"〇","×")) -> × | AH99: =IF($W99="","",IF(F99=$AC99,"〇","×")) -> × | AI99: =IF($W99="","",IF(G99=$AC99,"〇","×")) -> × | AJ99: =IF($W99="","",IF(H99=$AC99,"〇","×")) -> × | AK99: =IF($W99="","",IF(I99=$AC99,"〇","×")) -> × | AL99: =IF($W99="","",IF(J99=$AC99,"〇","×")) -> × | ... AX99: =IF($W99="","",IF(V99=$AC99,"〇","×")) -> 〇
A100: {=INDIRECT("'"&試験名&"'!A"&ROW()-2)} -> 0 | B100: =IF(A100="","",IF(A99=A100,B99+1,1)) -> 1 | W100: =B100 -> 1 | X100: =IF(W100="","",COUNTIF($C100:$V100,X$2)) -> 0 | Y100: =IF(W100="","",COUNTIF($C100:$V100,Y$2)) -> 0 | Z100: =IF(W100="","",COUNTIF($C100:$V100,Z$2)) -> 0 | AA100: =IF(W100="","",COUNTIF($C100:$V100,AA$2)) -> 0 | AB100: =IF(W100="","",COUNTA(T_受験者[])/4-COUNTA($C100:$V100)) -> 6 | AC100: {=IF(W100="","",INDIRECT("'"&試験名&"'!B"&ROW()-2))} -> 0 | AD100: =IF(W100="","",COUNTIF(AE100:AX100,"〇")/(COUNTA(T_受験者[])/4)) -> 3.3333333 | AE100: =IF($W100="","",IF(C100=$AC100,"〇","×")) -> 〇 | AF100: =IF($W100="","",IF(D100=$AC100,"〇","×")) -> 〇 | AG100: =IF($W100="","",IF(E100=$AC100,"〇","×")) -> 〇 | AH100: =IF($W100="","",IF(F100=$AC100,"〇","×")) -> 〇 | AI100: =IF($W100="","",IF(G100=$AC100,"〇","×")) -> 〇 | AJ100: =IF($W100="","",IF(H100=$AC100,"〇","×")) -> 〇 | AK100: =IF($W100="","",IF(I100=$AC100,"〇","×")) -> 〇 | AL100: =IF($W100="","",IF(J100=$AC100,"〇","×")) -> 〇 | ... AX100: =IF($W100="","",IF(V100=$AC100,"〇","×")) -> 〇
A101: {=INDIRECT("'"&試験名&"'!A"&ROW()-2)} -> 0 | B101: =IF(A101="","",IF(A100=A101,B100+1,1)) -> 2 | W101: =B101 -> 2 | X101: =IF(W101="","",COUNTIF($C101:$V101,X$2)) -> 0 | Y101: =IF(W101="","",COUNTIF($C101:$V101,Y$2)) -> 0 | Z101: =IF(W101="","",COUNTIF($C101:$V101,Z$2)) -> 0 | AA101: =IF(W101="","",COUNTIF($C101:$V101,AA$2)) -> 0 | AB101: =IF(W101="","",COUNTA(T_受験者[])/4-COUNTA($C101:$V101)) -> 6 | AC101: {=IF(W101="","",INDIRECT("'"&試験名&"'!B"&ROW()-2))} -> 0 | AD101: =IF(W101="","",COUNTIF(AE101:AX101,"〇")/(COUNTA(T_受験者[])/4)) -> 3.3333333 | AE101: =IF($W101="","",IF(C101=$AC101,"〇","×")) -> 〇 | AF101: =IF($W101="","",IF(D101=$AC101,"〇","×")) -> 〇 | AG101: =IF($W101="","",IF(E101=$AC101,"〇","×")) -> 〇 | AH101: =IF($W101="","",IF(F101=$AC101,"〇","×")) -> 〇 | AI101: =IF($W101="","",IF(G101=$AC101,"〇","×")) -> 〇 | AJ101: =IF($W101="","",IF(H101=$AC101,"〇","×")) -> 〇 | AK101: =IF($W101="","",IF(I101=$AC101,"〇","×")) -> 〇 | AL101: =IF($W101="","",IF(J101=$AC101,"〇","×")) -> 〇 | ... AX101: =IF($W101="","",IF(V101=$AC101,"〇","×")) -> 〇
A102: {=INDIRECT("'"&試験名&"'!A"&ROW()-2)} -> 0 | B102: =IF(A102="","",IF(A101=A102,B101+1,1)) -> 3 | W102: =B102 -> 3 | X102: =IF(W102="","",COUNTIF($C102:$V102,X$2)) -> 0 | Y102: =IF(W102="","",COUNTIF($C102:$V102,Y$2)) -> 0 | Z102: =IF(W102="","",COUNTIF($C102:$V102,Z$2)) -> 0 | AA102: =IF(W102="","",COUNTIF($C102:$V102,AA$2)) -> 0 | AB102: =IF(W102="","",COUNTA(T_受験者[])/4-COUNTA($C102:$V102)) -> 6 | AC102: {=IF(W102="","",INDIRECT("'"&試験名&"'!B"&ROW()-2))} -> 0 | AD102: =IF(W102="","",COUNTIF(AE102:AX102,"〇")/(COUNTA(T_受験者[])/4)) -> 3.3333333 | AE102: =IF($W102="","",IF(C102=$AC102,"〇","×")) -> 〇 | AF102: =IF($W102="","",IF(D102=$AC102,"〇","×")) -> 〇 | AG102: =IF($W102="","",IF(E102=$AC102,"〇","×")) -> 〇 | AH102: =IF($W102="","",IF(F102=$AC102,"〇","×")) -> 〇 | AI102: =IF($W102="","",IF(G102=$AC102,"〇","×")) -> 〇 | AJ102: =IF($W102="","",IF(H102=$AC102,"〇","×")) -> 〇 | AK102: =IF($W102="","",IF(I102=$AC102,"〇","×")) -> 〇 | AL102: =IF($W102="","",IF(J102=$AC102,"〇","×")) -> 〇 | ... AX102: =IF($W102="","",IF(V102=$AC102,"〇","×")) -> 〇
A103: {=INDIRECT("'"&試験名&"'!A"&ROW()-2)} -> 0 | B103: =IF(A103="","",IF(A102=A103,B102+1,1)) -> 4 | W103: =B103 -> 4 | X103: =IF(W103="","",COUNTIF($C103:$V103,X$2)) -> 0 | Y103: =IF(W103="","",COUNTIF($C103:$V103,Y$2)) -> 0 | Z103: =IF(W103="","",COUNTIF($C103:$V103,Z$2)) -> 0 | AA103: =IF(W103="","",COUNTIF($C103:$V103,AA$2)) -> 0 | AB103: =IF(W103="","",COUNTA(T_受験者[])/4-COUNTA($C103:$V103)) -> 6 | AC103: {=IF(W103="","",INDIRECT("'"&試験名&"'!B"&ROW()-2))} -> 0 | AD103: =IF(W103="","",COUNTIF(AE103:AX103,"〇")/(COUNTA(T_受験者[])/4)) -> 3.3333333 | AE103: =IF($W103="","",IF(C103=$AC103,"〇","×")) -> 〇 | AF103: =IF($W103="","",IF(D103=$AC103,"〇","×")) -> 〇 | AG103: =IF($W103="","",IF(E103=$AC103,"〇","×")) -> 〇 | AH103: =IF($W103="","",IF(F103=$AC103,"〇","×")) -> 〇 | AI103: =IF($W103="","",IF(G103=$AC103,"〇","×")) -> 〇 | AJ103: =IF($W103="","",IF(H103=$AC103,"〇","×")) -> 〇 | AK103: =IF($W103="","",IF(I103=$AC103,"〇","×")) -> 〇 | AL103: =IF($W103="","",IF(J103=$AC103,"〇","×")) -> 〇 | ... AX103: =IF($W103="","",IF(V103=$AC103,"〇","×")) -> 〇
A104: {=INDIRECT("'"&試験名&"'!A"&ROW()-2)} -> 0 | B104: =IF(A104="","",IF(A103=A104,B103+1,1)) -> 5 | W104: =B104 -> 5 | X104: =IF(W104="","",COUNTIF($C104:$V104,X$2)) -> 0 | Y104: =IF(W104="","",COUNTIF($C104:$V104,Y$2)) -> 0 | Z104: =IF(W104="","",COUNTIF($C104:$V104,Z$2)) -> 0 | AA104: =IF(W104="","",COUNTIF($C104:$V104,AA$2)) -> 0 | AB104: =IF(W104="","",COUNTA(T_受験者[])/4-COUNTA($C104:$V104)) -> 6 | AC104: {=IF(W104="","",INDIRECT("'"&試験名&"'!B"&ROW()-2))} -> 0 | AD104: =IF(W104="","",COUNTIF(AE104:AX104,"〇")/(COUNTA(T_受験者[])/4)) -> 3.3333333 | AE104: =IF($W104="","",IF(C104=$AC104,"〇","×")) -> 〇 | AF104: =IF($W104="","",IF(D104=$AC104,"〇","×")) -> 〇 | AG104: =IF($W104="","",IF(E104=$AC104,"〇","×")) -> 〇 | AH104: =IF($W104="","",IF(F104=$AC104,"〇","×")) -> 〇 | AI104: =IF($W104="","",IF(G104=$AC104,"〇","×")) -> 〇 | AJ104: =IF($W104="","",IF(H104=$AC104,"〇","×")) -> 〇 | AK104: =IF($W104="","",IF(I104=$AC104,"〇","×")) -> 〇 | AL104: =IF($W104="","",IF(J104=$AC104,"〇","×")) -> 〇 | ... AX104: =IF($W104="","",IF(V104=$AC104,"〇","×")) -> 〇
A105: {=INDIRECT("'"&試験名&"'!A"&ROW()-2)} -> 0 | B105: =IF(A105="","",IF(A104=A105,B104+1,1)) -> 6 | W105: =B105 -> 6 | X105: =IF(W105="","",COUNTIF($C105:$V105,X$2)) -> 0 | Y105: =IF(W105="","",COUNTIF($C105:$V105,Y$2)) -> 0 | Z105: =IF(W105="","",COUNTIF($C105:$V105,Z$2)) -> 0 | AA105: =IF(W105="","",COUNTIF($C105:$V105,AA$2)) -> 0 | AB105: =IF(W105="","",COUNTA(T_受験者[])/4-COUNTA($C105:$V105)) -> 6 | AC105: {=IF(W105="","",INDIRECT("'"&試験名&"'!B"&ROW()-2))} -> 0 | AD105: =IF(W105="","",COUNTIF(AE105:AX105,"〇")/(COUNTA(T_受験者[])/4)) -> 3.3333333 | AE105: =IF($W105="","",IF(C105=$AC105,"〇","×")) -> 〇 | AF105: =IF($W105="","",IF(D105=$AC105,"〇","×")) -> 〇 | AG105: =IF($W105="","",IF(E105=$AC105,"〇","×")) -> 〇 | AH105: =IF($W105="","",IF(F105=$AC105,"〇","×")) -> 〇 | AI105: =IF($W105="","",IF(G105=$AC105,"〇","×")) -> 〇 | AJ105: =IF($W105="","",IF(H105=$AC105,"〇","×")) -> 〇 | AK105: =IF($W105="","",IF(I105=$AC105,"〇","×")) -> 〇 | AL105: =IF($W105="","",IF(J105=$AC105,"〇","×")) -> 〇 | ... AX105: =IF($W105="","",IF(V105=$AC105,"〇","×")) -> 〇
A106: {=INDIRECT("'"&試験名&"'!A"&ROW()-2)} -> 0 | B106: =IF(A106="","",IF(A105=A106,B105+1,1)) -> 7 | W106: =B106 -> 7 | X106: =IF(W106="","",COUNTIF($C106:$V106,X$2)) -> 0 | Y106: =IF(W106="","",COUNTIF($C106:$V106,Y$2)) -> 0 | Z106: =IF(W106="","",COUNTIF($C106:$V106,Z$2)) -> 0 | AA106: =IF(W106="","",COUNTIF($C106:$V106,AA$2)) -> 0 | AB106: =IF(W106="","",COUNTA(T_受験者[])/4-COUNTA($C106:$V106)) -> 6 | AC106: {=IF(W106="","",INDIRECT("'"&試験名&"'!B"&ROW()-2))} -> 0 | AD106: =IF(W106="","",COUNTIF(AE106:AX106,"〇")/(COUNTA(T_受験者[])/4)) -> 3.3333333 | AE106: =IF($W106="","",IF(C106=$AC106,"〇","×")) -> 〇 | AF106: =IF($W106="","",IF(D106=$AC106,"〇","×")) -> 〇 | AG106: =IF($W106="","",IF(E106=$AC106,"〇","×")) -> 〇 | AH106: =IF($W106="","",IF(F106=$AC106,"〇","×")) -> 〇 | AI106: =IF($W106="","",IF(G106=$AC106,"〇","×")) -> 〇 | AJ106: =IF($W106="","",IF(H106=$AC106,"〇","×")) -> 〇 | AK106: =IF($W106="","",IF(I106=$AC106,"〇","×")) -> 〇 | AL106: =IF($W106="","",IF(J106=$AC106,"〇","×")) -> 〇 | ... AX106: =IF($W106="","",IF(V106=$AC106,"〇","×")) -> 〇
...

Sheet 集計
A1: レベル | B1: =VLOOKUP(試験名,試験情報!A:B,2,FALSE) -> N4 | U1: 標準偏差 | V1: =STDEVP(T_成績[合計]) -> 14.926673
A2: {=T_受験者[#Headers]} -> 学籍番号 | B2: クラス | C2: 出席番号 | D2: 名前 | E2: 文字・語彙正解数 | F2: 文字・語彙 | G2: 文法正解数 | H2: 文法 | I2: 読解正解数 | J2: 読解 | K2: 文法・読解正解数 | L2: 文法・読解 | M2: 聴解正解数 | N2: 聴解 | O2: 文字・語彙・文法・読解 | P2: 判定1 | Q2: 判定2 | R2: 判定3 | S2: 合計 | T2: 順位 | U2: 合否 | V2: 偏差値
A3: {=T_受験者[]} -> 2504094 | B3: 1-13 | C3: 13 | D3: UGESH SAPKOTA | E3: =COUNTIF(INDIRECT("解答入力!"&ADDRESS(VLOOKUP(試験名,T_試験[#Data],7,FALSE)+2,30+C3)&":"&ADDRESS(VLOOKUP(試験名,T_試験[#Data],8,FALSE)+2,30+C3)),"〇") -> 24 | F3: =ROUND(E3*60/VLOOKUP(試験名,T_試験[[#All],[書籍名および実施回]:[聴解問題数]],3,FALSE),0) -> 42 | G3: =COUNTIF(INDIRECT("解答入力!"&ADDRESS(VLOOKUP(試験名,T_試験[#Data],9,FALSE)+2,30+C3)&":"&ADDRESS(VLOOKUP(試験名,T_試験[#Data],10,FALSE)+2,30+C3)),"〇") -> 11 | H3: =ROUND(G3*60/VLOOKUP(試験名,T_試験[[#All],[書籍名および実施回]:[聴解問題数]],4,FALSE),0) -> 26 | I3: =COUNTIF(INDIRECT("解答入力!"&ADDRESS(VLOOKUP(試験名,T_試験[#Data],11,FALSE)+2,30+C3)&":"&ADDRESS(VLOOKUP(試験名,T_試験[#Data],12,FALSE)+2,30+C3)),"〇") -> 3 | J3: =ROUND(I3*60/VLOOKUP(試験名,T_試験[[#All],[書籍名および実施回]:[聴解問題数]],5,FALSE),0) -> 18 | K3: =G3+I3 -> 14 | L3: =ROUND(K3*60/(VLOOKUP(試験名,T_試験[],4,FALSE)+VLOOKUP(試験名,T_試験[],5,FALSE)),0) -> 24 | M3: =COUNTIF(INDIRECT("解答入力!"&ADDRESS(VLOOKUP(試験名,T_試験[#Data],13,FALSE)+2,30+C3)&":"&ADDRESS(VLOOKUP(試験名,T_試験[#Data],14,FALSE)+2,30+C3)),"〇") -> 17 | N3: =ROUND(M3*60/VLOOKUP(試験名,T_試験[[#All],[書籍名および実施回]:[聴解問題数]],6,FALSE),0) -> 36 | O3: =IF(OR($B$1="N5",$B$1="N4"),F3+L3,0) -> 66 | P3: =IF(OR($B$1="N5",($B$1="N4")),IF(O3>=VLOOKUP($B$1,T_基準点[],3,FALSE),"○","✕"),IF(F3>=VLOOKUP($B$1,T_基準点[],3,FALSE),"○","✕")) -> ○ | Q3: =IF(OR($B$1="N5",($B$1="N4")),"○",IF(L3>=VLOOKUP($B$1,T_基準点[],5,FALSE),"○","✕")) -> ○ | R3: =IF(N3>=VLOOKUP($B$1,T_基準点[],7,FALSE),"○","✕") -> ○ | S3: =F3+L3+N3 -> 102 | T3: =RANK(S3,T_成績[合計],0) -> 4 | U3: =IF(AND(P3="○",Q3="○",R3="○",S3>=VLOOKUP($B$1,T_基準点[],8,FALSE)),"○","×") -> × | V3: =50+10*(T_成績[[#This Row],[合計]]-T_成績[[#Totals],[合計]])/$V$1 -> 47.43189
A4: 2504103 | B4: 1-13 | C4: 14 | D4: DHAKAL LILA MAYA | E4: =COUNTIF(INDIRECT("解答入力!"&ADDRESS(VLOOKUP(試験名,T_試験[#Data],7,FALSE)+2,30+C4)&":"&ADDRESS(VLOOKUP(試験名,T_試験[#Data],8,FALSE)+2,30+C4)),"〇") -> 24 | F4: =ROUND(E4*60/VLOOKUP(試験名,T_試験[[#All],[書籍名および実施回]:[聴解問題数]],3,FALSE),0) -> 42 | G4: =COUNTIF(INDIRECT("解答入力!"&ADDRESS(VLOOKUP(試験名,T_試験[#Data],9,FALSE)+2,30+C4)&":"&ADDRESS(VLOOKUP(試験名,T_試験[#Data],10,FALSE)+2,30+C4)),"〇") -> 11 | H4: =ROUND(G4*60/VLOOKUP(試験名,T_試験[[#All],[書籍名および実施回]:[聴解問題数]],4,FALSE),0) -> 26 | I4: =COUNTIF(INDIRECT("解答入力!"&ADDRESS(VLOOKUP(試験名,T_試験[#Data],11,FALSE)+2,30+C4)&":"&ADDRESS(VLOOKUP(試験名,T_試験[#Data],12,FALSE)+2,30+C4)),"〇") -> 3 | J4: =ROUND(I4*60/VLOOKUP(試験名,T_試験[[#All],[書籍名および実施回]:[聴解問題数]],5,FALSE),0) -> 18 | K4: =G4+I4 -> 14 | L4: =ROUND(K4*60/(VLOOKUP(試験名,T_試験[],4,FALSE)+VLOOKUP(試験名,T_試験[],5,FALSE)),0) -> 24 | M4: =COUNTIF(INDIRECT("解答入力!"&ADDRESS(VLOOKUP(試験名,T_試験[#Data],13,FALSE)+2,30+C4)&":"&ADDRESS(VLOOKUP(試験名,T_試験[#Data],14,FALSE)+2,30+C4)),"〇") -> 18 | N4: =ROUND(M4*60/VLOOKUP(試験名,T_試験[[#All],[書籍名および実施回]:[聴解問題数]],6,FALSE),0) -> 39 | O4: =IF(OR($B$1="N5",$B$1="N4"),F4+L4,0) -> 66 | P4: =IF(OR($B$1="N5",($B$1="N4")),IF(O4>=VLOOKUP($B$1,T_基準点[],3,FALSE),"○","✕"),IF(F4>=VLOOKUP($B$1,T_基準点[],3,FALSE),"○","✕")) -> ○ | Q4: =IF(OR($B$1="N5",($B$1="N4")),"○",IF(L4>=VLOOKUP($B$1,T_基準点[],5,FALSE),"○","✕")) -> ○ | R4: =IF(N4>=VLOOKUP($B$1,T_基準点[],7,FALSE),"○","✕") -> ○ | S4: =F4+L4+N4 -> 105 | T4: =RANK(S4,T_成績[合計],0) -> 3 | U4: =IF(AND(P4="○",Q4="○",R4="○",S4>=VLOOKUP($B$1,T_基準点[],8,FALSE)),"○","×") -> × | V4: =50+10*(T_成績[[#This Row],[合計]]-T_成績[[#Totals],[合計]])/$V$1 -> 49.441715
A5: 2504108 | B5: 1-13 | C5: 15 | D5: NIRMALA BIST | E5: =COUNTIF(INDIRECT("解答入力!"&ADDRESS(VLOOKUP(試験名,T_試験[#Data],7,FALSE)+2,30+C5)&":"&ADDRESS(VLOOKUP(試験名,T_試験[#Data],8,FALSE)+2,30+C5)),"〇") -> 18 | F5: =ROUND(E5*60/VLOOKUP(試験名,T_試験[[#All],[書籍名および実施回]:[聴解問題数]],3,FALSE),0) -> 32 | G5: =COUNTIF(INDIRECT("解答入力!"&ADDRESS(VLOOKUP(試験名,T_試験[#Data],9,FALSE)+2,30+C5)&":"&ADDRESS(VLOOKUP(試験名,T_試験[#Data],10,FALSE)+2,30+C5)),"〇") -> 13 | H5: =ROUND(G5*60/VLOOKUP(試験名,T_試験[[#All],[書籍名および実施回]:[聴解問題数]],4,FALSE),0) -> 31 | I5: =COUNTIF(INDIRECT("解答入力!"&ADDRESS(VLOOKUP(試験名,T_試験[#Data],11,FALSE)+2,30+C5)&":"&ADDRESS(VLOOKUP(試験名,T_試験[#Data],12,FALSE)+2,30+C5)),"〇") -> 3 | J5: =ROUND(I5*60/VLOOKUP(試験名,T_試験[[#All],[書籍名および実施回]:[聴解問題数]],5,FALSE),0) -> 18 | K5: =G5+I5 -> 16 | L5: =ROUND(K5*60/(VLOOKUP(試験名,T_試験[],4,FALSE)+VLOOKUP(試験名,T_試験[],5,FALSE)),0) -> 27 | M5: =COUNTIF(INDIRECT("解答入力!"&ADDRESS(VLOOKUP(試験名,T_試験[#Data],13,FALSE)+2,30+C5)&":"&ADDRESS(VLOOKUP(試験名,T_試験[#Data],14,FALSE)+2,30+C5)),"〇") -> 20 | N5: =ROUND(M5*60/VLOOKUP(試験名,T_試験[[#All],[書籍名および実施回]:[聴解問題数]],6,FALSE),0) -> 43 | O5: =IF(OR($B$1="N5",$B$1="N4"),F5+L5,0) -> 59 | P5: =IF(OR($B$1="N5",($B$1="N4")),IF(O5>=VLOOKUP($B$1,T_基準点[],3,FALSE),"○","✕"),IF(F5>=VLOOKUP($B$1,T_基準点[],3,FALSE),"○","✕")) -> ○ | Q5: =IF(OR($B$1="N5",($B$1="N4")),"○",IF(L5>=VLOOKUP($B$1,T_基準点[],5,FALSE),"○","✕")) -> ○ | R5: =IF(N5>=VLOOKUP($B$1,T_基準点[],7,FALSE),"○","✕") -> ○ | S5: =F5+L5+N5 -> 102 | T5: =RANK(S5,T_成績[合計],0) -> 4 | U5: =IF(AND(P5="○",Q5="○",R5="○",S5>=VLOOKUP($B$1,T_基準点[],8,FALSE)),"○","×") -> × | V5: =50+10*(T_成績[[#This Row],[合計]]-T_成績[[#Totals],[合計]])/$V$1 -> 47.43189
A6: 2504114 | B6: 1-13 | C6: 16 | D6: CHAUDHARY RAJESH | E6: =COUNTIF(INDIRECT("解答入力!"&ADDRESS(VLOOKUP(試験名,T_試験[#Data],7,FALSE)+2,30+C6)&":"&ADDRESS(VLOOKUP(試験名,T_試験[#Data],8,FALSE)+2,30+C6)),"〇") -> 25 | F6: =ROUND(E6*60/VLOOKUP(試験名,T_試験[[#All],[書籍名および実施回]:[聴解問題数]],3,FALSE),0) -> 44 | G6: =COUNTIF(INDIRECT("解答入力!"&ADDRESS(VLOOKUP(試験名,T_試験[#Data],9,FALSE)+2,30+C6)&":"&ADDRESS(VLOOKUP(試験名,T_試験[#Data],10,FALSE)+2,30+C6)),"〇") -> 14 | H6: =ROUND(G6*60/VLOOKUP(試験名,T_試験[[#All],[書籍名および実施回]:[聴解問題数]],4,FALSE),0) -> 34 | I6: =COUNTIF(INDIRECT("解答入力!"&ADDRESS(VLOOKUP(試験名,T_試験[#Data],11,FALSE)+2,30+C6)&":"&ADDRESS(VLOOKUP(試験名,T_試験[#Data],12,FALSE)+2,30+C6)),"〇") -> 5 | J6: =ROUND(I6*60/VLOOKUP(試験名,T_試験[[#All],[書籍名および実施回]:[聴解問題数]],5,FALSE),0) -> 30 | K6: =G6+I6 -> 19 | L6: =ROUND(K6*60/(VLOOKUP(試験名,T_試験[],4,FALSE)+VLOOKUP(試験名,T_試験[],5,FALSE)),0) -> 33 | M6: =COUNTIF(INDIRECT("解答入力!"&ADDRESS(VLOOKUP(試験名,T_試験[#Data],13,FALSE)+2,30+C6)&":"&ADDRESS(VLOOKUP(試験名,T_試験[#Data],14,FALSE)+2,30+C6)),"〇") -> 19 | N6: =ROUND(M6*60/VLOOKUP(試験名,T_試験[[#All],[書籍名および実施回]:[聴解問題数]],6,FALSE),0) -> 41 | O6: =IF(OR($B$1="N5",$B$1="N4"),F6+L6,0) -> 77 | P6: =IF(OR($B$1="N5",($B$1="N4")),IF(O6>=VLOOKUP($B$1,T_基準点[],3,FALSE),"○","✕"),IF(F6>=VLOOKUP($B$1,T_基準点[],3,FALSE),"○","✕")) -> ○ | Q6: =IF(OR($B$1="N5",($B$1="N4")),"○",IF(L6>=VLOOKUP($B$1,T_基準点[],5,FALSE),"○","✕")) -> ○ | R6: =IF(N6>=VLOOKUP($B$1,T_基準点[],7,FALSE),"○","✕") -> ○ | S6: =F6+L6+N6 -> 118 | T6: =RANK(S6,T_成績[合計],0) -> 2 | U6: =IF(AND(P6="○",Q6="○",R6="○",S6>=VLOOKUP($B$1,T_基準点[],8,FALSE)),"○","×") -> × | V6: =50+10*(T_成績[[#This Row],[合計]]-T_成績[[#Totals],[合計]])/$V$1 -> 58.150957
A7: 2510013 | B7: 1-13 | C7: 20 | D7: LE XUAN BACH | E7: =COUNTIF(INDIRECT("解答入力!"&ADDRESS(VLOOKUP(試験名,T_試験[#Data],7,FALSE)+2,30+C7)&":"&ADDRESS(VLOOKUP(試験名,T_試験[#Data],8,FALSE)+2,30+C7)),"〇") -> 30 | F7: =ROUND(E7*60/VLOOKUP(試験名,T_試験[[#All],[書籍名および実施回]:[聴解問題数]],3,FALSE),0) -> 53 | G7: =COUNTIF(INDIRECT("解答入力!"&ADDRESS(VLOOKUP(試験名,T_試験[#Data],9,FALSE)+2,30+C7)&":"&ADDRESS(VLOOKUP(試験名,T_試験[#Data],10,FALSE)+2,30+C7)),"〇") -> 17 | H7: =ROUND(G7*60/VLOOKUP(試験名,T_試験[[#All],[書籍名および実施回]:[聴解問題数]],4,FALSE),0) -> 41 | I7: =COUNTIF(INDIRECT("解答入力!"&ADDRESS(VLOOKUP(試験名,T_試験[#Data],11,FALSE)+2,30+C7)&":"&ADDRESS(VLOOKUP(試験名,T_試験[#Data],12,FALSE)+2,30+C7)),"〇") -> 3 | J7: =ROUND(I7*60/VLOOKUP(試験名,T_試験[[#All],[書籍名および実施回]:[聴解問題数]],5,FALSE),0) -> 18 | K7: =G7+I7 -> 20 | L7: =ROUND(K7*60/(VLOOKUP(試験名,T_試験[],4,FALSE)+VLOOKUP(試験名,T_試験[],5,FALSE)),0) -> 34 | M7: =COUNTIF(INDIRECT("解答入力!"&ADDRESS(VLOOKUP(試験名,T_試験[#Data],13,FALSE)+2,30+C7)&":"&ADDRESS(VLOOKUP(試験名,T_試験[#Data],14,FALSE)+2,30+C7)),"〇") -> 19 | N7: =ROUND(M7*60/VLOOKUP(試験名,T_試験[[#All],[書籍名および実施回]:[聴解問題数]],6,FALSE),0) -> 41 | O7: =IF(OR($B$1="N5",$B$1="N4"),F7+L7,0) -> 87 | P7: =IF(OR($B$1="N5",($B$1="N4")),IF(O7>=VLOOKUP($B$1,T_基準点[],3,FALSE),"○","✕"),IF(F7>=VLOOKUP($B$1,T_基準点[],3,FALSE),"○","✕")) -> ○ | Q7: =IF(OR($B$1="N5",($B$1="N4")),"○",IF(L7>=VLOOKUP($B$1,T_基準点[],5,FALSE),"○","✕")) -> ○ | R7: =IF(N7>=VLOOKUP($B$1,T_基準点[],7,FALSE),"○","✕") -> ○ | S7: =F7+L7+N7 -> 128 | T7: =RANK(S7,T_成績[合計],0) -> 1 | U7: =IF(AND(P7="○",Q7="○",R7="○",S7>=VLOOKUP($B$1,T_基準点[],8,FALSE)),"○","×") -> ○ | V7: =50+10*(T_成績[[#This Row],[合計]]-T_成績[[#Totals],[合計]])/$V$1 -> 64.850374
A8: 2504019 | B8: 1-13 | C8: 3 | D8: KC HIMAL | E8: =COUNTIF(INDIRECT("解答入力!"&ADDRESS(VLOOKUP(試験名,T_試験[#Data],7,FALSE)+2,30+C8)&":"&ADDRESS(VLOOKUP(試験名,T_試験[#Data],8,FALSE)+2,30+C8)),"〇") -> 17 | F8: =ROUND(E8*60/VLOOKUP(試験名,T_試験[[#All],[書籍名および実施回]:[聴解問題数]],3,FALSE),0) -> 30 | G8: =COUNTIF(INDIRECT("解答入力!"&ADDRESS(VLOOKUP(試験名,T_試験[#Data],9,FALSE)+2,30+C8)&":"&ADDRESS(VLOOKUP(試験名,T_試験[#Data],10,FALSE)+2,30+C8)),"〇") -> 10 | H8: =ROUND(G8*60/VLOOKUP(試験名,T_試験[[#All],[書籍名および実施回]:[聴解問題数]],4,FALSE),0) -> 24 | I8: =COUNTIF(INDIRECT("解答入力!"&ADDRESS(VLOOKUP(試験名,T_試験[#Data],11,FALSE)+2,30+C8)&":"&ADDRESS(VLOOKUP(試験名,T_試験[#Data],12,FALSE)+2,30+C8)),"〇") -> 3 | J8: =ROUND(I8*60/VLOOKUP(試験名,T_試験[[#All],[書籍名および実施回]:[聴解問題数]],5,FALSE),0) -> 18 | K8: =G8+I8 -> 13 | L8: =ROUND(K8*60/(VLOOKUP(試験名,T_試験[],4,FALSE)+VLOOKUP(試験名,T_試験[],5,FALSE)),0) -> 22 | M8: =COUNTIF(INDIRECT("解答入力!"&ADDRESS(VLOOKUP(試験名,T_試験[#Data],13,FALSE)+2,30+C8)&":"&ADDRESS(VLOOKUP(試験名,T_試験[#Data],14,FALSE)+2,30+C8)),"〇") -> 13 | N8: =ROUND(M8*60/VLOOKUP(試験名,T_試験[[#All],[書籍名および実施回]:[聴解問題数]],6,FALSE),0) -> 28 | O8: =IF(OR($B$1="N5",$B$1="N4"),F8+L8,0) -> 52 | P8: =IF(OR($B$1="N5",($B$1="N4")),IF(O8>=VLOOKUP($B$1,T_基準点[],3,FALSE),"○","✕"),IF(F8>=VLOOKUP($B$1,T_基準点[],3,FALSE),"○","✕")) -> ○ | Q8: =IF(OR($B$1="N5",($B$1="N4")),"○",IF(L8>=VLOOKUP($B$1,T_基準点[],5,FALSE),"○","✕")) -> ○ | R8: =IF(N8>=VLOOKUP($B$1,T_基準点[],7,FALSE),"○","✕") -> ○ | S8: =F8+L8+N8 -> 80 | T8: =RANK(S8,T_成績[合計],0) -> 6 | U8: =IF(AND(P8="○",Q8="○",R8="○",S8>=VLOOKUP($B$1,T_基準点[],8,FALSE)),"○","×") -> × | V8: =50+10*(T_成績[[#This Row],[合計]]-T_成績[[#Totals],[合計]])/$V$1 -> 32.693173
D9: 平均点 | E9: 集計 | F9: =SUBTOTAL(101,T_成績[文字・語彙]) -> 40.5 | L9: =SUBTOTAL(101,T_成績[文法・読解]) -> 27.333333 | N9: =SUBTOTAL(101,T_成績[聴解]) -> 38 | S9: =SUBTOTAL(101,T_成績[合計]) -> 105.83333

Sheet 学生配布用
A1: 学籍番号 | B1: 名前 | C1: 文字・語彙 | F1: 文法 | I1: 読解 | L1: 聴解 | O1: 総合得点 | P1: 合否
A2: =T_受験者[[#This Row],[学籍番号]] -> 2504094 | B2: =T_受験者[[#This Row],[名前]] -> UGESH SAPKOTA | C2: 文字・語彙 | D2: =VLOOKUP(A2,集計!A3:N7,6,FALSE)/60 -> 0.7 | E2: =IF(学生配布用!$D2>=0.67,"A",IF(学生配布用!$D2>=0.34,"B","C")) -> A | F2: 文法 | G2: =VLOOKUP(A2,集計!A3:N7,8,FALSE)/60 -> 0.43333333 | H2: =IF(学生配布用!$G2>=0.67,"A",IF(学生配布用!$G2>=0.34,"B","C")) -> B | I2: 読解 | J2: =VLOOKUP(A2,集計!A3:N7,10,FALSE)/60 -> 0.3 | K2: =IF(学生配布用!$J2>=0.67,"A",IF(学生配布用!$J2>=0.34,"B","C")) -> C | L2: 聴解 | M2: =VLOOKUP(A2,集計!A3:N7,14,FALSE)/60 -> 0.6 | N2: =IF(学生配布用!$M2>=0.67,"A",IF(学生配布用!$M2>=0.34,"B","C")) -> B | O2: =VLOOKUP(A2,集計!A3:U7,19,FALSE) -> 102 | P2: =VLOOKUP(A2,集計!A3:U7,21,FALSE) -> ×
A3: =T_受験者[[#This Row],[学籍番号]] -> 2504103 | B3: =T_受験者[[#This Row],[名前]] -> DHAKAL LILA MAYA | C3: 文字・語彙 | D3: =VLOOKUP(A3,集計!A4:N9,6,FALSE)/60 -> 0.7 | E3: =IF(学生配布用!$D3>=0.67,"A",IF(学生配布用!$D3>=0.34,"B","C")) -> A | F3: 文法 | G3: =VLOOKUP(A3,集計!A4:N9,8,FALSE)/60 -> 0.43333333 | H3: =IF(学生配布用!$G3>=0.67,"A",IF(学生配布用!$G3>=0.34,"B","C")) -> B | I3: 読解 | J3: =VLOOKUP(A3,集計!A4:N9,10,FALSE)/60 -> 0.3 | K3: =IF(学生配布用!$J3>=0.67,"A",IF(学生配布用!$J3>=0.34,"B","C")) -> C | L3: 聴解 | M3: =VLOOKUP(A3,集計!A4:N9,14,FALSE)/60 -> 0.65 | N3: =IF(学生配布用!$M3>=0.67,"A",IF(学生配布用!$M3>=0.34,"B","C")) -> B | O3: =VLOOKUP(A3,集計!A4:U9,19,FALSE) -> 105 | P3: =VLOOKUP(A3,集計!A4:U9,21,FALSE) -> ×
A4: =T_受験者[[#This Row],[学籍番号]] -> 2504108 | B4: =T_受験者[[#This Row],[名前]] -> NIRMALA BIST | C4: 文字・語彙 | D4: =VLOOKUP(A4,集計!A5:N10,6,FALSE)/60 -> 0.53333333 | E4: =IF(学生配布用!$D4>=0.67,"A",IF(学生配布用!$D4>=0.34,"B","C")) -> B | F4: 文法 | G4: =VLOOKUP(A4,集計!A5:N10,8,FALSE)/60 -> 0.51666667 | H4: =IF(学生配布用!$G4>=0.67,"A",IF(学生配布用!$G4>=0.34,"B","C")) -> B | I4: 読解 | J4: =VLOOKUP(A4,集計!A5:N10,10,FALSE)/60 -> 0.3 | K4: =IF(学生配布用!$J4>=0.67,"A",IF(学生配布用!$J4>=0.34,"B","C")) -> C | L4: 聴解 | M4: =VLOOKUP(A4,集計!A5:N10,14,FALSE)/60 -> 0.71666667 | N4: =IF(学生配布用!$M4>=0.67,"A",IF(学生配布用!$M4>=0.34,"B","C")) -> A | O4: =VLOOKUP(A4,集計!A5:U10,19,FALSE) -> 102 | P4: =VLOOKUP(A4,集計!A5:U10,21,FALSE) -> ×
A5: =T_受験者[[#This Row],[学籍番号]] -> 2504114 | B5: =T_受験者[[#This Row],[名前]] -> CHAUDHARY RAJESH | C5: 文字・語彙 | D5: =VLOOKUP(A5,集計!A6:N11,6,FALSE)/60 -> 0.73333333 | E5: =IF(学生配布用!$D5>=0.67,"A",IF(学生配布用!$D5>=0.34,"B","C")) -> A | F5: 文法 | G5: =VLOOKUP(A5,集計!A6:N11,8,FALSE)/60 -> 0.56666667 | H5: =IF(学生配布用!$G5>=0.67,"A",IF(学生配布用!$G5>=0.34,"B","C")) -> B | I5: 読解 | J5: =VLOOKUP(A5,集計!A6:N11,10,FALSE)/60 -> 0.5 | K5: =IF(学生配布用!$J5>=0.67,"A",IF(学生配布用!$J5>=0.34,"B","C")) -> B | L5: 聴解 | M5: =VLOOKUP(A5,集計!A6:N11,14,FALSE)/60 -> 0.68333333 | N5: =IF(学生配布用!$M5>=0.67,"A",IF(学生配布用!$M5>=0.34,"B","C")) -> A | O5: =VLOOKUP(A5,集計!A6:U11,19,FALSE) -> 118 | P5: =VLOOKUP(A5,集計!A6:U11,21,FALSE) -> ×
A6: =T_受験者[[#This Row],[学籍番号]] -> 2510013 | B6: =T_受験者[[#This Row],[名前]] -> LE XUAN BACH | C6: 文字・語彙 | D6: =VLOOKUP(A6,集計!A7:N12,6,FALSE)/60 -> 0.88333333 | E6: =IF(学生配布用!$D6>=0.67,"A",IF(学生配布用!$D6>=0.34,"B","C")) -> A | F6: 文法 | G6: =VLOOKUP(A6,集計!A7:N12,8,FALSE)/60 -> 0.68333333 | H6: =IF(学生配布用!$G6>=0.67,"A",IF(学生配布用!$G6>=0.34,"B","C")) -> A | I6: 読解 | J6: =VLOOKUP(A6,集計!A7:N12,10,FALSE)/60 -> 0.3 | K6: =IF(学生配布用!$J6>=0.67,"A",IF(学生配布用!$J6>=0.34,"B","C")) -> C | L6: 聴解 | M6: =VLOOKUP(A6,集計!A7:N12,14,FALSE)/60 -> 0.68333333 | N6: =IF(学生配布用!$M6>=0.67,"A",IF(学生配布用!$M6>=0.34,"B","C")) -> A | O6: =VLOOKUP(A6,集計!A7:U12,19,FALSE) -> 128 | P6: =VLOOKUP(A6,集計!A7:U12,21,FALSE) -> ○
A7: =T_受験者[[#This Row],[学籍番号]] -> 2504019 | B7: =T_受験者[[#This Row],[名前]] -> KC HIMAL | C7: 文字・語彙 | D7: =VLOOKUP(A7,集計!A9:N13,6,FALSE)/60 -> #N/A | E7: =IF(学生配布用!$D7>=0.67,"A",IF(学生配布用!$D7>=0.34,"B","C")) -> #N/A | F7: 文法 | G7: =VLOOKUP(A7,集計!A9:N13,8,FALSE)/60 -> #N/A | H7: =IF(学生配布用!$G7>=0.67,"A",IF(学生配布用!$G7>=0.34,"B","C")) -> #N/A | I7: 読解 | J7: =VLOOKUP(A7,集計!A9:N13,10,FALSE)/60 -> #N/A | K7: =IF(学生配布用!$J7>=0.67,"A",IF(学生配布用!$J7>=0.34,"B","C")) -> #N/A | L7: 聴解 | M7: =VLOOKUP(A7,集計!A9:N13,14,FALSE)/60 -> #N/A | N7: =IF(学生配布用!$M7>=0.67,"A",IF(学生配布用!$M7>=0.34,"B","C")) -> #N/A | O7: =VLOOKUP(A7,集計!A9:U13,19,FALSE) -> #N/A | P7: =VLOOKUP(A7,集計!A9:U13,21,FALSE) -> #N/A
A8: =T_受験者[[#This Row],[学籍番号]] -> #VALUE! | B8: =T_受験者[[#This Row],[名前]] -> #VALUE! | C8: 文字・語彙 | D8: =VLOOKUP(A8,集計!A9:N14,6,FALSE)/60 -> #VALUE! | E8: =IF(学生配布用!$D8>=0.67,"A",IF(学生配布用!$D8>=0.34,"B","C")) -> #VALUE! | F8: 文法 | G8: =VLOOKUP(A8,集計!A9:N14,8,FALSE)/60 -> #VALUE! | H8: =IF(学生配布用!$G8>=0.67,"A",IF(学生配布用!$G8>=0.34,"B","C")) -> #VALUE! | I8: 読解 | J8: =VLOOKUP(A8,集計!A9:N14,10,FALSE)/60 -> #VALUE! | K8: =IF(学生配布用!$J8>=0.67,"A",IF(学生配布用!$J8>=0.34,"B","C")) -> #VALUE! | L8: 聴解 | M8: =VLOOKUP(A8,集計!A9:N14,14,FALSE)/60 -> #VALUE! | N8: =IF(学生配布用!$M8>=0.67,"A",IF(学生配布用!$M8>=0.34,"B","C")) -> #VALUE! | O8: =VLOOKUP(A8,集計!A9:U14,19,FALSE) -> #VALUE! | P8: =VLOOKUP(A8,集計!A9:U14,21,FALSE) -> #VALUE!
A9: =T_受験者[[#This Row],[学籍番号]] -> #VALUE! | B9: =T_受験者[[#This Row],[名前]] -> #VALUE! | C9: 文字・語彙 | D9: =VLOOKUP(A9,集計!A9:N15,6,FALSE)/60 -> #VALUE! | E9: =IF(学生配布用!$D9>=0.67,"A",IF(学生配布用!$D9>=0.34,"B","C")) -> #VALUE! | F9: 文法 | G9: =VLOOKUP(A9,集計!A9:N15,8,FALSE)/60 -> #VALUE! | H9: =IF(学生配布用!$G9>=0.67,"A",IF(学生配布用!$G9>=0.34,"B","C")) -> #VALUE! | I9: 読解 | J9: =VLOOKUP(A9,集計!A9:N15,10,FALSE)/60 -> #VALUE! | K9: =IF(学生配布用!$J9>=0.67,"A",IF(学生配布用!$J9>=0.34,"B","C")) -> #VALUE! | L9: 聴解 | M9: =VLOOKUP(A9,集計!A9:N15,14,FALSE)/60 -> #VALUE! | N9: =IF(学生配布用!$M9>=0.67,"A",IF(学生配布用!$M9>=0.34,"B","C")) -> #VALUE! | O9: =VLOOKUP(A9,集計!A9:U15,19,FALSE) -> #VALUE! | P9: =VLOOKUP(A9,集計!A9:U15,21,FALSE) -> #VALUE!
A10: =T_受験者[[#This Row],[学籍番号]] -> #VALUE! | B10: =T_受験者[[#This Row],[名前]] -> #VALUE! | C10: 文字・語彙 | D10: =VLOOKUP(A10,集計!A9:N16,6,FALSE)/60 -> #VALUE! | E10: =IF(学生配布用!$D10>=0.67,"A",IF(学生配布用!$D10>=0.34,"B","C")) -> #VALUE! | F10: 文法 | G10: =VLOOKUP(A10,集計!A9:N16,8,FALSE)/60 -> #VALUE! | H10: =IF(学生配布用!$G10>=0.67,"A",IF(学生配布用!$G10>=0.34,"B","C")) -> #VALUE! | I10: 読解 | J10: =VLOOKUP(A10,集計!A9:N16,10,FALSE)/60 -> #VALUE! | K10: =IF(学生配布用!$J10>=0.67,"A",IF(学生配布用!$J10>=0.34,"B","C")) -> #VALUE! | L10: 聴解 | M10: =VLOOKUP(A10,集計!A9:N16,14,FALSE)/60 -> #VALUE! | N10: =IF(学生配布用!$M10>=0.67,"A",IF(学生配布用!$M10>=0.34,"B","C")) -> #VALUE! | O10: =VLOOKUP(A10,集計!A9:U16,19,FALSE) -> #VALUE! | P10: =VLOOKUP(A10,集計!A9:U16,21,FALSE) -> #VALUE!
A11: =T_受験者[[#This Row],[学籍番号]] -> #VALUE! | B11: =T_受験者[[#This Row],[名前]] -> #VALUE! | C11: 文字・語彙 | D11: =VLOOKUP(A11,集計!A9:N17,6,FALSE)/60 -> #VALUE! | E11: =IF(学生配布用!$D11>=0.67,"A",IF(学生配布用!$D11>=0.34,"B","C")) -> #VALUE! | F11: 文法 | G11: =VLOOKUP(A11,集計!A9:N17,8,FALSE)/60 -> #VALUE! | H11: =IF(学生配布用!$G11>=0.67,"A",IF(学生配布用!$G11>=0.34,"B","C")) -> #VALUE! | I11: 読解 | J11: =VLOOKUP(A11,集計!A9:N17,10,FALSE)/60 -> #VALUE! | K11: =IF(学生配布用!$J11>=0.67,"A",IF(学生配布用!$J11>=0.34,"B","C")) -> #VALUE! | L11: 聴解 | M11: =VLOOKUP(A11,集計!A9:N17,14,FALSE)/60 -> #VALUE! | N11: =IF(学生配布用!$M11>=0.67,"A",IF(学生配布用!$M11>=0.34,"B","C")) -> #VALUE! | O11: =VLOOKUP(A11,集計!A9:U17,19,FALSE) -> #VALUE! | P11: =VLOOKUP(A11,集計!A9:U17,21,FALSE) -> #VALUE!
A12: =T_受験者[[#This Row],[学籍番号]] -> #VALUE! | B12: =T_受験者[[#This Row],[名前]] -> #VALUE! | C12: 文字・語彙 | D12: =VLOOKUP(A12,集計!A9:N18,6,FALSE)/60 -> #VALUE! | E12: =IF(学生配布用!$D12>=0.67,"A",IF(学生配布用!$D12>=0.34,"B","C")) -> #VALUE! | F12: 文法 | G12: =VLOOKUP(A12,集計!A9:N18,8,FALSE)/60 -> #VALUE! | H12: =IF(学生配布用!$G12>=0.67,"A",IF(学生配布用!$G12>=0.34,"B","C")) -> #VALUE! | I12: 読解 | J12: =VLOOKUP(A12,集計!A9:N18,10,FALSE)/60 -> #VALUE! | K12: =IF(学生配布用!$J12>=0.67,"A",IF(学生配布用!$J12>=0.34,"B","C")) -> #VALUE! | L12: 聴解 | M12: =VLOOKUP(A12,集計!A9:N18,14,FALSE)/60 -> #VALUE! | N12: =IF(学生配布用!$M12>=0.67,"A",IF(学生配布用!$M12>=0.34,"B","C")) -> #VALUE! | O12: =VLOOKUP(A12,集計!A9:U18,19,FALSE) -> #VALUE! | P12: =VLOOKUP(A12,集計!A9:U18,21,FALSE) -> #VALUE!
