Workbook
Name 時期選択肢: 選択肢!$A$2:$A$11
Name 進路区分: 選択肢!$C$2:$C$6

Sheet 進路状況入力シート
A1: ="卒業予定人数："&COUNT(T_学生別進路[学籍番号])&"名" -> 卒業予定人数：240名
A2: ="進学確定人数："&COUNTIF(T_学生別進路[進学確定],"○")&"／"&COUNT(T_学生別進路[学籍番号])-COUNTIF(T_進路入力[状況],"進学以外")&"名（"&TEXT(COUNTIF(T_学生別進路[進学確定],"○")/(COUNT(T_学生別進路[学籍番号])-COUNTIF(T_進路入力[状況],"進学以外")),"0.0"&"％）") -> 進学確定人数：216／217名（99.5%)
A3: ="進学以外の人数："&COUNTIF(T_進路入力[状況],"進学以外")&"名" -> 進学以外の人数：23名
A6: 学籍番号 | B6: クラス | C6: 氏名 | D6: 学校名 | E6: 学部、学科、試験区分、備考 | F6: 状況 | G6: 試験日 | H6: 合格発表日 | I6: 進学以外 | J6: 進路決定 | K6: 進路決定確認ワーク | L6: 進路決定者フラグ
A7: 2404012 | B7: 2-1 | C7: KAUNG KHANT KYAW | E7: 特定活動ビザ希望 | F7: 進学以外 | I7: 特定活動 | K7: =T_進路入力[[#This Row],[学籍番号]]&T_進路入力[[#This Row],[進路決定]] -> 2404012 | L7: =_xlfn.IFNA(RIGHT(VLOOKUP(T_進路入力[[#This Row],[学籍番号]]&"○",T_進路入力[進路決定確認ワーク],1,FALSE),1),"")
A8: 2404021 | B8: 2-1 | C8: NANG PHWAY WADI OO | D8: 大手前大学 | F8: 不合格 | G8: 45967 | H8: 45981 | K8: =T_進路入力[[#This Row],[学籍番号]]&T_進路入力[[#This Row],[進路決定]] -> 2404021 | L8: =_xlfn.IFNA(RIGHT(VLOOKUP(T_進路入力[[#This Row],[学籍番号]]&"○",T_進路入力[進路決定確認ワーク],1,FALSE),1),"") -> ○
A9: 2404021 | B9: 2-1 | C9: NANG PHWAY WADI OO | D9: 大阪モード学園 | F9: 合格 | H9: 45992 | J9: ○ | K9: =T_進路入力[[#This Row],[学籍番号]]&T_進路入力[[#This Row],[進路決定]] -> 2404021○ | L9: =_xlfn.IFNA(RIGHT(VLOOKUP(T_進路入力[[#This Row],[学籍番号]]&"○",T_進路入力[進路決定確認ワーク],1,FALSE),1),"") -> ○
A10: 2404022 | B10: 2-1 | C10: THIRI MAY | D10: 神戸松蔭大学 | E10: 指定校推薦 | F10: 合格 | J10: ○ | K10: =T_進路入力[[#This Row],[学籍番号]]&T_進路入力[[#This Row],[進路決定]] -> 2404022○ | L10: =_xlfn.IFNA(RIGHT(VLOOKUP(T_進路入力[[#This Row],[学籍番号]]&"○",T_進路入力[進路決定確認ワーク],1,FALSE),1),"") -> ○
A11: 2404025 | B11: 2-1 | C11: MIN THIHA | D11: 中央工学校OSAKA | E11: 併願 | F11: 検討中 | K11: =T_進路入力[[#This Row],[学籍番号]]&T_進路入力[[#This Row],[進路決定]] -> 2404025 | L11: =_xlfn.IFNA(RIGHT(VLOOKUP(T_進路入力[[#This Row],[学籍番号]]&"○",T_進路入力[進路決定確認ワーク],1,FALSE),1),"") -> ○
A12: 2404025 | B12: 2-1 | C12: MIN THIHA | D12: 大阪産業大学 | E12: 併願 | F12: 合格 | G12: 46081 | H12: 46092 | J12: ○ | K12: =T_進路入力[[#This Row],[学籍番号]]&T_進路入力[[#This Row],[進路決定]] -> 2404025○ | L12: =_xlfn.IFNA(RIGHT(VLOOKUP(T_進路入力[[#This Row],[学籍番号]]&"○",T_進路入力[進路決定確認ワーク],1,FALSE),1),"") -> ○
A13: 2404025 | B13: 2-1 | C13: MIN THIHA | D13: 大阪モード学園 | E13: 併願 | F13: 辞退 | G13: 46074 | H13: 46079 | K13: =T_進路入力[[#This Row],[学籍番号]]&T_進路入力[[#This Row],[進路決定]] -> 2404025 | L13: =_xlfn.IFNA(RIGHT(VLOOKUP(T_進路入力[[#This Row],[学籍番号]]&"○",T_進路入力[進路決定確認ワーク],1,FALSE),1),"") -> ○
A14: 2404025 | B14: 2-1 | C14: MIN THIHA | D14: ECC国際外語専門学校 | F14: 不合格 | G14: 45986 | K14: =T_進路入力[[#This Row],[学籍番号]]&T_進路入力[[#This Row],[進路決定]] -> 2404025 | L14: =_xlfn.IFNA(RIGHT(VLOOKUP(T_進路入力[[#This Row],[学籍番号]]&"○",T_進路入力[進路決定確認ワーク],1,FALSE),1),"") -> ○
A15: 2404027 | B15: 2-1 | C15: PHYO SI THU | D15: 東京テクニカルカレッジ | E15: 1回目、電子学科 | F15: 不合格 | G15: 45960 | K15: =T_進路入力[[#This Row],[学籍番号]]&T_進路入力[[#This Row],[進路決定]] -> 2404027 | L15: =_xlfn.IFNA(RIGHT(VLOOKUP(T_進路入力[[#This Row],[学籍番号]]&"○",T_進路入力[進路決定確認ワーク],1,FALSE),1),"") -> ○
A16: 2404027 | B16: 2-1 | C16: PHYO SI THU | D16: 東京テクニカルカレッジ | E16: 2回目、AI学科 | F16: 合格 | G16: 45991 | H16: 46001 | J16: ○ | K16: =T_進路入力[[#This Row],[学籍番号]]&T_進路入力[[#This Row],[進路決定]] -> 2404027○ | L16: =_xlfn.IFNA(RIGHT(VLOOKUP(T_進路入力[[#This Row],[学籍番号]]&"○",T_進路入力[進路決定確認ワーク],1,FALSE),1),"") -> ○
A17: 2404027 | B17: 2-1 | C17: PHYO SI THU | D17: 大阪電子専門学校 | F17: 試験待ち | G17: 46002 | K17: =T_進路入力[[#This Row],[学籍番号]]&T_進路入力[[#This Row],[進路決定]] -> 2404027 | L17: =_xlfn.IFNA(RIGHT(VLOOKUP(T_進路入力[[#This Row],[学籍番号]]&"○",T_進路入力[進路決定確認ワーク],1,FALSE),1),"") -> ○
A18: 2404031 | B18: 2-1 | C18: NWAY NWAY TUN | D18: 東京テクニカルカレッジ | F18: 合格 | G18: 45937 | J18: ○ | K18: =T_進路入力[[#This Row],[学籍番号]]&T_進路入力[[#This Row],[進路決定]] -> 2404031○ | L18: =_xlfn.IFNA(RIGHT(VLOOKUP(T_進路入力[[#This Row],[学籍番号]]&"○",T_進路入力[進路決定確認ワーク],1,FALSE),1),"") -> ○
A19: 2404042 | B19: 2-1 | C19: PHU PHU MYAT THU | D19: ECC国際外語専門学校 | F19: 合格 | G19: 45986 | H19: 45993 | J19: ○ | K19: =T_進路入力[[#This Row],[学籍番号]]&T_進路入力[[#This Row],[進路決定]] -> 2404042○ | L19: =_xlfn.IFNA(RIGHT(VLOOKUP(T_進路入力[[#This Row],[学籍番号]]&"○",T_進路入力[進路決定確認ワーク],1,FALSE),1),"") -> ○
A20: 2404043 | B20: 2-1 | C20: RITA HLA MOE | D20: 神戸国際大学 | F20: 合格 | G20: 45933 | J20: ○ | K20: =T_進路入力[[#This Row],[学籍番号]]&T_進路入力[[#This Row],[進路決定]] -> 2404043○ | L20: =_xlfn.IFNA(RIGHT(VLOOKUP(T_進路入力[[#This Row],[学籍番号]]&"○",T_進路入力[進路決定確認ワーク],1,FALSE),1),"") -> ○
A21: 2404025 | B21: 2-1 | C21: MIN THIHA | D21: 関西国際旅行ホテル専門学校 | F21: 不合格 | K21: =T_進路入力[[#This Row],[学籍番号]]&T_進路入力[[#This Row],[進路決定]] -> 2404025 | L21: =_xlfn.IFNA(RIGHT(VLOOKUP(T_進路入力[[#This Row],[学籍番号]]&"○",T_進路入力[進路決定確認ワーク],1,FALSE),1),"") -> ○
A22: 2404046 | B22: 2-1 | C22: KYAL SIN LIN | D22: ECC国際外語専門学校 | F22: 合格 | G22: 46004 | H22: 46007 | J22: ○ | K22: =T_進路入力[[#This Row],[学籍番号]]&T_進路入力[[#This Row],[進路決定]] -> 2404046○ | L22: =_xlfn.IFNA(RIGHT(VLOOKUP(T_進路入力[[#This Row],[学籍番号]]&"○",T_進路入力[進路決定確認ワーク],1,FALSE),1),"") -> ○
A23: 2404047 | B23: 2-1 | C23: KHIN YADANAR OO | D23: エール学園 | F23: 合格 | G23: 46039 | H23: 46048 | J23: ○ | K23: =T_進路入力[[#This Row],[学籍番号]]&T_進路入力[[#This Row],[進路決定]] -> 2404047○ | L23: =_xlfn.IFNA(RIGHT(VLOOKUP(T_進路入力[[#This Row],[学籍番号]]&"○",T_進路入力[進路決定確認ワーク],1,FALSE),1),"") -> ○
A24: 2404047 | B24: 2-1 | C24: KHIN YADANAR OO | D24: 中央工学校 | F24: 不合格 | G24: 46001 | H24: 46008 | K24: =T_進路入力[[#This Row],[学籍番号]]&T_進路入力[[#This Row],[進路決定]] -> 2404047 | L24: =_xlfn.IFNA(RIGHT(VLOOKUP(T_進路入力[[#This Row],[学籍番号]]&"○",T_進路入力[進路決定確認ワーク],1,FALSE),1),"") -> ○
A25: 2404050 | B25: 2-1 | C25: THUTA ZAW | D25: 東京みらいIT&AI専門学校 | F25: 合格 | G25: 45983 | H25: 45989 | J25: ○ | K25: =T_進路入力[[#This Row],[学籍番号]]&T_進路入力[[#This Row],[進路決定]] -> 2404050○ | L25: =_xlfn.IFNA(RIGHT(VLOOKUP(T_進路入力[[#This Row],[学籍番号]]&"○",T_進路入力[進路決定確認ワーク],1,FALSE),1),"") -> ○
A26: 2404051 | B26: 2-1 | C26: KAUNG ZIN NYI | D26: 中央工学校 | E26: 東京で日本語を勉強できる専門学校 | F26: 合格 | G26: 46001 | H26: 46008 | J26: ○ | K26: =T_進路入力[[#This Row],[学籍番号]]&T_進路入力[[#This Row],[進路決定]] -> 2404051○ | L26: =_xlfn.IFNA(RIGHT(VLOOKUP(T_進路入力[[#This Row],[学籍番号]]&"○",T_進路入力[進路決定確認ワーク],1,FALSE),1),"") -> ○
A27: 2404058 | B27: 2-1 | C27: HAN THU SAN | D27: 大手前大学 | F27: 合格 | G27: 45966 | H27: 45981 | J27: ○ | K27: =T_進路入力[[#This Row],[学籍番号]]&T_進路入力[[#This Row],[進路決定]] -> 2404058○ | L27: =_xlfn.IFNA(RIGHT(VLOOKUP(T_進路入力[[#This Row],[学籍番号]]&"○",T_進路入力[進路決定確認ワーク],1,FALSE),1),"") -> ○
A28: 2404073 | B28: 2-1 | C28: FAKIR SHAKIB | D28: 東京国際ビジネスカレッジ神戸校 | F28: 合格 | G28: 45997 | H28: 46001 | J28: ○ | K28: =T_進路入力[[#This Row],[学籍番号]]&T_進路入力[[#This Row],[進路決定]] -> 2404073○ | L28: =_xlfn.IFNA(RIGHT(VLOOKUP(T_進路入力[[#This Row],[学籍番号]]&"○",T_進路入力[進路決定確認ワーク],1,FALSE),1),"") -> ○
A29: 2404084 | B29: 2-1 | C29: MD. MATIUR RAHMAN | D29: 流通科学大学 | F29: 合格 | G29: 45948 | H29: 45965 | J29: ○ | K29: =T_進路入力[[#This Row],[学籍番号]]&T_進路入力[[#This Row],[進路決定]] -> 2404084○ | L29: =_xlfn.IFNA(RIGHT(VLOOKUP(T_進路入力[[#This Row],[学籍番号]]&"○",T_進路入力[進路決定確認ワーク],1,FALSE),1),"") -> ○
A30: 2404093 | B30: 2-1 | C30: DELWAR HOSHEN SAYED | D30: 流通科学大学 | F30: 合格 | G30: 45948 | H30: 45965 | J30: ○ | K30: =T_進路入力[[#This Row],[学籍番号]]&T_進路入力[[#This Row],[進路決定]] -> 2404093○ | L30: =_xlfn.IFNA(RIGHT(VLOOKUP(T_進路入力[[#This Row],[学籍番号]]&"○",T_進路入力[進路決定確認ワーク],1,FALSE),1),"") -> ○
A31: 2407013 | B31: 2-1 | C31: SOE NYI HTUT | D31: 立命館大学 | F31: 不合格 | G31: 46068 | H31: 45961 | K31: =T_進路入力[[#This Row],[学籍番号]]&T_進路入力[[#This Row],[進路決定]] -> 2407013 | L31: =_xlfn.IFNA(RIGHT(VLOOKUP(T_進路入力[[#This Row],[学籍番号]]&"○",T_進路入力[進路決定確認ワーク],1,FALSE),1),"") -> ○
A32: 2407013 | B32: 2-1 | C32: SOE NYI HTUT | D32: 大阪国際大学 | E32: 国際コミュニケーション科 | F32: 検討中 | G32: 45977 | H32: 45964 | K32: =T_進路入力[[#This Row],[学籍番号]]&T_進路入力[[#This Row],[進路決定]] -> 2407013 | L32: =_xlfn.IFNA(RIGHT(VLOOKUP(T_進路入力[[#This Row],[学籍番号]]&"○",T_進路入力[進路決定確認ワーク],1,FALSE),1),"") -> ○
A33: 2407013 | B33: 2-1 | C33: SOE NYI HTUT | D33: 大阪学院大学 | F33: 合格 | H33: 46080 | J33: ○ | K33: =T_進路入力[[#This Row],[学籍番号]]&T_進路入力[[#This Row],[進路決定]] -> 2407013○ | L33: =_xlfn.IFNA(RIGHT(VLOOKUP(T_進路入力[[#This Row],[学籍番号]]&"○",T_進路入力[進路決定確認ワーク],1,FALSE),1),"") -> ○
A34: 2407025 | B34: 2-1 | C34: KHIN PYAE SONE | D34: 神戸電子専門学校 | F34: 合格 | G34: 45958 | J34: ○ | K34: =T_進路入力[[#This Row],[学籍番号]]&T_進路入力[[#This Row],[進路決定]] -> 2407025○ | L34: =_xlfn.IFNA(RIGHT(VLOOKUP(T_進路入力[[#This Row],[学籍番号]]&"○",T_進路入力[進路決定確認ワーク],1,FALSE),1),"") -> ○
A35: 2407013 | B35: 2-1 | C35: SOE NYI HTUT | D35: 大阪学院大学 | E35: 国際学部 | F35: 結果待ち | G35: 46074 | H35: 46080 | K35: =T_進路入力[[#This Row],[学籍番号]]&T_進路入力[[#This Row],[進路決定]] -> 2407013 | L35: =_xlfn.IFNA(RIGHT(VLOOKUP(T_進路入力[[#This Row],[学籍番号]]&"○",T_進路入力[進路決定確認ワーク],1,FALSE),1),"") -> ○
A36: 2404011 | B36: 2-2 | C36: BUI NGOC ANH THU | D36: 東京国際ビジネスカレッジ神戸校 | E36: キャリアコミュケーション | F36: 合格 | G36: 46067 | J36: ○ | K36: =T_進路入力[[#This Row],[学籍番号]]&T_進路入力[[#This Row],[進路決定]] -> 2404011○ | L36: =_xlfn.IFNA(RIGHT(VLOOKUP(T_進路入力[[#This Row],[学籍番号]]&"○",T_進路入力[進路決定確認ワーク],1,FALSE),1),"") -> ○
A37: 2404013 | B37: 2-2 | C37: CHIT MAUNG MAUNG | F37: 進学以外 | I37: 特定活動 | K37: =T_進路入力[[#This Row],[学籍番号]]&T_進路入力[[#This Row],[進路決定]] -> 2404013 | L37: =_xlfn.IFNA(RIGHT(VLOOKUP(T_進路入力[[#This Row],[学籍番号]]&"○",T_進路入力[進路決定確認ワーク],1,FALSE),1),"")
A38: 2404013 | B38: 2-2 | C38: CHIT MAUNG MAUNG | D38: 花壇自動車専門学校 | F38: 不合格 | G38: 45974 | H38: 45989 | K38: =T_進路入力[[#This Row],[学籍番号]]&T_進路入力[[#This Row],[進路決定]] -> 2404013 | L38: =_xlfn.IFNA(RIGHT(VLOOKUP(T_進路入力[[#This Row],[学籍番号]]&"○",T_進路入力[進路決定確認ワーク],1,FALSE),1),"")
A39: 2404013 | B39: 2-2 | C39: CHIT MAUNG MAUNG | D39: 国際外語・観光・エアライン専門学校 | E39: １年日本語コース→新潟国際自動車大学校 | F39: 辞退 | G39: 46044 | H39: 46056 | K39: =T_進路入力[[#This Row],[学籍番号]]&T_進路入力[[#This Row],[進路決定]] -> 2404013 | L39: =_xlfn.IFNA(RIGHT(VLOOKUP(T_進路入力[[#This Row],[学籍番号]]&"○",T_進路入力[進路決定確認ワーク],1,FALSE),1),"")
A40: 2404015 | B40: 2-2 | C40: NAY LIN OO | D40: 流通科学大学 | F40: 辞退 | K40: =T_進路入力[[#This Row],[学籍番号]]&T_進路入力[[#This Row],[進路決定]] -> 2404015 | L40: =_xlfn.IFNA(RIGHT(VLOOKUP(T_進路入力[[#This Row],[学籍番号]]&"○",T_進路入力[進路決定確認ワーク],1,FALSE),1),"") -> ○
A41: 2404015 | B41: 2-2 | C41: NAY LIN OO | D41: 神戸松蔭大学 | E41: (指定校推薦) | F41: 合格 | G41: 46056 | H41: 46069 | J41: ○ | K41: =T_進路入力[[#This Row],[学籍番号]]&T_進路入力[[#This Row],[進路決定]] -> 2404015○ | L41: =_xlfn.IFNA(RIGHT(VLOOKUP(T_進路入力[[#This Row],[学籍番号]]&"○",T_進路入力[進路決定確認ワーク],1,FALSE),1),"") -> ○
A42: 2404016 | B42: 2-2 | C42: THAW ZIN HTUN | D42: 神戸電子専門学校 | E42: AIシステム開発学科 | F42: 合格 | G42: 46003 | H42: 46009 | J42: ○ | K42: =T_進路入力[[#This Row],[学籍番号]]&T_進路入力[[#This Row],[進路決定]] -> 2404016○ | L42: =_xlfn.IFNA(RIGHT(VLOOKUP(T_進路入力[[#This Row],[学籍番号]]&"○",T_進路入力[進路決定確認ワーク],1,FALSE),1),"") -> ○
...

Sheet 【印刷用】進路状況入力シート
A1: =進路状況入力シート!A1 -> 卒業予定人数：240名
A2: =進路状況入力シート!A2 -> 進学確定人数：216／217名（99.5%)
A3: =進路状況入力シート!A3 -> 進学以外の人数：23名
A6: 学籍番号 | B6: クラス | C6: 氏名 | D6: 学校名 | E6: 学部、学科、試験区分、備考 | F6: 状況 | G6: 試験日 | H6: 合格発表日 | I6: 進学以外 | J6: 進路決定 | K6: 進路決定確認ワーク | L6: 進路決定者フラグ
A7: {=T_進路入力[]} -> 2404012 | B7: 2-1 | C7: KAUNG KHANT KYAW | D7: 0 | E7: 特定活動ビザ希望 | F7: 進学以外 | G7: 0 | H7: 0 | I7: 特定活動 | J7: 0 | K7: 2404012
A8: 2404021 | B8: 2-1 | C8: NANG PHWAY WADI OO | D8: 大手前大学 | E8: 0 | F8: 不合格 | G8: 45967 | H8: 45981 | I8: 0 | J8: 0 | K8: 2404021 | L8: ○
A9: 2404021 | B9: 2-1 | C9: NANG PHWAY WADI OO | D9: 大阪モード学園 | E9: 0 | F9: 合格 | G9: 0 | H9: 45992 | I9: 0 | J9: ○ | K9: 2404021○ | L9: ○
A10: 2404022 | B10: 2-1 | C10: THIRI MAY | D10: 神戸松蔭大学 | E10: 指定校推薦 | F10: 合格 | G10: 0 | H10: 0 | I10: 0 | J10: ○ | K10: 2404022○ | L10: ○
A11: 2404025 | B11: 2-1 | C11: MIN THIHA | D11: 中央工学校OSAKA | E11: 併願 | F11: 検討中 | G11: 0 | H11: 0 | I11: 0 | J11: 0 | K11: 2404025 | L11: ○
A12: 2404025 | B12: 2-1 | C12: MIN THIHA | D12: 大阪産業大学 | E12: 併願 | F12: 合格 | G12: 46081 | H12: 46092 | I12: 0 | J12: ○ | K12: 2404025○ | L12: ○
A13: 2404025 | B13: 2-1 | C13: MIN THIHA | D13: 大阪モード学園 | E13: 併願 | F13: 辞退 | G13: 46074 | H13: 46079 | I13: 0 | J13: 0 | K13: 2404025 | L13: ○
A14: 2404025 | B14: 2-1 | C14: MIN THIHA | D14: ECC国際外語専門学校 | E14: 0 | F14: 不合格 | G14: 45986 | H14: 0 | I14: 0 | J14: 0 | K14: 2404025 | L14: ○
A15: 2404027 | B15: 2-1 | C15: PHYO SI THU | D15: 東京テクニカルカレッジ | E15: 1回目、電子学科 | F15: 不合格 | G15: 45960 | H15: 0 | I15: 0 | J15: 0 | K15: 2404027 | L15: ○
A16: 2404027 | B16: 2-1 | C16: PHYO SI THU | D16: 東京テクニカルカレッジ | E16: 2回目、AI学科 | F16: 合格 | G16: 45991 | H16: 46001 | I16: 0 | J16: ○ | K16: 2404027○ | L16: ○
A17: 2404027 | B17: 2-1 | C17: PHYO SI THU | D17: 大阪電子専門学校 | E17: 0 | F17: 試験待ち | G17: 46002 | H17: 0 | I17: 0 | J17: 0 | K17: 2404027 | L17: ○
A18: 2404031 | B18: 2-1 | C18: NWAY NWAY TUN | D18: 東京テクニカルカレッジ | E18: 0 | F18: 合格 | G18: 45937 | H18: 0 | I18: 0 | J18: ○ | K18: 2404031○ | L18: ○
A19: 2404042 | B19: 2-1 | C19: PHU PHU MYAT THU | D19: ECC国際外語専門学校 | E19: 0 | F19: 合格 | G19: 45986 | H19: 45993 | I19: 0 | J19: ○ | K19: 2404042○ | L19: ○
A20: 2404043 | B20: 2-1 | C20: RITA HLA MOE | D20: 神戸国際大学 | E20: 0 | F20: 合格 | G20: 45933 | H20: 0 | I20: 0 | J20: ○ | K20: 2404043○ | L20: ○
A21: 2404025 | B21: 2-1 | C21: MIN THIHA | D21: 関西国際旅行ホテル専門学校 | E21: 0 | F21: 不合格 | G21: 0 | H21: 0 | I21: 0 | J21: 0 | K21: 2404025 | L21: ○
A22: 2404046 | B22: 2-1 | C22: KYAL SIN LIN | D22: ECC国際外語専門学校 | E22: 0 | F22: 合格 | G22: 46004 | H22: 46007 | I22: 0 | J22: ○ | K22: 2404046○ | L22: ○
A23: 2404047 | B23: 2-1 | C23: KHIN YADANAR OO | D23: エール学園 | E23: 0 | F23: 合格 | G23: 46039 | H23: 46048 | I23: 0 | J23: ○ | K23: 2404047○ | L23: ○
A24: 2404047 | B24: 2-1 | C24: KHIN YADANAR OO | D24: 中央工学校 | E24: 0 | F24: 不合格 | G24: 46001 | H24: 46008 | I24: 0 | J24: 0 | K24: 2404047 | L24: ○
A25: 2404050 | B25: 2-1 | C25: THUTA ZAW | D25: 東京みらいIT&AI専門学校 | E25: 0 | F25: 合格 | G25: 45983 | H25: 45989 | I25: 0 | J25: ○ | K25: 2404050○ | L25: ○
A26: 2404051 | B26: 2-1 | C26: KAUNG ZIN NYI | D26: 中央工学校 | E26: 東京で日本語を勉強できる専門学校 | F26: 合格 | G26: 46001 | H26: 46008 | I26: 0 | J26: ○ | K26: 2404051○ | L26: ○
A27: 2404058 | B27: 2-1 | C27: HAN THU SAN | D27: 大手前大学 | E27: 0 | F27: 合格 | G27: 45966 | H27: 45981 | I27: 0 | J27: ○ | K27: 2404058○ | L27: ○
A28: 2404073 | B28: 2-1 | C28: FAKIR SHAKIB | D28: 東京国際ビジネスカレッジ神戸校 | E28: 0 | F28: 合格 | G28: 45997 | H28: 46001 | I28: 0 | J28: ○ | K28: 2404073○ | L28: ○
A29: 2404084 | B29: 2-1 | C29: MD. MATIUR RAHMAN | D29: 流通科学大学 | E29: 0 | F29: 合格 | G29: 45948 | H29: 45965 | I29: 0 | J29: ○ | K29: 2404084○ | L29: ○
A30: 2404093 | B30: 2-1 | C30: DELWAR HOSHEN SAYED | D30: 流通科学大学 | E30: 0 | F30: 合格 | G30: 45948 | H30: 45965 | I30: 0 | J30: ○ | K30: 2404093○ | L30: ○
A31: 2407013 | B31: 2-1 | C31: SOE NYI HTUT | D31: 立命館大学 | E31: 0 | F31: 不合格 | G31: 46068 | H31: 45961 | I31: 0 | J31: 0 | K31: 2407013 | L31: ○
A32: 2407013 | B32: 2-1 | C32: SOE NYI HTUT | D32: 大阪国際大学 | E32: 国際コミュニケーション科 | F32: 検討中 | G32: 45977 | H32: 45964 | I32: 0 | J32: 0 | K32: 2407013 | L32: ○
A33: 2407013 | B33: 2-1 | C33: SOE NYI HTUT | D33: 大阪学院大学 | E33: 0 | F33: 合格 | G33: 0 | H33: 46080 | I33: 0 | J33: ○ | K33: 2407013○ | L33: ○
A34: 2407025 | B34: 2-1 | C34: KHIN PYAE SONE | D34: 神戸電子専門学校 | E34: 0 | F34: 合格 | G34: 45958 | H34: 0 | I34: 0 | J34: ○ | K34: 2407025○ | L34: ○
A35: 2407013 | B35: 2-1 | C35: SOE NYI HTUT | D35: 大阪学院大学 | E35: 国際学部 | F35: 結果待ち | G35: 46074 | H35: 46080 | I35: 0 | J35: 0 | K35: 2407013 | L35: ○
A36: 2404011 | B36: 2-2 | C36: BUI NGOC ANH THU | D36: 東京国際ビジネスカレッジ神戸校 | E36: キャリアコミュケーション | F36: 合格 | G36: 46067 | H36: 0 | I36: 0 | J36: ○ | K36: 2404011○ | L36: ○
A37: 2404013 | B37: 2-2 | C37: CHIT MAUNG MAUNG | D37: 0 | E37: 0 | F37: 進学以外 | G37: 0 | H37: 0 | I37: 特定活動 | J37: 0 | K37: 2404013
A38: 2404013 | B38: 2-2 | C38: CHIT MAUNG MAUNG | D38: 花壇自動車専門学校 | E38: 0 | F38: 不合格 | G38: 45974 | H38: 45989 | I38: 0 | J38: 0 | K38: 2404013
A39: 2404013 | B39: 2-2 | C39: CHIT MAUNG MAUNG | D39: 国際外語・観光・エアライン専門学校 | E39: １年日本語コース→新潟国際自動車大学校 | F39: 辞退 | G39: 46044 | H39: 46056 | I39: 0 | J39: 0 | K39: 2404013
A40: 2404015 | B40: 2-2 | C40: NAY LIN OO | D40: 流通科学大学 | E40: 0 | F40: 辞退 | G40: 0 | H40: 0 | I40: 0 | J40: 0 | K40: 2404015 | L40: ○
A41: 2404015 | B41: 2-2 | C41: NAY LIN OO | D41: 神戸松蔭大学 | E41: (指定校推薦) | F41: 合格 | G41: 46056 | H41: 46069 | I41: 0 | J41: ○ | K41: 2404015○ | L41: ○
A42: 2404016 | B42: 2-2 | C42: THAW ZIN HTUN | D42: 神戸電子専門学校 | E42: AIシステム開発学科 | F42: 合格 | G42: 46003 | H42: 46009 | I42: 0 | J42: ○ | K42: 2404016○ | L42: ○
...

Sheet 学生別進路確定閲覧シート
A1: =進路状況入力シート!A1 -> 卒業予定人数：240名
A2: =進路状況入力シート!A2 -> 進学確定人数：216／217名（99.5%)
A3: =進路状況入力シート!A3 -> 進学以外の人数：23名
K5: 45991 | L5: 46022 | M5: 46053 | N5: 46081 | O5: 46112
A6: 学籍番号 | B6: クラス | C6: 名前 | D6: 進学確定 | E6: 進路確定 | F6: 進路確定フラグ | G6: 進学希望フラグ | H6: 合格校 | I6: 安心度 | J6: 合格時期 | K6: 11月末時点合格 | L6: 12月末時点合格 | M6: 1月末時点合格 | N6: 2月末時点合格 | O6: 3月末時点合格 | P6: 4月末時点合格
A7: 2404012 | B7: =VLOOKUP(T_学生別進路[[#This Row],[学籍番号]],進路状況入力シート!A:B,2,FALSE) -> 2-1 | C7: =VLOOKUP(T_学生別進路[[#This Row],[学籍番号]],進路状況入力シート!A:C,3,FALSE) -> KAUNG KHANT KYAW | D7: =IF(AND(T_学生別進路[[#This Row],[進路確定]]="○",T_学生別進路[[#This Row],[進学希望フラグ]]=1),"○","") | E7: =_xlfn.IFNA(RIGHT(VLOOKUP(T_学生別進路[[#This Row],[学籍番号]]&"○",進路状況入力シート!K:K,1,FALSE),1),"") | F7: =IF(T_学生別進路[[#This Row],[進学希望フラグ]]=0,"",IF(T_学生別進路[[#This Row],[進路確定]]="○",1,0)) | G7: =IF( AND( COUNTIFS(T_進路入力[学籍番号],T_学生別進路[[#This Row],[学籍番号]], T_進路入力[状況],"進学以外")>0, COUNTIFS(T_進路入力[学籍番号],T_学生別進路[[#This Row],[学籍番号]], T_進路入力[状況],"<>進学以外")>0 ), 0, IF(VLOOKUP(T_学生別進路[[#This Row],[学籍番号]],T_進路入力[],6,FALSE)="進学以外",0,1) ) -> 0 | H7: =_xlfn.XLOOKUP(T_学生別進路[[#This Row],[学籍番号]]&"○",進路状況入力シート!K:K,進路状況入力シート!D:D,"",0,1) | K7: =IF(T_学生別進路[[#This Row],[合格時期]]="",0,IF(T_学生別進路[[#This Row],[合格時期]]<K$5,1,0)) -> 0 | L7: =IF(T_学生別進路[[#This Row],[合格時期]]="",0,IF(T_学生別進路[[#This Row],[合格時期]]<L$5,1,0)) -> 0 | M7: =IF(T_学生別進路[[#This Row],[合格時期]]="",0,IF(T_学生別進路[[#This Row],[合格時期]]<M$5,1,0)) -> 0 | N7: =IF(T_学生別進路[[#This Row],[合格時期]]="",0,IF(T_学生別進路[[#This Row],[合格時期]]<N$5,1,0)) -> 0 | O7: =IF(T_学生別進路[[#This Row],[合格時期]]="",0,IF(T_学生別進路[[#This Row],[合格時期]]<O$5,1,0)) -> 0 | P7: 5/24期限
A8: 2404021 | B8: =VLOOKUP(T_学生別進路[[#This Row],[学籍番号]],進路状況入力シート!A:B,2,FALSE) -> 2-1 | C8: =VLOOKUP(T_学生別進路[[#This Row],[学籍番号]],進路状況入力シート!A:C,3,FALSE) -> NANG PHWAY WADI OO | D8: =IF(AND(T_学生別進路[[#This Row],[進路確定]]="○",T_学生別進路[[#This Row],[進学希望フラグ]]=1),"○","") -> ○ | E8: =_xlfn.IFNA(RIGHT(VLOOKUP(T_学生別進路[[#This Row],[学籍番号]]&"○",進路状況入力シート!K:K,1,FALSE),1),"") -> ○ | F8: =IF(T_学生別進路[[#This Row],[進学希望フラグ]]=0,"",IF(T_学生別進路[[#This Row],[進路確定]]="○",1,0)) -> 1 | G8: =IF( AND( COUNTIFS(T_進路入力[学籍番号],T_学生別進路[[#This Row],[学籍番号]], T_進路入力[状況],"進学以外")>0, COUNTIFS(T_進路入力[学籍番号],T_学生別進路[[#This Row],[学籍番号]], T_進路入力[状況],"<>進学以外")>0 ), 0, IF(VLOOKUP(T_学生別進路[[#This Row],[学籍番号]],T_進路入力[],6,FALSE)="進学以外",0,1) ) -> 1 | H8: =_xlfn.XLOOKUP(T_学生別進路[[#This Row],[学籍番号]]&"○",進路状況入力シート!K:K,進路状況入力シート!D:D,"",0,1) -> 大阪モード学園 | I8: B | J8: 45962 | K8: =IF(T_学生別進路[[#This Row],[合格時期]]="",0,IF(T_学生別進路[[#This Row],[合格時期]]<K$5,1,0)) -> 1 | L8: =IF(T_学生別進路[[#This Row],[合格時期]]="",0,IF(T_学生別進路[[#This Row],[合格時期]]<L$5,1,0)) -> 1 | M8: =IF(T_学生別進路[[#This Row],[合格時期]]="",0,IF(T_学生別進路[[#This Row],[合格時期]]<M$5,1,0)) -> 1 | N8: =IF(T_学生別進路[[#This Row],[合格時期]]="",0,IF(T_学生別進路[[#This Row],[合格時期]]<N$5,1,0)) -> 1 | O8: =IF(T_学生別進路[[#This Row],[合格時期]]="",0,IF(T_学生別進路[[#This Row],[合格時期]]<O$5,1,0)) -> 1
A9: 2404022 | B9: =VLOOKUP(T_学生別進路[[#This Row],[学籍番号]],進路状況入力シート!A:B,2,FALSE) -> 2-1 | C9: =VLOOKUP(T_学生別進路[[#This Row],[学籍番号]],進路状況入力シート!A:C,3,FALSE) -> THIRI MAY | D9: =IF(AND(T_学生別進路[[#This Row],[進路確定]]="○",T_学生別進路[[#This Row],[進学希望フラグ]]=1),"○","") -> ○ | E9: =_xlfn.IFNA(RIGHT(VLOOKUP(T_学生別進路[[#This Row],[学籍番号]]&"○",進路状況入力シート!K:K,1,FALSE),1),"") -> ○ | F9: =IF(T_学生別進路[[#This Row],[進学希望フラグ]]=0,"",IF(T_学生別進路[[#This Row],[進路確定]]="○",1,0)) -> 1 | G9: =IF( AND( COUNTIFS(T_進路入力[学籍番号],T_学生別進路[[#This Row],[学籍番号]], T_進路入力[状況],"進学以外")>0, COUNTIFS(T_進路入力[学籍番号],T_学生別進路[[#This Row],[学籍番号]], T_進路入力[状況],"<>進学以外")>0 ), 0, IF(VLOOKUP(T_学生別進路[[#This Row],[学籍番号]],T_進路入力[],6,FALSE)="進学以外",0,1) ) -> 1 | H9: =_xlfn.XLOOKUP(T_学生別進路[[#This Row],[学籍番号]]&"○",進路状況入力シート!K:K,進路状況入力シート!D:D,"",0,1) -> 神戸松蔭大学 | I9: A | J9: 45992 | K9: =IF(T_学生別進路[[#This Row],[合格時期]]="",0,IF(T_学生別進路[[#This Row],[合格時期]]<K$5,1,0)) -> 0 | L9: =IF(T_学生別進路[[#This Row],[合格時期]]="",0,IF(T_学生別進路[[#This Row],[合格時期]]<L$5,1,0)) -> 1 | M9: =IF(T_学生別進路[[#This Row],[合格時期]]="",0,IF(T_学生別進路[[#This Row],[合格時期]]<M$5,1,0)) -> 1 | N9: =IF(T_学生別進路[[#This Row],[合格時期]]="",0,IF(T_学生別進路[[#This Row],[合格時期]]<N$5,1,0)) -> 1 | O9: =IF(T_学生別進路[[#This Row],[合格時期]]="",0,IF(T_学生別進路[[#This Row],[合格時期]]<O$5,1,0)) -> 1
A10: 2404025 | B10: =VLOOKUP(T_学生別進路[[#This Row],[学籍番号]],進路状況入力シート!A:B,2,FALSE) -> 2-1 | C10: =VLOOKUP(T_学生別進路[[#This Row],[学籍番号]],進路状況入力シート!A:C,3,FALSE) -> MIN THIHA | D10: =IF(AND(T_学生別進路[[#This Row],[進路確定]]="○",T_学生別進路[[#This Row],[進学希望フラグ]]=1),"○","") -> ○ | E10: =_xlfn.IFNA(RIGHT(VLOOKUP(T_学生別進路[[#This Row],[学籍番号]]&"○",進路状況入力シート!K:K,1,FALSE),1),"") -> ○ | F10: =IF(T_学生別進路[[#This Row],[進学希望フラグ]]=0,"",IF(T_学生別進路[[#This Row],[進路確定]]="○",1,0)) -> 1 | G10: =IF( AND( COUNTIFS(T_進路入力[学籍番号],T_学生別進路[[#This Row],[学籍番号]], T_進路入力[状況],"進学以外")>0, COUNTIFS(T_進路入力[学籍番号],T_学生別進路[[#This Row],[学籍番号]], T_進路入力[状況],"<>進学以外")>0 ), 0, IF(VLOOKUP(T_学生別進路[[#This Row],[学籍番号]],T_進路入力[],6,FALSE)="進学以外",0,1) ) -> 1 | H10: =_xlfn.XLOOKUP(T_学生別進路[[#This Row],[学籍番号]]&"○",進路状況入力シート!K:K,進路状況入力シート!D:D,"",0,1) -> 大阪産業大学 | I10: B | J10: 45992 | K10: =IF(T_学生別進路[[#This Row],[合格時期]]="",0,IF(T_学生別進路[[#This Row],[合格時期]]<K$5,1,0)) -> 0 | L10: =IF(T_学生別進路[[#This Row],[合格時期]]="",0,IF(T_学生別進路[[#This Row],[合格時期]]<L$5,1,0)) -> 1 | M10: =IF(T_学生別進路[[#This Row],[合格時期]]="",0,IF(T_学生別進路[[#This Row],[合格時期]]<M$5,1,0)) -> 1 | N10: =IF(T_学生別進路[[#This Row],[合格時期]]="",0,IF(T_学生別進路[[#This Row],[合格時期]]<N$5,1,0)) -> 1 | O10: =IF(T_学生別進路[[#This Row],[合格時期]]="",0,IF(T_学生別進路[[#This Row],[合格時期]]<O$5,1,0)) -> 1
A11: 2404027 | B11: =VLOOKUP(T_学生別進路[[#This Row],[学籍番号]],進路状況入力シート!A:B,2,FALSE) -> 2-1 | C11: =VLOOKUP(T_学生別進路[[#This Row],[学籍番号]],進路状況入力シート!A:C,3,FALSE) -> PHYO SI THU | D11: =IF(AND(T_学生別進路[[#This Row],[進路確定]]="○",T_学生別進路[[#This Row],[進学希望フラグ]]=1),"○","") -> ○ | E11: =_xlfn.IFNA(RIGHT(VLOOKUP(T_学生別進路[[#This Row],[学籍番号]]&"○",進路状況入力シート!K:K,1,FALSE),1),"") -> ○ | F11: =IF(T_学生別進路[[#This Row],[進学希望フラグ]]=0,"",IF(T_学生別進路[[#This Row],[進路確定]]="○",1,0)) -> 1 | G11: =IF( AND( COUNTIFS(T_進路入力[学籍番号],T_学生別進路[[#This Row],[学籍番号]], T_進路入力[状況],"進学以外")>0, COUNTIFS(T_進路入力[学籍番号],T_学生別進路[[#This Row],[学籍番号]], T_進路入力[状況],"<>進学以外")>0 ), 0, IF(VLOOKUP(T_学生別進路[[#This Row],[学籍番号]],T_進路入力[],6,FALSE)="進学以外",0,1) ) -> 1 | H11: =_xlfn.XLOOKUP(T_学生別進路[[#This Row],[学籍番号]]&"○",進路状況入力シート!K:K,進路状況入力シート!D:D,"",0,1) -> 東京テクニカルカレッジ | I11: A | J11: 45962 | K11: =IF(T_学生別進路[[#This Row],[合格時期]]="",0,IF(T_学生別進路[[#This Row],[合格時期]]<K$5,1,0)) -> 1 | L11: =IF(T_学生別進路[[#This Row],[合格時期]]="",0,IF(T_学生別進路[[#This Row],[合格時期]]<L$5,1,0)) -> 1 | M11: =IF(T_学生別進路[[#This Row],[合格時期]]="",0,IF(T_学生別進路[[#This Row],[合格時期]]<M$5,1,0)) -> 1 | N11: =IF(T_学生別進路[[#This Row],[合格時期]]="",0,IF(T_学生別進路[[#This Row],[合格時期]]<N$5,1,0)) -> 1 | O11: =IF(T_学生別進路[[#This Row],[合格時期]]="",0,IF(T_学生別進路[[#This Row],[合格時期]]<O$5,1,0)) -> 1
A12: 2404031 | B12: =VLOOKUP(T_学生別進路[[#This Row],[学籍番号]],進路状況入力シート!A:B,2,FALSE) -> 2-1 | C12: =VLOOKUP(T_学生別進路[[#This Row],[学籍番号]],進路状況入力シート!A:C,3,FALSE) -> NWAY NWAY TUN | D12: =IF(AND(T_学生別進路[[#This Row],[進路確定]]="○",T_学生別進路[[#This Row],[進学希望フラグ]]=1),"○","") -> ○ | E12: =_xlfn.IFNA(RIGHT(VLOOKUP(T_学生別進路[[#This Row],[学籍番号]]&"○",進路状況入力シート!K:K,1,FALSE),1),"") -> ○ | F12: =IF(T_学生別進路[[#This Row],[進学希望フラグ]]=0,"",IF(T_学生別進路[[#This Row],[進路確定]]="○",1,0)) -> 1 | G12: =IF( AND( COUNTIFS(T_進路入力[学籍番号],T_学生別進路[[#This Row],[学籍番号]], T_進路入力[状況],"進学以外")>0, COUNTIFS(T_進路入力[学籍番号],T_学生別進路[[#This Row],[学籍番号]], T_進路入力[状況],"<>進学以外")>0 ), 0, IF(VLOOKUP(T_学生別進路[[#This Row],[学籍番号]],T_進路入力[],6,FALSE)="進学以外",0,1) ) -> 1 | H12: =_xlfn.XLOOKUP(T_学生別進路[[#This Row],[学籍番号]]&"○",進路状況入力シート!K:K,進路状況入力シート!D:D,"",0,1) -> 東京テクニカルカレッジ | J12: 45931 | K12: =IF(T_学生別進路[[#This Row],[合格時期]]="",0,IF(T_学生別進路[[#This Row],[合格時期]]<K$5,1,0)) -> 1 | L12: =IF(T_学生別進路[[#This Row],[合格時期]]="",0,IF(T_学生別進路[[#This Row],[合格時期]]<L$5,1,0)) -> 1 | M12: =IF(T_学生別進路[[#This Row],[合格時期]]="",0,IF(T_学生別進路[[#This Row],[合格時期]]<M$5,1,0)) -> 1 | N12: =IF(T_学生別進路[[#This Row],[合格時期]]="",0,IF(T_学生別進路[[#This Row],[合格時期]]<N$5,1,0)) -> 1 | O12: =IF(T_学生別進路[[#This Row],[合格時期]]="",0,IF(T_学生別進路[[#This Row],[合格時期]]<O$5,1,0)) -> 1
A13: 2404042 | B13: =VLOOKUP(T_学生別進路[[#This Row],[学籍番号]],進路状況入力シート!A:B,2,FALSE) -> 2-1 | C13: =VLOOKUP(T_学生別進路[[#This Row],[学籍番号]],進路状況入力シート!A:C,3,FALSE) -> PHU PHU MYAT THU | D13: =IF(AND(T_学生別進路[[#This Row],[進路確定]]="○",T_学生別進路[[#This Row],[進学希望フラグ]]=1),"○","") -> ○ | E13: =_xlfn.IFNA(RIGHT(VLOOKUP(T_学生別進路[[#This Row],[学籍番号]]&"○",進路状況入力シート!K:K,1,FALSE),1),"") -> ○ | F13: =IF(T_学生別進路[[#This Row],[進学希望フラグ]]=0,"",IF(T_学生別進路[[#This Row],[進路確定]]="○",1,0)) -> 1 | G13: =IF( AND( COUNTIFS(T_進路入力[学籍番号],T_学生別進路[[#This Row],[学籍番号]], T_進路入力[状況],"進学以外")>0, COUNTIFS(T_進路入力[学籍番号],T_学生別進路[[#This Row],[学籍番号]], T_進路入力[状況],"<>進学以外")>0 ), 0, IF(VLOOKUP(T_学生別進路[[#This Row],[学籍番号]],T_進路入力[],6,FALSE)="進学以外",0,1) ) -> 1 | H13: =_xlfn.XLOOKUP(T_学生別進路[[#This Row],[学籍番号]]&"○",進路状況入力シート!K:K,進路状況入力シート!D:D,"",0,1) -> ECC国際外語専門学校 | I13: A | J13: 45992 | K13: =IF(T_学生別進路[[#This Row],[合格時期]]="",0,IF(T_学生別進路[[#This Row],[合格時期]]<K$5,1,0)) -> 0 | L13: =IF(T_学生別進路[[#This Row],[合格時期]]="",0,IF(T_学生別進路[[#This Row],[合格時期]]<L$5,1,0)) -> 1 | M13: =IF(T_学生別進路[[#This Row],[合格時期]]="",0,IF(T_学生別進路[[#This Row],[合格時期]]<M$5,1,0)) -> 1 | N13: =IF(T_学生別進路[[#This Row],[合格時期]]="",0,IF(T_学生別進路[[#This Row],[合格時期]]<N$5,1,0)) -> 1 | O13: =IF(T_学生別進路[[#This Row],[合格時期]]="",0,IF(T_学生別進路[[#This Row],[合格時期]]<O$5,1,0)) -> 1
A14: 2404043 | B14: =VLOOKUP(T_学生別進路[[#This Row],[学籍番号]],進路状況入力シート!A:B,2,FALSE) -> 2-1 | C14: =VLOOKUP(T_学生別進路[[#This Row],[学籍番号]],進路状況入力シート!A:C,3,FALSE) -> RITA HLA MOE | D14: =IF(AND(T_学生別進路[[#This Row],[進路確定]]="○",T_学生別進路[[#This Row],[進学希望フラグ]]=1),"○","") -> ○ | E14: =_xlfn.IFNA(RIGHT(VLOOKUP(T_学生別進路[[#This Row],[学籍番号]]&"○",進路状況入力シート!K:K,1,FALSE),1),"") -> ○ | F14: =IF(T_学生別進路[[#This Row],[進学希望フラグ]]=0,"",IF(T_学生別進路[[#This Row],[進路確定]]="○",1,0)) -> 1 | G14: =IF( AND( COUNTIFS(T_進路入力[学籍番号],T_学生別進路[[#This Row],[学籍番号]], T_進路入力[状況],"進学以外")>0, COUNTIFS(T_進路入力[学籍番号],T_学生別進路[[#This Row],[学籍番号]], T_進路入力[状況],"<>進学以外")>0 ), 0, IF(VLOOKUP(T_学生別進路[[#This Row],[学籍番号]],T_進路入力[],6,FALSE)="進学以外",0,1) ) -> 1 | H14: =_xlfn.XLOOKUP(T_学生別進路[[#This Row],[学籍番号]]&"○",進路状況入力シート!K:K,進路状況入力シート!D:D,"",0,1) -> 神戸国際大学 | J14: 45962 | K14: =IF(T_学生別進路[[#This Row],[合格時期]]="",0,IF(T_学生別進路[[#This Row],[合格時期]]<K$5,1,0)) -> 1 | L14: =IF(T_学生別進路[[#This Row],[合格時期]]="",0,IF(T_学生別進路[[#This Row],[合格時期]]<L$5,1,0)) -> 1 | M14: =IF(T_学生別進路[[#This Row],[合格時期]]="",0,IF(T_学生別進路[[#This Row],[合格時期]]<M$5,1,0)) -> 1 | N14: =IF(T_学生別進路[[#This Row],[合格時期]]="",0,IF(T_学生別進路[[#This Row],[合格時期]]<N$5,1,0)) -> 1 | O14: =IF(T_学生別進路[[#This Row],[合格時期]]="",0,IF(T_学生別進路[[#This Row],[合格時期]]<O$5,1,0)) -> 1
A15: 2404046 | B15: =VLOOKUP(T_学生別進路[[#This Row],[学籍番号]],進路状況入力シート!A:B,2,FALSE) -> 2-1 | C15: =VLOOKUP(T_学生別進路[[#This Row],[学籍番号]],進路状況入力シート!A:C,3,FALSE) -> KYAL SIN LIN | D15: =IF(AND(T_学生別進路[[#This Row],[進路確定]]="○",T_学生別進路[[#This Row],[進学希望フラグ]]=1),"○","") -> ○ | E15: =_xlfn.IFNA(RIGHT(VLOOKUP(T_学生別進路[[#This Row],[学籍番号]]&"○",進路状況入力シート!K:K,1,FALSE),1),"") -> ○ | F15: =IF(T_学生別進路[[#This Row],[進学希望フラグ]]=0,"",IF(T_学生別進路[[#This Row],[進路確定]]="○",1,0)) -> 1 | G15: =IF( AND( COUNTIFS(T_進路入力[学籍番号],T_学生別進路[[#This Row],[学籍番号]], T_進路入力[状況],"進学以外")>0, COUNTIFS(T_進路入力[学籍番号],T_学生別進路[[#This Row],[学籍番号]], T_進路入力[状況],"<>進学以外")>0 ), 0, IF(VLOOKUP(T_学生別進路[[#This Row],[学籍番号]],T_進路入力[],6,FALSE)="進学以外",0,1) ) -> 1 | H15: =_xlfn.XLOOKUP(T_学生別進路[[#This Row],[学籍番号]]&"○",進路状況入力シート!K:K,進路状況入力シート!D:D,"",0,1) -> ECC国際外語専門学校 | I15: A | J15: 45992 | K15: =IF(T_学生別進路[[#This Row],[合格時期]]="",0,IF(T_学生別進路[[#This Row],[合格時期]]<K$5,1,0)) -> 0 | L15: =IF(T_学生別進路[[#This Row],[合格時期]]="",0,IF(T_学生別進路[[#This Row],[合格時期]]<L$5,1,0)) -> 1 | M15: =IF(T_学生別進路[[#This Row],[合格時期]]="",0,IF(T_学生別進路[[#This Row],[合格時期]]<M$5,1,0)) -> 1 | N15: =IF(T_学生別進路[[#This Row],[合格時期]]="",0,IF(T_学生別進路[[#This Row],[合格時期]]<N$5,1,0)) -> 1 | O15: =IF(T_学生別進路[[#This Row],[合格時期]]="",0,IF(T_学生別進路[[#This Row],[合格時期]]<O$5,1,0)) -> 1
A16: 2404047 | B16: =VLOOKUP(T_学生別進路[[#This Row],[学籍番号]],進路状況入力シート!A:B,2,FALSE) -> 2-1 | C16: =VLOOKUP(T_学生別進路[[#This Row],[学籍番号]],進路状況入力シート!A:C,3,FALSE) -> KHIN YADANAR OO | D16: =IF(AND(T_学生別進路[[#This Row],[進路確定]]="○",T_学生別進路[[#This Row],[進学希望フラグ]]=1),"○","") -> ○ | E16: =_xlfn.IFNA(RIGHT(VLOOKUP(T_学生別進路[[#This Row],[学籍番号]]&"○",進路状況入力シート!K:K,1,FALSE),1),"") -> ○ | F16: =IF(T_学生別進路[[#This Row],[進学希望フラグ]]=0,"",IF(T_学生別進路[[#This Row],[進路確定]]="○",1,0)) -> 1 | G16: =IF( AND( COUNTIFS(T_進路入力[学籍番号],T_学生別進路[[#This Row],[学籍番号]], T_進路入力[状況],"進学以外")>0, COUNTIFS(T_進路入力[学籍番号],T_学生別進路[[#This Row],[学籍番号]], T_進路入力[状況],"<>進学以外")>0 ), 0, IF(VLOOKUP(T_学生別進路[[#This Row],[学籍番号]],T_進路入力[],6,FALSE)="進学以外",0,1) ) -> 1 | H16: =_xlfn.XLOOKUP(T_学生別進路[[#This Row],[学籍番号]]&"○",進路状況入力シート!K:K,進路状況入力シート!D:D,"",0,1) -> エール学園 | I16: A | J16: 45962 | K16: =IF(T_学生別進路[[#This Row],[合格時期]]="",0,IF(T_学生別進路[[#This Row],[合格時期]]<K$5,1,0)) -> 1 | L16: =IF(T_学生別進路[[#This Row],[合格時期]]="",0,IF(T_学生別進路[[#This Row],[合格時期]]<L$5,1,0)) -> 1 | M16: =IF(T_学生別進路[[#This Row],[合格時期]]="",0,IF(T_学生別進路[[#This Row],[合格時期]]<M$5,1,0)) -> 1 | N16: =IF(T_学生別進路[[#This Row],[合格時期]]="",0,IF(T_学生別進路[[#This Row],[合格時期]]<N$5,1,0)) -> 1 | O16: =IF(T_学生別進路[[#This Row],[合格時期]]="",0,IF(T_学生別進路[[#This Row],[合格時期]]<O$5,1,0)) -> 1
A17: 2404050 | B17: =VLOOKUP(T_学生別進路[[#This Row],[学籍番号]],進路状況入力シート!A:B,2,FALSE) -> 2-1 | C17: =VLOOKUP(T_学生別進路[[#This Row],[学籍番号]],進路状況入力シート!A:C,3,FALSE) -> THUTA ZAW | D17: =IF(AND(T_学生別進路[[#This Row],[進路確定]]="○",T_学生別進路[[#This Row],[進学希望フラグ]]=1),"○","") -> ○ | E17: =_xlfn.IFNA(RIGHT(VLOOKUP(T_学生別進路[[#This Row],[学籍番号]]&"○",進路状況入力シート!K:K,1,FALSE),1),"") -> ○ | F17: =IF(T_学生別進路[[#This Row],[進学希望フラグ]]=0,"",IF(T_学生別進路[[#This Row],[進路確定]]="○",1,0)) -> 1 | G17: =IF( AND( COUNTIFS(T_進路入力[学籍番号],T_学生別進路[[#This Row],[学籍番号]], T_進路入力[状況],"進学以外")>0, COUNTIFS(T_進路入力[学籍番号],T_学生別進路[[#This Row],[学籍番号]], T_進路入力[状況],"<>進学以外")>0 ), 0, IF(VLOOKUP(T_学生別進路[[#This Row],[学籍番号]],T_進路入力[],6,FALSE)="進学以外",0,1) ) -> 1 | H17: =_xlfn.XLOOKUP(T_学生別進路[[#This Row],[学籍番号]]&"○",進路状況入力シート!K:K,進路状況入力シート!D:D,"",0,1) -> 東京みらいIT&AI専門学校 | I17: A | J17: 45992 | K17: =IF(T_学生別進路[[#This Row],[合格時期]]="",0,IF(T_学生別進路[[#This Row],[合格時期]]<K$5,1,0)) -> 0 | L17: =IF(T_学生別進路[[#This Row],[合格時期]]="",0,IF(T_学生別進路[[#This Row],[合格時期]]<L$5,1,0)) -> 1 | M17: =IF(T_学生別進路[[#This Row],[合格時期]]="",0,IF(T_学生別進路[[#This Row],[合格時期]]<M$5,1,0)) -> 1 | N17: =IF(T_学生別進路[[#This Row],[合格時期]]="",0,IF(T_学生別進路[[#This Row],[合格時期]]<N$5,1,0)) -> 1 | O17: =IF(T_学生別進路[[#This Row],[合格時期]]="",0,IF(T_学生別進路[[#This Row],[合格時期]]<O$5,1,0)) -> 1
A18: 2404051 | B18: =VLOOKUP(T_学生別進路[[#This Row],[学籍番号]],進路状況入力シート!A:B,2,FALSE) -> 2-1 | C18: =VLOOKUP(T_学生別進路[[#This Row],[学籍番号]],進路状況入力シート!A:C,3,FALSE) -> KAUNG ZIN NYI | D18: =IF(AND(T_学生別進路[[#This Row],[進路確定]]="○",T_学生別進路[[#This Row],[進学希望フラグ]]=1),"○","") -> ○ | E18: =_xlfn.IFNA(RIGHT(VLOOKUP(T_学生別進路[[#This Row],[学籍番号]]&"○",進路状況入力シート!K:K,1,FALSE),1),"") -> ○ | F18: =IF(T_学生別進路[[#This Row],[進学希望フラグ]]=0,"",IF(T_学生別進路[[#This Row],[進路確定]]="○",1,0)) -> 1 | G18: =IF( AND( COUNTIFS(T_進路入力[学籍番号],T_学生別進路[[#This Row],[学籍番号]], T_進路入力[状況],"進学以外")>0, COUNTIFS(T_進路入力[学籍番号],T_学生別進路[[#This Row],[学籍番号]], T_進路入力[状況],"<>進学以外")>0 ), 0, IF(VLOOKUP(T_学生別進路[[#This Row],[学籍番号]],T_進路入力[],6,FALSE)="進学以外",0,1) ) -> 1 | H18: =_xlfn.XLOOKUP(T_学生別進路[[#This Row],[学籍番号]]&"○",進路状況入力シート!K:K,進路状況入力シート!D:D,"",0,1) -> 中央工学校 | I18: A | J18: 45962 | K18: =IF(T_学生別進路[[#This Row],[合格時期]]="",0,IF(T_学生別進路[[#This Row],[合格時期]]<K$5,1,0)) -> 1 | L18: =IF(T_学生別進路[[#This Row],[合格時期]]="",0,IF(T_学生別進路[[#This Row],[合格時期]]<L$5,1,0)) -> 1 | M18: =IF(T_学生別進路[[#This Row],[合格時期]]="",0,IF(T_学生別進路[[#This Row],[合格時期]]<M$5,1,0)) -> 1 | N18: =IF(T_学生別進路[[#This Row],[合格時期]]="",0,IF(T_学生別進路[[#This Row],[合格時期]]<N$5,1,0)) -> 1 | O18: =IF(T_学生別進路[[#This Row],[合格時期]]="",0,IF(T_学生別進路[[#This Row],[合格時期]]<O$5,1,0)) -> 1
A19: 2404058 | B19: =VLOOKUP(T_学生別進路[[#This Row],[学籍番号]],進路状況入力シート!A:B,2,FALSE) -> 2-1 | C19: =VLOOKUP(T_学生別進路[[#This Row],[学籍番号]],進路状況入力シート!A:C,3,FALSE) -> HAN THU SAN | D19: =IF(AND(T_学生別進路[[#This Row],[進路確定]]="○",T_学生別進路[[#This Row],[進学希望フラグ]]=1),"○","") -> ○ | E19: =_xlfn.IFNA(RIGHT(VLOOKUP(T_学生別進路[[#This Row],[学籍番号]]&"○",進路状況入力シート!K:K,1,FALSE),1),"") -> ○ | F19: =IF(T_学生別進路[[#This Row],[進学希望フラグ]]=0,"",IF(T_学生別進路[[#This Row],[進路確定]]="○",1,0)) -> 1 | G19: =IF( AND( COUNTIFS(T_進路入力[学籍番号],T_学生別進路[[#This Row],[学籍番号]], T_進路入力[状況],"進学以外")>0, COUNTIFS(T_進路入力[学籍番号],T_学生別進路[[#This Row],[学籍番号]], T_進路入力[状況],"<>進学以外")>0 ), 0, IF(VLOOKUP(T_学生別進路[[#This Row],[学籍番号]],T_進路入力[],6,FALSE)="進学以外",0,1) ) -> 1 | H19: =_xlfn.XLOOKUP(T_学生別進路[[#This Row],[学籍番号]]&"○",進路状況入力シート!K:K,進路状況入力シート!D:D,"",0,1) -> 大手前大学 | I19: A | J19: 45962 | K19: =IF(T_学生別進路[[#This Row],[合格時期]]="",0,IF(T_学生別進路[[#This Row],[合格時期]]<K$5,1,0)) -> 1 | L19: =IF(T_学生別進路[[#This Row],[合格時期]]="",0,IF(T_学生別進路[[#This Row],[合格時期]]<L$5,1,0)) -> 1 | M19: =IF(T_学生別進路[[#This Row],[合格時期]]="",0,IF(T_学生別進路[[#This Row],[合格時期]]<M$5,1,0)) -> 1 | N19: =IF(T_学生別進路[[#This Row],[合格時期]]="",0,IF(T_学生別進路[[#This Row],[合格時期]]<N$5,1,0)) -> 1 | O19: =IF(T_学生別進路[[#This Row],[合格時期]]="",0,IF(T_学生別進路[[#This Row],[合格時期]]<O$5,1,0)) -> 1
A20: 2404073 | B20: =VLOOKUP(T_学生別進路[[#This Row],[学籍番号]],進路状況入力シート!A:B,2,FALSE) -> 2-1 | C20: =VLOOKUP(T_学生別進路[[#This Row],[学籍番号]],進路状況入力シート!A:C,3,FALSE) -> FAKIR SHAKIB | D20: =IF(AND(T_学生別進路[[#This Row],[進路確定]]="○",T_学生別進路[[#This Row],[進学希望フラグ]]=1),"○","") -> ○ | E20: =_xlfn.IFNA(RIGHT(VLOOKUP(T_学生別進路[[#This Row],[学籍番号]]&"○",進路状況入力シート!K:K,1,FALSE),1),"") -> ○ | F20: =IF(T_学生別進路[[#This Row],[進学希望フラグ]]=0,"",IF(T_学生別進路[[#This Row],[進路確定]]="○",1,0)) -> 1 | G20: =IF( AND( COUNTIFS(T_進路入力[学籍番号],T_学生別進路[[#This Row],[学籍番号]], T_進路入力[状況],"進学以外")>0, COUNTIFS(T_進路入力[学籍番号],T_学生別進路[[#This Row],[学籍番号]], T_進路入力[状況],"<>進学以外")>0 ), 0, IF(VLOOKUP(T_学生別進路[[#This Row],[学籍番号]],T_進路入力[],6,FALSE)="進学以外",0,1) ) -> 1 | H20: =_xlfn.XLOOKUP(T_学生別進路[[#This Row],[学籍番号]]&"○",進路状況入力シート!K:K,進路状況入力シート!D:D,"",0,1) -> 東京国際ビジネスカレッジ神戸校 | I20: A | J20: 45962 | K20: =IF(T_学生別進路[[#This Row],[合格時期]]="",0,IF(T_学生別進路[[#This Row],[合格時期]]<K$5,1,0)) -> 1 | L20: =IF(T_学生別進路[[#This Row],[合格時期]]="",0,IF(T_学生別進路[[#This Row],[合格時期]]<L$5,1,0)) -> 1 | M20: =IF(T_学生別進路[[#This Row],[合格時期]]="",0,IF(T_学生別進路[[#This Row],[合格時期]]<M$5,1,0)) -> 1 | N20: =IF(T_学生別進路[[#This Row],[合格時期]]="",0,IF(T_学生別進路[[#This Row],[合格時期]]<N$5,1,0)) -> 1 | O20: =IF(T_学生別進路[[#This Row],[合格時期]]="",0,IF(T_学生別進路[[#This Row],[合格時期]]<O$5,1,0)) -> 1
A21: 2404084 | B21: =VLOOKUP(T_学生別進路[[#This Row],[学籍番号]],進路状況入力シート!A:B,2,FALSE) -> 2-1 | C21: =VLOOKUP(T_学生別進路[[#This Row],[学籍番号]],進路状況入力シート!A:C,3,FALSE) -> MD. MATIUR RAHMAN | D21: =IF(AND(T_学生別進路[[#This Row],[進路確定]]="○",T_学生別進路[[#This Row],[進学希望フラグ]]=1),"○","") -> ○ | E21: =_xlfn.IFNA(RIGHT(VLOOKUP(T_学生別進路[[#This Row],[学籍番号]]&"○",進路状況入力シート!K:K,1,FALSE),1),"") -> ○ | F21: =IF(T_学生別進路[[#This Row],[進学希望フラグ]]=0,"",IF(T_学生別進路[[#This Row],[進路確定]]="○",1,0)) -> 1 | G21: =IF( AND( COUNTIFS(T_進路入力[学籍番号],T_学生別進路[[#This Row],[学籍番号]], T_進路入力[状況],"進学以外")>0, COUNTIFS(T_進路入力[学籍番号],T_学生別進路[[#This Row],[学籍番号]], T_進路入力[状況],"<>進学以外")>0 ), 0, IF(VLOOKUP(T_学生別進路[[#This Row],[学籍番号]],T_進路入力[],6,FALSE)="進学以外",0,1) ) -> 1 | H21: =_xlfn.XLOOKUP(T_学生別進路[[#This Row],[学籍番号]]&"○",進路状況入力シート!K:K,進路状況入力シート!D:D,"",0,1) -> 流通科学大学 | J21: 45962 | K21: =IF(T_学生別進路[[#This Row],[合格時期]]="",0,IF(T_学生別進路[[#This Row],[合格時期]]<K$5,1,0)) -> 1 | L21: =IF(T_学生別進路[[#This Row],[合格時期]]="",0,IF(T_学生別進路[[#This Row],[合格時期]]<L$5,1,0)) -> 1 | M21: =IF(T_学生別進路[[#This Row],[合格時期]]="",0,IF(T_学生別進路[[#This Row],[合格時期]]<M$5,1,0)) -> 1 | N21: =IF(T_学生別進路[[#This Row],[合格時期]]="",0,IF(T_学生別進路[[#This Row],[合格時期]]<N$5,1,0)) -> 1 | O21: =IF(T_学生別進路[[#This Row],[合格時期]]="",0,IF(T_学生別進路[[#This Row],[合格時期]]<O$5,1,0)) -> 1
A22: 2404093 | B22: =VLOOKUP(T_学生別進路[[#This Row],[学籍番号]],進路状況入力シート!A:B,2,FALSE) -> 2-1 | C22: =VLOOKUP(T_学生別進路[[#This Row],[学籍番号]],進路状況入力シート!A:C,3,FALSE) -> DELWAR HOSHEN SAYED | D22: =IF(AND(T_学生別進路[[#This Row],[進路確定]]="○",T_学生別進路[[#This Row],[進学希望フラグ]]=1),"○","") -> ○ | E22: =_xlfn.IFNA(RIGHT(VLOOKUP(T_学生別進路[[#This Row],[学籍番号]]&"○",進路状況入力シート!K:K,1,FALSE),1),"") -> ○ | F22: =IF(T_学生別進路[[#This Row],[進学希望フラグ]]=0,"",IF(T_学生別進路[[#This Row],[進路確定]]="○",1,0)) -> 1 | G22: =IF( AND( COUNTIFS(T_進路入力[学籍番号],T_学生別進路[[#This Row],[学籍番号]], T_進路入力[状況],"進学以外")>0, COUNTIFS(T_進路入力[学籍番号],T_学生別進路[[#This Row],[学籍番号]], T_進路入力[状況],"<>進学以外")>0 ), 0, IF(VLOOKUP(T_学生別進路[[#This Row],[学籍番号]],T_進路入力[],6,FALSE)="進学以外",0,1) ) -> 1 | H22: =_xlfn.XLOOKUP(T_学生別進路[[#This Row],[学籍番号]]&"○",進路状況入力シート!K:K,進路状況入力シート!D:D,"",0,1) -> 流通科学大学 | J22: 45962 | K22: =IF(T_学生別進路[[#This Row],[合格時期]]="",0,IF(T_学生別進路[[#This Row],[合格時期]]<K$5,1,0)) -> 1 | L22: =IF(T_学生別進路[[#This Row],[合格時期]]="",0,IF(T_学生別進路[[#This Row],[合格時期]]<L$5,1,0)) -> 1 | M22: =IF(T_学生別進路[[#This Row],[合格時期]]="",0,IF(T_学生別進路[[#This Row],[合格時期]]<M$5,1,0)) -> 1 | N22: =IF(T_学生別進路[[#This Row],[合格時期]]="",0,IF(T_学生別進路[[#This Row],[合格時期]]<N$5,1,0)) -> 1 | O22: =IF(T_学生別進路[[#This Row],[合格時期]]="",0,IF(T_学生別進路[[#This Row],[合格時期]]<O$5,1,0)) -> 1
A23: 2407013 | B23: =VLOOKUP(T_学生別進路[[#This Row],[学籍番号]],進路状況入力シート!A:B,2,FALSE) -> 2-1 | C23: =VLOOKUP(T_学生別進路[[#This Row],[学籍番号]],進路状況入力シート!A:C,3,FALSE) -> SOE NYI HTUT | D23: =IF(AND(T_学生別進路[[#This Row],[進路確定]]="○",T_学生別進路[[#This Row],[進学希望フラグ]]=1),"○","") -> ○ | E23: =_xlfn.IFNA(RIGHT(VLOOKUP(T_学生別進路[[#This Row],[学籍番号]]&"○",進路状況入力シート!K:K,1,FALSE),1),"") -> ○ | F23: =IF(T_学生別進路[[#This Row],[進学希望フラグ]]=0,"",IF(T_学生別進路[[#This Row],[進路確定]]="○",1,0)) -> 1 | G23: =IF( AND( COUNTIFS(T_進路入力[学籍番号],T_学生別進路[[#This Row],[学籍番号]], T_進路入力[状況],"進学以外")>0, COUNTIFS(T_進路入力[学籍番号],T_学生別進路[[#This Row],[学籍番号]], T_進路入力[状況],"<>進学以外")>0 ), 0, IF(VLOOKUP(T_学生別進路[[#This Row],[学籍番号]],T_進路入力[],6,FALSE)="進学以外",0,1) ) -> 1 | H23: =_xlfn.XLOOKUP(T_学生別進路[[#This Row],[学籍番号]]&"○",進路状況入力シート!K:K,進路状況入力シート!D:D,"",0,1) -> 大阪学院大学 | I23: A | J23: 45931 | K23: =IF(T_学生別進路[[#This Row],[合格時期]]="",0,IF(T_学生別進路[[#This Row],[合格時期]]<K$5,1,0)) -> 1 | L23: =IF(T_学生別進路[[#This Row],[合格時期]]="",0,IF(T_学生別進路[[#This Row],[合格時期]]<L$5,1,0)) -> 1 | M23: =IF(T_学生別進路[[#This Row],[合格時期]]="",0,IF(T_学生別進路[[#This Row],[合格時期]]<M$5,1,0)) -> 1 | N23: =IF(T_学生別進路[[#This Row],[合格時期]]="",0,IF(T_学生別進路[[#This Row],[合格時期]]<N$5,1,0)) -> 1 | O23: =IF(T_学生別進路[[#This Row],[合格時期]]="",0,IF(T_学生別進路[[#This Row],[合格時期]]<O$5,1,0)) -> 1
A24: 2407025 | B24: =VLOOKUP(T_学生別進路[[#This Row],[学籍番号]],進路状況入力シート!A:B,2,FALSE) -> 2-1 | C24: =VLOOKUP(T_学生別進路[[#This Row],[学籍番号]],進路状況入力シート!A:C,3,FALSE) -> KHIN PYAE SONE | D24: =IF(AND(T_学生別進路[[#This Row],[進路確定]]="○",T_学生別進路[[#This Row],[進学希望フラグ]]=1),"○","") -> ○ | E24: =_xlfn.IFNA(RIGHT(VLOOKUP(T_学生別進路[[#This Row],[学籍番号]]&"○",進路状況入力シート!K:K,1,FALSE),1),"") -> ○ | F24: =IF(T_学生別進路[[#This Row],[進学希望フラグ]]=0,"",IF(T_学生別進路[[#This Row],[進路確定]]="○",1,0)) -> 1 | G24: =IF( AND( COUNTIFS(T_進路入力[学籍番号],T_学生別進路[[#This Row],[学籍番号]], T_進路入力[状況],"進学以外")>0, COUNTIFS(T_進路入力[学籍番号],T_学生別進路[[#This Row],[学籍番号]], T_進路入力[状況],"<>進学以外")>0 ), 0, IF(VLOOKUP(T_学生別進路[[#This Row],[学籍番号]],T_進路入力[],6,FALSE)="進学以外",0,1) ) -> 1 | H24: =_xlfn.XLOOKUP(T_学生別進路[[#This Row],[学籍番号]]&"○",進路状況入力シート!K:K,進路状況入力シート!D:D,"",0,1) -> 神戸電子専門学校 | J24: 45962 | K24: =IF(T_学生別進路[[#This Row],[合格時期]]="",0,IF(T_学生別進路[[#This Row],[合格時期]]<K$5,1,0)) -> 1 | L24: =IF(T_学生別進路[[#This Row],[合格時期]]="",0,IF(T_学生別進路[[#This Row],[合格時期]]<L$5,1,0)) -> 1 | M24: =IF(T_学生別進路[[#This Row],[合格時期]]="",0,IF(T_学生別進路[[#This Row],[合格時期]]<M$5,1,0)) -> 1 | N24: =IF(T_学生別進路[[#This Row],[合格時期]]="",0,IF(T_学生別進路[[#This Row],[合格時期]]<N$5,1,0)) -> 1 | O24: =IF(T_学生別進路[[#This Row],[合格時期]]="",0,IF(T_学生別進路[[#This Row],[合格時期]]<O$5,1,0)) -> 1
A25: 2404011 | B25: =VLOOKUP(T_学生別進路[[#This Row],[学籍番号]],進路状況入力シート!A:B,2,FALSE) -> 2-2 | C25: =VLOOKUP(T_学生別進路[[#This Row],[学籍番号]],進路状況入力シート!A:C,3,FALSE) -> BUI NGOC ANH THU | D25: =IF(AND(T_学生別進路[[#This Row],[進路確定]]="○",T_学生別進路[[#This Row],[進学希望フラグ]]=1),"○","") -> ○ | E25: =_xlfn.IFNA(RIGHT(VLOOKUP(T_学生別進路[[#This Row],[学籍番号]]&"○",進路状況入力シート!K:K,1,FALSE),1),"") -> ○ | F25: =IF(T_学生別進路[[#This Row],[進学希望フラグ]]=0,"",IF(T_学生別進路[[#This Row],[進路確定]]="○",1,0)) -> 1 | G25: =IF( AND( COUNTIFS(T_進路入力[学籍番号],T_学生別進路[[#This Row],[学籍番号]], T_進路入力[状況],"進学以外")>0, COUNTIFS(T_進路入力[学籍番号],T_学生別進路[[#This Row],[学籍番号]], T_進路入力[状況],"<>進学以外")>0 ), 0, IF(VLOOKUP(T_学生別進路[[#This Row],[学籍番号]],T_進路入力[],6,FALSE)="進学以外",0,1) ) -> 1 | H25: =_xlfn.XLOOKUP(T_学生別進路[[#This Row],[学籍番号]]&"○",進路状況入力シート!K:K,進路状況入力シート!D:D,"",0,1) -> 東京国際ビジネスカレッジ神戸校 | I25: B | J25: 46054 | K25: =IF(T_学生別進路[[#This Row],[合格時期]]="",0,IF(T_学生別進路[[#This Row],[合格時期]]<K$5,1,0)) -> 0 | L25: =IF(T_学生別進路[[#This Row],[合格時期]]="",0,IF(T_学生別進路[[#This Row],[合格時期]]<L$5,1,0)) -> 0 | M25: =IF(T_学生別進路[[#This Row],[合格時期]]="",0,IF(T_学生別進路[[#This Row],[合格時期]]<M$5,1,0)) -> 0 | N25: =IF(T_学生別進路[[#This Row],[合格時期]]="",0,IF(T_学生別進路[[#This Row],[合格時期]]<N$5,1,0)) -> 1 | O25: =IF(T_学生別進路[[#This Row],[合格時期]]="",0,IF(T_学生別進路[[#This Row],[合格時期]]<O$5,1,0)) -> 1
A26: 2404013 | B26: =VLOOKUP(T_学生別進路[[#This Row],[学籍番号]],進路状況入力シート!A:B,2,FALSE) -> 2-2 | C26: =VLOOKUP(T_学生別進路[[#This Row],[学籍番号]],進路状況入力シート!A:C,3,FALSE) -> CHIT MAUNG MAUNG | D26: =IF(AND(T_学生別進路[[#This Row],[進路確定]]="○",T_学生別進路[[#This Row],[進学希望フラグ]]=1),"○","") | E26: =_xlfn.IFNA(RIGHT(VLOOKUP(T_学生別進路[[#This Row],[学籍番号]]&"○",進路状況入力シート!K:K,1,FALSE),1),"") | F26: =IF(T_学生別進路[[#This Row],[進学希望フラグ]]=0,"",IF(T_学生別進路[[#This Row],[進路確定]]="○",1,0)) | G26: =IF( AND( COUNTIFS(T_進路入力[学籍番号],T_学生別進路[[#This Row],[学籍番号]], T_進路入力[状況],"進学以外")>0, COUNTIFS(T_進路入力[学籍番号],T_学生別進路[[#This Row],[学籍番号]], T_進路入力[状況],"<>進学以外")>0 ), 0, IF(VLOOKUP(T_学生別進路[[#This Row],[学籍番号]],T_進路入力[],6,FALSE)="進学以外",0,1) ) -> 0 | H26: =_xlfn.XLOOKUP(T_学生別進路[[#This Row],[学籍番号]]&"○",進路状況入力シート!K:K,進路状況入力シート!D:D,"",0,1) | I26: B | K26: =IF(T_学生別進路[[#This Row],[合格時期]]="",0,IF(T_学生別進路[[#This Row],[合格時期]]<K$5,1,0)) -> 0 | L26: =IF(T_学生別進路[[#This Row],[合格時期]]="",0,IF(T_学生別進路[[#This Row],[合格時期]]<L$5,1,0)) -> 0 | M26: =IF(T_学生別進路[[#This Row],[合格時期]]="",0,IF(T_学生別進路[[#This Row],[合格時期]]<M$5,1,0)) -> 0 | N26: =IF(T_学生別進路[[#This Row],[合格時期]]="",0,IF(T_学生別進路[[#This Row],[合格時期]]<N$5,1,0)) -> 0 | O26: =IF(T_学生別進路[[#This Row],[合格時期]]="",0,IF(T_学生別進路[[#This Row],[合格時期]]<O$5,1,0)) -> 0 | P26: 5/27期限
A27: 2404015 | B27: =VLOOKUP(T_学生別進路[[#This Row],[学籍番号]],進路状況入力シート!A:B,2,FALSE) -> 2-2 | C27: =VLOOKUP(T_学生別進路[[#This Row],[学籍番号]],進路状況入力シート!A:C,3,FALSE) -> NAY LIN OO | D27: =IF(AND(T_学生別進路[[#This Row],[進路確定]]="○",T_学生別進路[[#This Row],[進学希望フラグ]]=1),"○","") -> ○ | E27: =_xlfn.IFNA(RIGHT(VLOOKUP(T_学生別進路[[#This Row],[学籍番号]]&"○",進路状況入力シート!K:K,1,FALSE),1),"") -> ○ | F27: =IF(T_学生別進路[[#This Row],[進学希望フラグ]]=0,"",IF(T_学生別進路[[#This Row],[進路確定]]="○",1,0)) -> 1 | G27: =IF( AND( COUNTIFS(T_進路入力[学籍番号],T_学生別進路[[#This Row],[学籍番号]], T_進路入力[状況],"進学以外")>0, COUNTIFS(T_進路入力[学籍番号],T_学生別進路[[#This Row],[学籍番号]], T_進路入力[状況],"<>進学以外")>0 ), 0, IF(VLOOKUP(T_学生別進路[[#This Row],[学籍番号]],T_進路入力[],6,FALSE)="進学以外",0,1) ) -> 1 | H27: =_xlfn.XLOOKUP(T_学生別進路[[#This Row],[学籍番号]]&"○",進路状況入力シート!K:K,進路状況入力シート!D:D,"",0,1) -> 神戸松蔭大学 | I27: B | J27: 45992 | K27: =IF(T_学生別進路[[#This Row],[合格時期]]="",0,IF(T_学生別進路[[#This Row],[合格時期]]<K$5,1,0)) -> 0 | L27: =IF(T_学生別進路[[#This Row],[合格時期]]="",0,IF(T_学生別進路[[#This Row],[合格時期]]<L$5,1,0)) -> 1 | M27: =IF(T_学生別進路[[#This Row],[合格時期]]="",0,IF(T_学生別進路[[#This Row],[合格時期]]<M$5,1,0)) -> 1 | N27: =IF(T_学生別進路[[#This Row],[合格時期]]="",0,IF(T_学生別進路[[#This Row],[合格時期]]<N$5,1,0)) -> 1 | O27: =IF(T_学生別進路[[#This Row],[合格時期]]="",0,IF(T_学生別進路[[#This Row],[合格時期]]<O$5,1,0)) -> 1
A28: 2404016 | B28: =VLOOKUP(T_学生別進路[[#This Row],[学籍番号]],進路状況入力シート!A:B,2,FALSE) -> 2-2 | C28: =VLOOKUP(T_学生別進路[[#This Row],[学籍番号]],進路状況入力シート!A:C,3,FALSE) -> THAW ZIN HTUN | D28: =IF(AND(T_学生別進路[[#This Row],[進路確定]]="○",T_学生別進路[[#This Row],[進学希望フラグ]]=1),"○","") -> ○ | E28: =_xlfn.IFNA(RIGHT(VLOOKUP(T_学生別進路[[#This Row],[学籍番号]]&"○",進路状況入力シート!K:K,1,FALSE),1),"") -> ○ | F28: =IF(T_学生別進路[[#This Row],[進学希望フラグ]]=0,"",IF(T_学生別進路[[#This Row],[進路確定]]="○",1,0)) -> 1 | G28: =IF( AND( COUNTIFS(T_進路入力[学籍番号],T_学生別進路[[#This Row],[学籍番号]], T_進路入力[状況],"進学以外")>0, COUNTIFS(T_進路入力[学籍番号],T_学生別進路[[#This Row],[学籍番号]], T_進路入力[状況],"<>進学以外")>0 ), 0, IF(VLOOKUP(T_学生別進路[[#This Row],[学籍番号]],T_進路入力[],6,FALSE)="進学以外",0,1) ) -> 1 | H28: =_xlfn.XLOOKUP(T_学生別進路[[#This Row],[学籍番号]]&"○",進路状況入力シート!K:K,進路状況入力シート!D:D,"",0,1) -> 神戸電子専門学校 | I28: B | J28: 45992 | K28: =IF(T_学生別進路[[#This Row],[合格時期]]="",0,IF(T_学生別進路[[#This Row],[合格時期]]<K$5,1,0)) -> 0 | L28: =IF(T_学生別進路[[#This Row],[合格時期]]="",0,IF(T_学生別進路[[#This Row],[合格時期]]<L$5,1,0)) -> 1 | M28: =IF(T_学生別進路[[#This Row],[合格時期]]="",0,IF(T_学生別進路[[#This Row],[合格時期]]<M$5,1,0)) -> 1 | N28: =IF(T_学生別進路[[#This Row],[合格時期]]="",0,IF(T_学生別進路[[#This Row],[合格時期]]<N$5,1,0)) -> 1 | O28: =IF(T_学生別進路[[#This Row],[合格時期]]="",0,IF(T_学生別進路[[#This Row],[合格時期]]<O$5,1,0)) -> 1
A29: 2404017 | B29: =VLOOKUP(T_学生別進路[[#This Row],[学籍番号]],進路状況入力シート!A:B,2,FALSE) -> 2-2 | C29: =VLOOKUP(T_学生別進路[[#This Row],[学籍番号]],進路状況入力シート!A:C,3,FALSE) -> HNIN HNIN WAI | D29: =IF(AND(T_学生別進路[[#This Row],[進路確定]]="○",T_学生別進路[[#This Row],[進学希望フラグ]]=1),"○","") -> ○ | E29: =_xlfn.IFNA(RIGHT(VLOOKUP(T_学生別進路[[#This Row],[学籍番号]]&"○",進路状況入力シート!K:K,1,FALSE),1),"") -> ○ | F29: =IF(T_学生別進路[[#This Row],[進学希望フラグ]]=0,"",IF(T_学生別進路[[#This Row],[進路確定]]="○",1,0)) -> 1 | G29: =IF( AND( COUNTIFS(T_進路入力[学籍番号],T_学生別進路[[#This Row],[学籍番号]], T_進路入力[状況],"進学以外")>0, COUNTIFS(T_進路入力[学籍番号],T_学生別進路[[#This Row],[学籍番号]], T_進路入力[状況],"<>進学以外")>0 ), 0, IF(VLOOKUP(T_学生別進路[[#This Row],[学籍番号]],T_進路入力[],6,FALSE)="進学以外",0,1) ) -> 1 | H29: =_xlfn.XLOOKUP(T_学生別進路[[#This Row],[学籍番号]]&"○",進路状況入力シート!K:K,進路状況入力シート!D:D,"",0,1) -> 神戸国際大学 | J29: 45992 | K29: =IF(T_学生別進路[[#This Row],[合格時期]]="",0,IF(T_学生別進路[[#This Row],[合格時期]]<K$5,1,0)) -> 0 | L29: =IF(T_学生別進路[[#This Row],[合格時期]]="",0,IF(T_学生別進路[[#This Row],[合格時期]]<L$5,1,0)) -> 1 | M29: =IF(T_学生別進路[[#This Row],[合格時期]]="",0,IF(T_学生別進路[[#This Row],[合格時期]]<M$5,1,0)) -> 1 | N29: =IF(T_学生別進路[[#This Row],[合格時期]]="",0,IF(T_学生別進路[[#This Row],[合格時期]]<N$5,1,0)) -> 1 | O29: =IF(T_学生別進路[[#This Row],[合格時期]]="",0,IF(T_学生別進路[[#This Row],[合格時期]]<O$5,1,0)) -> 1
A30: 2404018 | B30: =VLOOKUP(T_学生別進路[[#This Row],[学籍番号]],進路状況入力シート!A:B,2,FALSE) -> 2-2 | C30: =VLOOKUP(T_学生別進路[[#This Row],[学籍番号]],進路状況入力シート!A:C,3,FALSE) -> MAY PHOO THIT | D30: =IF(AND(T_学生別進路[[#This Row],[進路確定]]="○",T_学生別進路[[#This Row],[進学希望フラグ]]=1),"○","") -> ○ | E30: =_xlfn.IFNA(RIGHT(VLOOKUP(T_学生別進路[[#This Row],[学籍番号]]&"○",進路状況入力シート!K:K,1,FALSE),1),"") -> ○ | F30: =IF(T_学生別進路[[#This Row],[進学希望フラグ]]=0,"",IF(T_学生別進路[[#This Row],[進路確定]]="○",1,0)) -> 1 | G30: =IF( AND( COUNTIFS(T_進路入力[学籍番号],T_学生別進路[[#This Row],[学籍番号]], T_進路入力[状況],"進学以外")>0, COUNTIFS(T_進路入力[学籍番号],T_学生別進路[[#This Row],[学籍番号]], T_進路入力[状況],"<>進学以外")>0 ), 0, IF(VLOOKUP(T_学生別進路[[#This Row],[学籍番号]],T_進路入力[],6,FALSE)="進学以外",0,1) ) -> 1 | H30: =_xlfn.XLOOKUP(T_学生別進路[[#This Row],[学籍番号]]&"○",進路状況入力シート!K:K,進路状況入力シート!D:D,"",0,1) -> 大阪モード学園 | J30: 45931 | K30: =IF(T_学生別進路[[#This Row],[合格時期]]="",0,IF(T_学生別進路[[#This Row],[合格時期]]<K$5,1,0)) -> 1 | L30: =IF(T_学生別進路[[#This Row],[合格時期]]="",0,IF(T_学生別進路[[#This Row],[合格時期]]<L$5,1,0)) -> 1 | M30: =IF(T_学生別進路[[#This Row],[合格時期]]="",0,IF(T_学生別進路[[#This Row],[合格時期]]<M$5,1,0)) -> 1 | N30: =IF(T_学生別進路[[#This Row],[合格時期]]="",0,IF(T_学生別進路[[#This Row],[合格時期]]<N$5,1,0)) -> 1 | O30: =IF(T_学生別進路[[#This Row],[合格時期]]="",0,IF(T_学生別進路[[#This Row],[合格時期]]<O$5,1,0)) -> 1
A31: 2404020 | B31: =VLOOKUP(T_学生別進路[[#This Row],[学籍番号]],進路状況入力シート!A:B,2,FALSE) -> 2-2 | C31: =VLOOKUP(T_学生別進路[[#This Row],[学籍番号]],進路状況入力シート!A:C,3,FALSE) -> SAI KWAN PHA | D31: =IF(AND(T_学生別進路[[#This Row],[進路確定]]="○",T_学生別進路[[#This Row],[進学希望フラグ]]=1),"○","") -> ○ | E31: =_xlfn.IFNA(RIGHT(VLOOKUP(T_学生別進路[[#This Row],[学籍番号]]&"○",進路状況入力シート!K:K,1,FALSE),1),"") -> ○ | F31: =IF(T_学生別進路[[#This Row],[進学希望フラグ]]=0,"",IF(T_学生別進路[[#This Row],[進路確定]]="○",1,0)) -> 1 | G31: =IF( AND( COUNTIFS(T_進路入力[学籍番号],T_学生別進路[[#This Row],[学籍番号]], T_進路入力[状況],"進学以外")>0, COUNTIFS(T_進路入力[学籍番号],T_学生別進路[[#This Row],[学籍番号]], T_進路入力[状況],"<>進学以外")>0 ), 0, IF(VLOOKUP(T_学生別進路[[#This Row],[学籍番号]],T_進路入力[],6,FALSE)="進学以外",0,1) ) -> 1 | H31: =_xlfn.XLOOKUP(T_学生別進路[[#This Row],[学籍番号]]&"○",進路状況入力シート!K:K,進路状況入力シート!D:D,"",0,1) -> ECC国際外語専門学校 | I31: B | J31: 46023 | K31: =IF(T_学生別進路[[#This Row],[合格時期]]="",0,IF(T_学生別進路[[#This Row],[合格時期]]<K$5,1,0)) -> 0 | L31: =IF(T_学生別進路[[#This Row],[合格時期]]="",0,IF(T_学生別進路[[#This Row],[合格時期]]<L$5,1,0)) -> 0 | M31: =IF(T_学生別進路[[#This Row],[合格時期]]="",0,IF(T_学生別進路[[#This Row],[合格時期]]<M$5,1,0)) -> 1 | N31: =IF(T_学生別進路[[#This Row],[合格時期]]="",0,IF(T_学生別進路[[#This Row],[合格時期]]<N$5,1,0)) -> 1 | O31: =IF(T_学生別進路[[#This Row],[合格時期]]="",0,IF(T_学生別進路[[#This Row],[合格時期]]<O$5,1,0)) -> 1
A32: 2404023 | B32: =VLOOKUP(T_学生別進路[[#This Row],[学籍番号]],進路状況入力シート!A:B,2,FALSE) -> 2-2 | C32: =VLOOKUP(T_学生別進路[[#This Row],[学籍番号]],進路状況入力シート!A:C,3,FALSE) -> LAE YI HTUN | D32: =IF(AND(T_学生別進路[[#This Row],[進路確定]]="○",T_学生別進路[[#This Row],[進学希望フラグ]]=1),"○","") -> ○ | E32: =_xlfn.IFNA(RIGHT(VLOOKUP(T_学生別進路[[#This Row],[学籍番号]]&"○",進路状況入力シート!K:K,1,FALSE),1),"") -> ○ | F32: =IF(T_学生別進路[[#This Row],[進学希望フラグ]]=0,"",IF(T_学生別進路[[#This Row],[進路確定]]="○",1,0)) -> 1 | G32: =IF( AND( COUNTIFS(T_進路入力[学籍番号],T_学生別進路[[#This Row],[学籍番号]], T_進路入力[状況],"進学以外")>0, COUNTIFS(T_進路入力[学籍番号],T_学生別進路[[#This Row],[学籍番号]], T_進路入力[状況],"<>進学以外")>0 ), 0, IF(VLOOKUP(T_学生別進路[[#This Row],[学籍番号]],T_進路入力[],6,FALSE)="進学以外",0,1) ) -> 1 | H32: =_xlfn.XLOOKUP(T_学生別進路[[#This Row],[学籍番号]]&"○",進路状況入力シート!K:K,進路状況入力シート!D:D,"",0,1) -> 修成建設専門学校 | J32: 45931 | K32: =IF(T_学生別進路[[#This Row],[合格時期]]="",0,IF(T_学生別進路[[#This Row],[合格時期]]<K$5,1,0)) -> 1 | L32: =IF(T_学生別進路[[#This Row],[合格時期]]="",0,IF(T_学生別進路[[#This Row],[合格時期]]<L$5,1,0)) -> 1 | M32: =IF(T_学生別進路[[#This Row],[合格時期]]="",0,IF(T_学生別進路[[#This Row],[合格時期]]<M$5,1,0)) -> 1 | N32: =IF(T_学生別進路[[#This Row],[合格時期]]="",0,IF(T_学生別進路[[#This Row],[合格時期]]<N$5,1,0)) -> 1 | O32: =IF(T_学生別進路[[#This Row],[合格時期]]="",0,IF(T_学生別進路[[#This Row],[合格時期]]<O$5,1,0)) -> 1
A33: 2404024 | B33: =VLOOKUP(T_学生別進路[[#This Row],[学籍番号]],進路状況入力シート!A:B,2,FALSE) -> 2-2 | C33: =VLOOKUP(T_学生別進路[[#This Row],[学籍番号]],進路状況入力シート!A:C,3,FALSE) -> KHAY MON CHAN | D33: =IF(AND(T_学生別進路[[#This Row],[進路確定]]="○",T_学生別進路[[#This Row],[進学希望フラグ]]=1),"○","") | E33: =_xlfn.IFNA(RIGHT(VLOOKUP(T_学生別進路[[#This Row],[学籍番号]]&"○",進路状況入力シート!K:K,1,FALSE),1),"") | F33: =IF(T_学生別進路[[#This Row],[進学希望フラグ]]=0,"",IF(T_学生別進路[[#This Row],[進路確定]]="○",1,0)) | G33: =IF( AND( COUNTIFS(T_進路入力[学籍番号],T_学生別進路[[#This Row],[学籍番号]], T_進路入力[状況],"進学以外")>0, COUNTIFS(T_進路入力[学籍番号],T_学生別進路[[#This Row],[学籍番号]], T_進路入力[状況],"<>進学以外")>0 ), 0, IF(VLOOKUP(T_学生別進路[[#This Row],[学籍番号]],T_進路入力[],6,FALSE)="進学以外",0,1) ) -> 0 | H33: =_xlfn.XLOOKUP(T_学生別進路[[#This Row],[学籍番号]]&"○",進路状況入力シート!K:K,進路状況入力シート!D:D,"",0,1) | K33: =IF(T_学生別進路[[#This Row],[合格時期]]="",0,IF(T_学生別進路[[#This Row],[合格時期]]<K$5,1,0)) -> 0 | L33: =IF(T_学生別進路[[#This Row],[合格時期]]="",0,IF(T_学生別進路[[#This Row],[合格時期]]<L$5,1,0)) -> 0 | M33: =IF(T_学生別進路[[#This Row],[合格時期]]="",0,IF(T_学生別進路[[#This Row],[合格時期]]<M$5,1,0)) -> 0 | N33: =IF(T_学生別進路[[#This Row],[合格時期]]="",0,IF(T_学生別進路[[#This Row],[合格時期]]<N$5,1,0)) -> 0 | O33: =IF(T_学生別進路[[#This Row],[合格時期]]="",0,IF(T_学生別進路[[#This Row],[合格時期]]<O$5,1,0)) -> 0 | P33: 5/24期限
A34: 2404026 | B34: =VLOOKUP(T_学生別進路[[#This Row],[学籍番号]],進路状況入力シート!A:B,2,FALSE) -> 2-2 | C34: =VLOOKUP(T_学生別進路[[#This Row],[学籍番号]],進路状況入力シート!A:C,3,FALSE) -> YE MIN HTET | D34: =IF(AND(T_学生別進路[[#This Row],[進路確定]]="○",T_学生別進路[[#This Row],[進学希望フラグ]]=1),"○","") -> ○ | E34: =_xlfn.IFNA(RIGHT(VLOOKUP(T_学生別進路[[#This Row],[学籍番号]]&"○",進路状況入力シート!K:K,1,FALSE),1),"") -> ○ | F34: =IF(T_学生別進路[[#This Row],[進学希望フラグ]]=0,"",IF(T_学生別進路[[#This Row],[進路確定]]="○",1,0)) -> 1 | G34: =IF( AND( COUNTIFS(T_進路入力[学籍番号],T_学生別進路[[#This Row],[学籍番号]], T_進路入力[状況],"進学以外")>0, COUNTIFS(T_進路入力[学籍番号],T_学生別進路[[#This Row],[学籍番号]], T_進路入力[状況],"<>進学以外")>0 ), 0, IF(VLOOKUP(T_学生別進路[[#This Row],[学籍番号]],T_進路入力[],6,FALSE)="進学以外",0,1) ) -> 1 | H34: =_xlfn.XLOOKUP(T_学生別進路[[#This Row],[学籍番号]]&"○",進路状況入力シート!K:K,進路状況入力シート!D:D,"",0,1) -> 神戸松蔭大学 | I34: B | J34: 45992 | K34: =IF(T_学生別進路[[#This Row],[合格時期]]="",0,IF(T_学生別進路[[#This Row],[合格時期]]<K$5,1,0)) -> 0 | L34: =IF(T_学生別進路[[#This Row],[合格時期]]="",0,IF(T_学生別進路[[#This Row],[合格時期]]<L$5,1,0)) -> 1 | M34: =IF(T_学生別進路[[#This Row],[合格時期]]="",0,IF(T_学生別進路[[#This Row],[合格時期]]<M$5,1,0)) -> 1 | N34: =IF(T_学生別進路[[#This Row],[合格時期]]="",0,IF(T_学生別進路[[#This Row],[合格時期]]<N$5,1,0)) -> 1 | O34: =IF(T_学生別進路[[#This Row],[合格時期]]="",0,IF(T_学生別進路[[#This Row],[合格時期]]<O$5,1,0)) -> 1
A35: 2404029 | B35: =VLOOKUP(T_学生別進路[[#This Row],[学籍番号]],進路状況入力シート!A:B,2,FALSE) -> 2-2 | C35: =VLOOKUP(T_学生別進路[[#This Row],[学籍番号]],進路状況入力シート!A:C,3,FALSE) -> KAY ZIN OO | D35: =IF(AND(T_学生別進路[[#This Row],[進路確定]]="○",T_学生別進路[[#This Row],[進学希望フラグ]]=1),"○","") -> ○ | E35: =_xlfn.IFNA(RIGHT(VLOOKUP(T_学生別進路[[#This Row],[学籍番号]]&"○",進路状況入力シート!K:K,1,FALSE),1),"") -> ○ | F35: =IF(T_学生別進路[[#This Row],[進学希望フラグ]]=0,"",IF(T_学生別進路[[#This Row],[進路確定]]="○",1,0)) -> 1 | G35: =IF( AND( COUNTIFS(T_進路入力[学籍番号],T_学生別進路[[#This Row],[学籍番号]], T_進路入力[状況],"進学以外")>0, COUNTIFS(T_進路入力[学籍番号],T_学生別進路[[#This Row],[学籍番号]], T_進路入力[状況],"<>進学以外")>0 ), 0, IF(VLOOKUP(T_学生別進路[[#This Row],[学籍番号]],T_進路入力[],6,FALSE)="進学以外",0,1) ) -> 1 | H35: =_xlfn.XLOOKUP(T_学生別進路[[#This Row],[学籍番号]]&"○",進路状況入力シート!K:K,進路状況入力シート!D:D,"",0,1) -> ECC国際外語専門学校 | I35: B | J35: 45962 | K35: =IF(T_学生別進路[[#This Row],[合格時期]]="",0,IF(T_学生別進路[[#This Row],[合格時期]]<K$5,1,0)) -> 1 | L35: =IF(T_学生別進路[[#This Row],[合格時期]]="",0,IF(T_学生別進路[[#This Row],[合格時期]]<L$5,1,0)) -> 1 | M35: =IF(T_学生別進路[[#This Row],[合格時期]]="",0,IF(T_学生別進路[[#This Row],[合格時期]]<M$5,1,0)) -> 1 | N35: =IF(T_学生別進路[[#This Row],[合格時期]]="",0,IF(T_学生別進路[[#This Row],[合格時期]]<N$5,1,0)) -> 1 | O35: =IF(T_学生別進路[[#This Row],[合格時期]]="",0,IF(T_学生別進路[[#This Row],[合格時期]]<O$5,1,0)) -> 1
A36: 2404030 | B36: =VLOOKUP(T_学生別進路[[#This Row],[学籍番号]],進路状況入力シート!A:B,2,FALSE) -> 2-2 | C36: =VLOOKUP(T_学生別進路[[#This Row],[学籍番号]],進路状況入力シート!A:C,3,FALSE) -> MYAT PWINT WAI | D36: =IF(AND(T_学生別進路[[#This Row],[進路確定]]="○",T_学生別進路[[#This Row],[進学希望フラグ]]=1),"○","") -> ○ | E36: =_xlfn.IFNA(RIGHT(VLOOKUP(T_学生別進路[[#This Row],[学籍番号]]&"○",進路状況入力シート!K:K,1,FALSE),1),"") -> ○ | F36: =IF(T_学生別進路[[#This Row],[進学希望フラグ]]=0,"",IF(T_学生別進路[[#This Row],[進路確定]]="○",1,0)) -> 1 | G36: =IF( AND( COUNTIFS(T_進路入力[学籍番号],T_学生別進路[[#This Row],[学籍番号]], T_進路入力[状況],"進学以外")>0, COUNTIFS(T_進路入力[学籍番号],T_学生別進路[[#This Row],[学籍番号]], T_進路入力[状況],"<>進学以外")>0 ), 0, IF(VLOOKUP(T_学生別進路[[#This Row],[学籍番号]],T_進路入力[],6,FALSE)="進学以外",0,1) ) -> 1 | H36: =_xlfn.XLOOKUP(T_学生別進路[[#This Row],[学籍番号]]&"○",進路状況入力シート!K:K,進路状況入力シート!D:D,"",0,1) -> 中央工学校 | I36: B | J36: 46023 | K36: =IF(T_学生別進路[[#This Row],[合格時期]]="",0,IF(T_学生別進路[[#This Row],[合格時期]]<K$5,1,0)) -> 0 | L36: =IF(T_学生別進路[[#This Row],[合格時期]]="",0,IF(T_学生別進路[[#This Row],[合格時期]]<L$5,1,0)) -> 0 | M36: =IF(T_学生別進路[[#This Row],[合格時期]]="",0,IF(T_学生別進路[[#This Row],[合格時期]]<M$5,1,0)) -> 1 | N36: =IF(T_学生別進路[[#This Row],[合格時期]]="",0,IF(T_学生別進路[[#This Row],[合格時期]]<N$5,1,0)) -> 1 | O36: =IF(T_学生別進路[[#This Row],[合格時期]]="",0,IF(T_学生別進路[[#This Row],[合格時期]]<O$5,1,0)) -> 1
A37: 2404049 | B37: =VLOOKUP(T_学生別進路[[#This Row],[学籍番号]],進路状況入力シート!A:B,2,FALSE) -> 2-2 | C37: =VLOOKUP(T_学生別進路[[#This Row],[学籍番号]],進路状況入力シート!A:C,3,FALSE) -> SAI KHANT SITHU | D37: =IF(AND(T_学生別進路[[#This Row],[進路確定]]="○",T_学生別進路[[#This Row],[進学希望フラグ]]=1),"○","") -> ○ | E37: =_xlfn.IFNA(RIGHT(VLOOKUP(T_学生別進路[[#This Row],[学籍番号]]&"○",進路状況入力シート!K:K,1,FALSE),1),"") -> ○ | F37: =IF(T_学生別進路[[#This Row],[進学希望フラグ]]=0,"",IF(T_学生別進路[[#This Row],[進路確定]]="○",1,0)) -> 1 | G37: =IF( AND( COUNTIFS(T_進路入力[学籍番号],T_学生別進路[[#This Row],[学籍番号]], T_進路入力[状況],"進学以外")>0, COUNTIFS(T_進路入力[学籍番号],T_学生別進路[[#This Row],[学籍番号]], T_進路入力[状況],"<>進学以外")>0 ), 0, IF(VLOOKUP(T_学生別進路[[#This Row],[学籍番号]],T_進路入力[],6,FALSE)="進学以外",0,1) ) -> 1 | H37: =_xlfn.XLOOKUP(T_学生別進路[[#This Row],[学籍番号]]&"○",進路状況入力シート!K:K,進路状況入力シート!D:D,"",0,1) -> 大阪モード学園 | J37: 45931 | K37: =IF(T_学生別進路[[#This Row],[合格時期]]="",0,IF(T_学生別進路[[#This Row],[合格時期]]<K$5,1,0)) -> 1 | L37: =IF(T_学生別進路[[#This Row],[合格時期]]="",0,IF(T_学生別進路[[#This Row],[合格時期]]<L$5,1,0)) -> 1 | M37: =IF(T_学生別進路[[#This Row],[合格時期]]="",0,IF(T_学生別進路[[#This Row],[合格時期]]<M$5,1,0)) -> 1 | N37: =IF(T_学生別進路[[#This Row],[合格時期]]="",0,IF(T_学生別進路[[#This Row],[合格時期]]<N$5,1,0)) -> 1 | O37: =IF(T_学生別進路[[#This Row],[合格時期]]="",0,IF(T_学生別進路[[#This Row],[合格時期]]<O$5,1,0)) -> 1
A38: 2404110 | B38: =VLOOKUP(T_学生別進路[[#This Row],[学籍番号]],進路状況入力シート!A:B,2,FALSE) -> 2-2 | C38: =VLOOKUP(T_学生別進路[[#This Row],[学籍番号]],進路状況入力シート!A:C,3,FALSE) -> MD. JONAYET | D38: =IF(AND(T_学生別進路[[#This Row],[進路確定]]="○",T_学生別進路[[#This Row],[進学希望フラグ]]=1),"○","") -> ○ | E38: =_xlfn.IFNA(RIGHT(VLOOKUP(T_学生別進路[[#This Row],[学籍番号]]&"○",進路状況入力シート!K:K,1,FALSE),1),"") -> ○ | F38: =IF(T_学生別進路[[#This Row],[進学希望フラグ]]=0,"",IF(T_学生別進路[[#This Row],[進路確定]]="○",1,0)) -> 1 | G38: =IF( AND( COUNTIFS(T_進路入力[学籍番号],T_学生別進路[[#This Row],[学籍番号]], T_進路入力[状況],"進学以外")>0, COUNTIFS(T_進路入力[学籍番号],T_学生別進路[[#This Row],[学籍番号]], T_進路入力[状況],"<>進学以外")>0 ), 0, IF(VLOOKUP(T_学生別進路[[#This Row],[学籍番号]],T_進路入力[],6,FALSE)="進学以外",0,1) ) -> 1 | H38: =_xlfn.XLOOKUP(T_学生別進路[[#This Row],[学籍番号]]&"○",進路状況入力シート!K:K,進路状況入力シート!D:D,"",0,1) -> 早稲田文理専門学校 | I38: A | J38: 45992 | K38: =IF(T_学生別進路[[#This Row],[合格時期]]="",0,IF(T_学生別進路[[#This Row],[合格時期]]<K$5,1,0)) -> 0 | L38: =IF(T_学生別進路[[#This Row],[合格時期]]="",0,IF(T_学生別進路[[#This Row],[合格時期]]<L$5,1,0)) -> 1 | M38: =IF(T_学生別進路[[#This Row],[合格時期]]="",0,IF(T_学生別進路[[#This Row],[合格時期]]<M$5,1,0)) -> 1 | N38: =IF(T_学生別進路[[#This Row],[合格時期]]="",0,IF(T_学生別進路[[#This Row],[合格時期]]<N$5,1,0)) -> 1 | O38: =IF(T_学生別進路[[#This Row],[合格時期]]="",0,IF(T_学生別進路[[#This Row],[合格時期]]<O$5,1,0)) -> 1
A39: 2404165 | B39: =VLOOKUP(T_学生別進路[[#This Row],[学籍番号]],進路状況入力シート!A:B,2,FALSE) -> 2-2 | C39: =VLOOKUP(T_学生別進路[[#This Row],[学籍番号]],進路状況入力シート!A:C,3,FALSE) -> GIRI TAPENDRA RAJ | D39: =IF(AND(T_学生別進路[[#This Row],[進路確定]]="○",T_学生別進路[[#This Row],[進学希望フラグ]]=1),"○","") -> ○ | E39: =_xlfn.IFNA(RIGHT(VLOOKUP(T_学生別進路[[#This Row],[学籍番号]]&"○",進路状況入力シート!K:K,1,FALSE),1),"") -> ○ | F39: =IF(T_学生別進路[[#This Row],[進学希望フラグ]]=0,"",IF(T_学生別進路[[#This Row],[進路確定]]="○",1,0)) -> 1 | G39: =IF( AND( COUNTIFS(T_進路入力[学籍番号],T_学生別進路[[#This Row],[学籍番号]], T_進路入力[状況],"進学以外")>0, COUNTIFS(T_進路入力[学籍番号],T_学生別進路[[#This Row],[学籍番号]], T_進路入力[状況],"<>進学以外")>0 ), 0, IF(VLOOKUP(T_学生別進路[[#This Row],[学籍番号]],T_進路入力[],6,FALSE)="進学以外",0,1) ) -> 1 | H39: =_xlfn.XLOOKUP(T_学生別進路[[#This Row],[学籍番号]]&"○",進路状況入力シート!K:K,進路状況入力シート!D:D,"",0,1) -> 柏木実業専門学校 | J39: 45962 | K39: =IF(T_学生別進路[[#This Row],[合格時期]]="",0,IF(T_学生別進路[[#This Row],[合格時期]]<K$5,1,0)) -> 1 | L39: =IF(T_学生別進路[[#This Row],[合格時期]]="",0,IF(T_学生別進路[[#This Row],[合格時期]]<L$5,1,0)) -> 1 | M39: =IF(T_学生別進路[[#This Row],[合格時期]]="",0,IF(T_学生別進路[[#This Row],[合格時期]]<M$5,1,0)) -> 1 | N39: =IF(T_学生別進路[[#This Row],[合格時期]]="",0,IF(T_学生別進路[[#This Row],[合格時期]]<N$5,1,0)) -> 1 | O39: =IF(T_学生別進路[[#This Row],[合格時期]]="",0,IF(T_学生別進路[[#This Row],[合格時期]]<O$5,1,0)) -> 1
A40: 2407029 | B40: =VLOOKUP(T_学生別進路[[#This Row],[学籍番号]],進路状況入力シート!A:B,2,FALSE) -> 2-2 | C40: =VLOOKUP(T_学生別進路[[#This Row],[学籍番号]],進路状況入力シート!A:C,3,FALSE) -> EI EI THEIN | D40: =IF(AND(T_学生別進路[[#This Row],[進路確定]]="○",T_学生別進路[[#This Row],[進学希望フラグ]]=1),"○","") | E40: =_xlfn.IFNA(RIGHT(VLOOKUP(T_学生別進路[[#This Row],[学籍番号]]&"○",進路状況入力シート!K:K,1,FALSE),1),"") -> ○ | F40: =IF(T_学生別進路[[#This Row],[進学希望フラグ]]=0,"",IF(T_学生別進路[[#This Row],[進路確定]]="○",1,0)) | G40: =IF( AND( COUNTIFS(T_進路入力[学籍番号],T_学生別進路[[#This Row],[学籍番号]], T_進路入力[状況],"進学以外")>0, COUNTIFS(T_進路入力[学籍番号],T_学生別進路[[#This Row],[学籍番号]], T_進路入力[状況],"<>進学以外")>0 ), 0, IF(VLOOKUP(T_学生別進路[[#This Row],[学籍番号]],T_進路入力[],6,FALSE)="進学以外",0,1) ) -> 0 | H40: =_xlfn.XLOOKUP(T_学生別進路[[#This Row],[学籍番号]]&"○",進路状況入力シート!K:K,進路状況入力シート!D:D,"",0,1) -> 0 | K40: =IF(T_学生別進路[[#This Row],[合格時期]]="",0,IF(T_学生別進路[[#This Row],[合格時期]]<K$5,1,0)) -> 0 | L40: =IF(T_学生別進路[[#This Row],[合格時期]]="",0,IF(T_学生別進路[[#This Row],[合格時期]]<L$5,1,0)) -> 0 | M40: =IF(T_学生別進路[[#This Row],[合格時期]]="",0,IF(T_学生別進路[[#This Row],[合格時期]]<M$5,1,0)) -> 0 | N40: =IF(T_学生別進路[[#This Row],[合格時期]]="",0,IF(T_学生別進路[[#This Row],[合格時期]]<N$5,1,0)) -> 0 | O40: =IF(T_学生別進路[[#This Row],[合格時期]]="",0,IF(T_学生別進路[[#This Row],[合格時期]]<O$5,1,0)) -> 0
